ERROR 2019-05-01 14:17:19,831 tool Error tokenizing data. C error: Expected 1 fields in line 3, saw 3

INFO 2019-05-01 14:17:19,842 basehttp "GET /dataset/19 HTTP/1.1" 200 1712
WARNING 2019-05-01 14:17:19,947 basehttp "GET /static/css/styles.css HTTP/1.1" 404 1767
WARNING 2019-05-01 14:17:20,057 basehttp "GET /static/css/styles.css HTTP/1.1" 404 1767
INFO 2019-05-01 14:17:42,106 autoreload /home/maus/bsuir/kp/mysite/engine/tool.py changed, reloading.
INFO 2019-05-01 14:17:42,708 autoreload Watching for file changes with StatReloader
ERROR 2019-05-01 14:17:44,595 tool <built-in method with_traceback of ParserError object at 0x7fec3edd5fa8>
INFO 2019-05-01 14:17:44,612 basehttp "GET /dataset/19 HTTP/1.1" 200 1712
WARNING 2019-05-01 14:17:44,708 basehttp "GET /static/css/styles.css HTTP/1.1" 404 1767
WARNING 2019-05-01 14:17:44,843 basehttp "GET /static/css/styles.css HTTP/1.1" 404 1767
INFO 2019-05-01 14:17:53,406 autoreload /home/maus/bsuir/kp/mysite/engine/tool.py changed, reloading.
INFO 2019-05-01 14:17:54,025 autoreload Watching for file changes with StatReloader
ERROR 2019-05-01 14:17:59,130 log Internal Server Error: /dataset/19
Traceback (most recent call last):
  File "/home/maus/bsuir/kp/mysite/engine/tool.py", line 22, in is_valid
    self.df = pd.read_csv(str(self.file))
  File "/home/maus/.local/share/virtualenvs/kp-3crlKS4c/lib/python3.7/site-packages/pandas/io/parsers.py", line 702, in parser_f
    return _read(filepath_or_buffer, kwds)
  File "/home/maus/.local/share/virtualenvs/kp-3crlKS4c/lib/python3.7/site-packages/pandas/io/parsers.py", line 435, in _read
    data = parser.read(nrows)
  File "/home/maus/.local/share/virtualenvs/kp-3crlKS4c/lib/python3.7/site-packages/pandas/io/parsers.py", line 1139, in read
    ret = self._engine.read(nrows)
  File "/home/maus/.local/share/virtualenvs/kp-3crlKS4c/lib/python3.7/site-packages/pandas/io/parsers.py", line 1995, in read
    data = self._reader.read(nrows)
  File "pandas/_libs/parsers.pyx", line 899, in pandas._libs.parsers.TextReader.read
  File "pandas/_libs/parsers.pyx", line 914, in pandas._libs.parsers.TextReader._read_low_memory
  File "pandas/_libs/parsers.pyx", line 968, in pandas._libs.parsers.TextReader._read_rows
  File "pandas/_libs/parsers.pyx", line 955, in pandas._libs.parsers.TextReader._tokenize_rows
  File "pandas/_libs/parsers.pyx", line 2172, in pandas._libs.parsers.raise_parser_error
pandas.errors.ParserError: Error tokenizing data. C error: Expected 1 fields in line 3, saw 3


During handling of the above exception, another exception occurred:

Traceback (most recent call last):
  File "/home/maus/.local/share/virtualenvs/kp-3crlKS4c/lib/python3.7/site-packages/django/core/handlers/exception.py", line 34, in inner
    response = get_response(request)
  File "/home/maus/.local/share/virtualenvs/kp-3crlKS4c/lib/python3.7/site-packages/django/core/handlers/base.py", line 115, in _get_response
    response = self.process_exception_by_middleware(e, request)
  File "/home/maus/.local/share/virtualenvs/kp-3crlKS4c/lib/python3.7/site-packages/django/core/handlers/base.py", line 113, in _get_response
    response = wrapped_callback(request, *callback_args, **callback_kwargs)
  File "/home/maus/.local/share/virtualenvs/kp-3crlKS4c/lib/python3.7/site-packages/django/views/generic/base.py", line 71, in view
    return self.dispatch(request, *args, **kwargs)
  File "/home/maus/.local/share/virtualenvs/kp-3crlKS4c/lib/python3.7/site-packages/django/views/generic/base.py", line 97, in dispatch
    return handler(request, *args, **kwargs)
  File "/home/maus/.local/share/virtualenvs/kp-3crlKS4c/lib/python3.7/site-packages/django/views/generic/detail.py", line 107, in get
    context = self.get_context_data(object=self.object)
  File "/home/maus/bsuir/kp/mysite/ignis/views.py", line 53, in get_context_data
    meta_data = dataset.meta_data()
  File "/home/maus/bsuir/kp/mysite/ignis/models.py", line 35, in meta_data
    return resolver.get_meta_data()
  File "/home/maus/bsuir/kp/mysite/engine/tool.py", line 13, in get_meta_data
    if self.is_valid() == False:
  File "/home/maus/bsuir/kp/mysite/engine/tool.py", line 25, in is_valid
    logger.error(e.with_traceback())
TypeError: with_traceback() takes exactly one argument (0 given)
ERROR 2019-05-01 14:17:59,131 basehttp "GET /dataset/19 HTTP/1.1" 500 191113
INFO 2019-05-01 14:18:44,391 autoreload /home/maus/bsuir/kp/mysite/engine/tool.py changed, reloading.
INFO 2019-05-01 14:18:45,039 autoreload Watching for file changes with StatReloader
INFO 2019-05-01 14:18:48,413 autoreload /home/maus/bsuir/kp/mysite/engine/tool.py changed, reloading.
INFO 2019-05-01 14:18:49,013 autoreload Watching for file changes with StatReloader
INFO 2019-05-01 14:18:54,461 autoreload /home/maus/bsuir/kp/mysite/engine/tool.py changed, reloading.
INFO 2019-05-01 14:18:55,114 autoreload Watching for file changes with StatReloader
ERROR 2019-05-01 14:18:58,485 tool error
Traceback (most recent call last):
  File "/home/maus/bsuir/kp/mysite/engine/tool.py", line 22, in is_valid
    self.df = pd.read_csv(str(self.file))
  File "/home/maus/.local/share/virtualenvs/kp-3crlKS4c/lib/python3.7/site-packages/pandas/io/parsers.py", line 702, in parser_f
    return _read(filepath_or_buffer, kwds)
  File "/home/maus/.local/share/virtualenvs/kp-3crlKS4c/lib/python3.7/site-packages/pandas/io/parsers.py", line 435, in _read
    data = parser.read(nrows)
  File "/home/maus/.local/share/virtualenvs/kp-3crlKS4c/lib/python3.7/site-packages/pandas/io/parsers.py", line 1139, in read
    ret = self._engine.read(nrows)
  File "/home/maus/.local/share/virtualenvs/kp-3crlKS4c/lib/python3.7/site-packages/pandas/io/parsers.py", line 1995, in read
    data = self._reader.read(nrows)
  File "pandas/_libs/parsers.pyx", line 899, in pandas._libs.parsers.TextReader.read
  File "pandas/_libs/parsers.pyx", line 914, in pandas._libs.parsers.TextReader._read_low_memory
  File "pandas/_libs/parsers.pyx", line 968, in pandas._libs.parsers.TextReader._read_rows
  File "pandas/_libs/parsers.pyx", line 955, in pandas._libs.parsers.TextReader._tokenize_rows
  File "pandas/_libs/parsers.pyx", line 2172, in pandas._libs.parsers.raise_parser_error
pandas.errors.ParserError: Error tokenizing data. C error: Expected 1 fields in line 3, saw 3

INFO 2019-05-01 14:18:58,508 basehttp "GET /dataset/19 HTTP/1.1" 200 1712
WARNING 2019-05-01 14:18:58,654 basehttp "GET /static/css/styles.css HTTP/1.1" 404 1767
WARNING 2019-05-01 14:18:58,736 basehttp "GET /static/css/styles.css HTTP/1.1" 404 1767
INFO 2019-05-01 14:19:18,689 basehttp "GET /dataset/ HTTP/1.1" 200 1621
WARNING 2019-05-01 14:19:18,822 basehttp "GET /static/css/styles.css HTTP/1.1" 404 1767
WARNING 2019-05-01 14:19:18,942 basehttp "GET /static/css/styles.css HTTP/1.1" 404 1767
INFO 2019-05-01 14:19:20,307 basehttp "GET /dataset/create HTTP/1.1" 200 1948
WARNING 2019-05-01 14:19:20,420 basehttp "GET /static/css/styles.css HTTP/1.1" 404 1767
WARNING 2019-05-01 14:19:20,533 basehttp "GET /static/css/styles.css HTTP/1.1" 404 1767
INFO 2019-05-01 14:19:26,347 basehttp "POST /dataset/create HTTP/1.1" 302 0
INFO 2019-05-01 14:19:26,408 basehttp "GET /dataset/ HTTP/1.1" 200 1729
WARNING 2019-05-01 14:19:26,574 basehttp "GET /static/css/styles.css HTTP/1.1" 404 1767
WARNING 2019-05-01 14:19:26,677 basehttp "GET /static/css/styles.css HTTP/1.1" 404 1767
INFO 2019-05-01 14:19:28,337 basehttp "GET /dataset/21 HTTP/1.1" 200 1647
WARNING 2019-05-01 14:19:28,490 basehttp "GET /static/css/styles.css HTTP/1.1" 404 1767
WARNING 2019-05-01 14:19:28,658 basehttp "GET /static/css/styles.css HTTP/1.1" 404 1767
INFO 2019-05-01 14:20:20,896 autoreload /home/maus/bsuir/kp/mysite/engine/tool.py changed, reloading.
INFO 2019-05-01 14:20:21,521 autoreload Watching for file changes with StatReloader
ERROR 2019-05-01 14:20:24,323 log Internal Server Error: /dataset/21
Traceback (most recent call last):
  File "/home/maus/.local/share/virtualenvs/kp-3crlKS4c/lib/python3.7/site-packages/django/core/handlers/exception.py", line 34, in inner
    response = get_response(request)
  File "/home/maus/.local/share/virtualenvs/kp-3crlKS4c/lib/python3.7/site-packages/django/core/handlers/base.py", line 115, in _get_response
    response = self.process_exception_by_middleware(e, request)
  File "/home/maus/.local/share/virtualenvs/kp-3crlKS4c/lib/python3.7/site-packages/django/core/handlers/base.py", line 113, in _get_response
    response = wrapped_callback(request, *callback_args, **callback_kwargs)
  File "/home/maus/.local/share/virtualenvs/kp-3crlKS4c/lib/python3.7/site-packages/django/views/generic/base.py", line 71, in view
    return self.dispatch(request, *args, **kwargs)
  File "/home/maus/.local/share/virtualenvs/kp-3crlKS4c/lib/python3.7/site-packages/django/views/generic/base.py", line 97, in dispatch
    return handler(request, *args, **kwargs)
  File "/home/maus/.local/share/virtualenvs/kp-3crlKS4c/lib/python3.7/site-packages/django/views/generic/detail.py", line 107, in get
    context = self.get_context_data(object=self.object)
  File "/home/maus/bsuir/kp/mysite/ignis/views.py", line 53, in get_context_data
    meta_data = dataset.meta_data()
  File "/home/maus/bsuir/kp/mysite/ignis/models.py", line 35, in meta_data
    return resolver.get_meta_data()
  File "/home/maus/bsuir/kp/mysite/engine/tool.py", line 15, in get_meta_data
    return {"valid": self.is_valid(), "range": self.get_range()}
  File "/home/maus/bsuir/kp/mysite/engine/tool.py", line 18, in get_range
    return "x".join(self.df.shape)
TypeError: sequence item 0: expected str instance, int found
ERROR 2019-05-01 14:20:24,324 basehttp "GET /dataset/21 HTTP/1.1" 500 96722
INFO 2019-05-01 14:20:41,658 autoreload /home/maus/bsuir/kp/mysite/engine/tool.py changed, reloading.
INFO 2019-05-01 14:20:42,315 autoreload Watching for file changes with StatReloader
INFO 2019-05-01 14:20:43,943 basehttp "GET /dataset/21 HTTP/1.1" 200 1647
WARNING 2019-05-01 14:20:44,060 basehttp "GET /static/css/styles.css HTTP/1.1" 404 1767
WARNING 2019-05-01 14:20:44,270 basehttp "GET /static/css/styles.css HTTP/1.1" 404 1767
INFO 2019-05-01 14:20:54,024 autoreload /home/maus/bsuir/kp/mysite/engine/tool.py changed, reloading.
INFO 2019-05-01 14:20:54,640 autoreload Watching for file changes with StatReloader
INFO 2019-05-01 14:21:37,552 autoreload /home/maus/bsuir/kp/mysite/ignis/views.py changed, reloading.
INFO 2019-05-01 14:21:38,154 autoreload Watching for file changes with StatReloader
INFO 2019-05-01 14:22:18,969 autoreload /home/maus/bsuir/kp/mysite/ignis/views.py changed, reloading.
INFO 2019-05-01 14:22:19,602 autoreload Watching for file changes with StatReloader
INFO 2019-05-01 14:22:44,861 autoreload /home/maus/bsuir/kp/mysite/ignis/views.py changed, reloading.
INFO 2019-05-01 14:22:45,504 autoreload Watching for file changes with StatReloader
INFO 2019-05-01 14:24:03,820 autoreload /home/maus/bsuir/kp/mysite/ignis/views.py changed, reloading.
INFO 2019-05-01 14:24:04,436 autoreload Watching for file changes with StatReloader
INFO 2019-05-01 14:24:09,886 autoreload /home/maus/bsuir/kp/mysite/ignis/views.py changed, reloading.
INFO 2019-05-01 14:24:10,519 autoreload Watching for file changes with StatReloader
ERROR 2019-05-01 14:24:22,950 log Internal Server Error: /dataset/21
Traceback (most recent call last):
  File "/home/maus/.local/share/virtualenvs/kp-3crlKS4c/lib/python3.7/site-packages/django/core/handlers/exception.py", line 34, in inner
    response = get_response(request)
  File "/home/maus/.local/share/virtualenvs/kp-3crlKS4c/lib/python3.7/site-packages/django/core/handlers/base.py", line 115, in _get_response
    response = self.process_exception_by_middleware(e, request)
  File "/home/maus/.local/share/virtualenvs/kp-3crlKS4c/lib/python3.7/site-packages/django/core/handlers/base.py", line 113, in _get_response
    response = wrapped_callback(request, *callback_args, **callback_kwargs)
  File "/home/maus/.local/share/virtualenvs/kp-3crlKS4c/lib/python3.7/site-packages/django/views/generic/base.py", line 71, in view
    return self.dispatch(request, *args, **kwargs)
  File "/home/maus/.local/share/virtualenvs/kp-3crlKS4c/lib/python3.7/site-packages/django/views/generic/base.py", line 97, in dispatch
    return handler(request, *args, **kwargs)
  File "/home/maus/.local/share/virtualenvs/kp-3crlKS4c/lib/python3.7/site-packages/django/views/generic/detail.py", line 107, in get
    context = self.get_context_data(object=self.object)
  File "/home/maus/bsuir/kp/mysite/ignis/views.py", line 56, in get_context_data
    for key, value in meta_data.items:
TypeError: 'builtin_function_or_method' object is not iterable
ERROR 2019-05-01 14:24:22,951 basehttp "GET /dataset/21 HTTP/1.1" 500 87341
WARNING 2019-05-01 14:24:23,184 log Not Found: /favicon.ico
WARNING 2019-05-01 14:24:23,184 basehttp "GET /favicon.ico HTTP/1.1" 404 3488
INFO 2019-05-01 14:24:30,770 autoreload Watching for file changes with StatReloader
ERROR 2019-05-01 14:24:31,905 log Internal Server Error: /dataset/21
Traceback (most recent call last):
  File "/home/maus/.local/share/virtualenvs/kp-3crlKS4c/lib/python3.7/site-packages/django/core/handlers/exception.py", line 34, in inner
    response = get_response(request)
  File "/home/maus/.local/share/virtualenvs/kp-3crlKS4c/lib/python3.7/site-packages/django/core/handlers/base.py", line 115, in _get_response
    response = self.process_exception_by_middleware(e, request)
  File "/home/maus/.local/share/virtualenvs/kp-3crlKS4c/lib/python3.7/site-packages/django/core/handlers/base.py", line 113, in _get_response
    response = wrapped_callback(request, *callback_args, **callback_kwargs)
  File "/home/maus/.local/share/virtualenvs/kp-3crlKS4c/lib/python3.7/site-packages/django/views/generic/base.py", line 71, in view
    return self.dispatch(request, *args, **kwargs)
  File "/home/maus/.local/share/virtualenvs/kp-3crlKS4c/lib/python3.7/site-packages/django/views/generic/base.py", line 97, in dispatch
    return handler(request, *args, **kwargs)
  File "/home/maus/.local/share/virtualenvs/kp-3crlKS4c/lib/python3.7/site-packages/django/views/generic/detail.py", line 107, in get
    context = self.get_context_data(object=self.object)
  File "/home/maus/bsuir/kp/mysite/ignis/views.py", line 56, in get_context_data
    for key, value in meta_data.items:
TypeError: 'builtin_function_or_method' object is not iterable
ERROR 2019-05-01 14:24:31,907 basehttp "GET /dataset/21 HTTP/1.1" 500 87341
INFO 2019-05-01 14:24:49,856 autoreload /home/maus/bsuir/kp/mysite/ignis/views.py changed, reloading.
INFO 2019-05-01 14:24:50,455 autoreload Watching for file changes with StatReloader
INFO 2019-05-01 14:24:51,525 basehttp "GET /dataset/21 HTTP/1.1" 200 1688
WARNING 2019-05-01 14:24:51,654 basehttp "GET /static/css/styles.css HTTP/1.1" 404 1767
WARNING 2019-05-01 14:24:51,799 basehttp "GET /static/css/styles.css HTTP/1.1" 404 1767
INFO 2019-05-01 14:25:56,448 autoreload /home/maus/bsuir/kp/mysite/engine/tool.py changed, reloading.
INFO 2019-05-01 14:25:58,007 autoreload Watching for file changes with StatReloader
INFO 2019-05-01 14:26:24,300 autoreload /home/maus/bsuir/kp/mysite/engine/tool.py changed, reloading.
INFO 2019-05-01 14:26:24,931 autoreload Watching for file changes with StatReloader
INFO 2019-05-01 14:26:44,494 basehttp "GET /dataset/21 HTTP/1.1" 200 1910
WARNING 2019-05-01 14:26:44,628 basehttp "GET /static/css/styles.css HTTP/1.1" 404 1767
WARNING 2019-05-01 14:26:44,714 basehttp "GET /static/css/styles.css HTTP/1.1" 404 1767
INFO 2019-05-01 14:27:31,846 autoreload /home/maus/bsuir/kp/mysite/engine/tool.py changed, reloading.
INFO 2019-05-01 14:27:32,476 autoreload Watching for file changes with StatReloader
ERROR 2019-05-01 14:27:35,303 log Internal Server Error: /dataset/21
Traceback (most recent call last):
  File "/home/maus/.local/share/virtualenvs/kp-3crlKS4c/lib/python3.7/site-packages/django/core/handlers/exception.py", line 34, in inner
    response = get_response(request)
  File "/home/maus/.local/share/virtualenvs/kp-3crlKS4c/lib/python3.7/site-packages/django/core/handlers/base.py", line 115, in _get_response
    response = self.process_exception_by_middleware(e, request)
  File "/home/maus/.local/share/virtualenvs/kp-3crlKS4c/lib/python3.7/site-packages/django/core/handlers/base.py", line 113, in _get_response
    response = wrapped_callback(request, *callback_args, **callback_kwargs)
  File "/home/maus/.local/share/virtualenvs/kp-3crlKS4c/lib/python3.7/site-packages/django/views/generic/base.py", line 71, in view
    return self.dispatch(request, *args, **kwargs)
  File "/home/maus/.local/share/virtualenvs/kp-3crlKS4c/lib/python3.7/site-packages/django/views/generic/base.py", line 97, in dispatch
    return handler(request, *args, **kwargs)
  File "/home/maus/.local/share/virtualenvs/kp-3crlKS4c/lib/python3.7/site-packages/django/views/generic/detail.py", line 107, in get
    context = self.get_context_data(object=self.object)
  File "/home/maus/bsuir/kp/mysite/ignis/views.py", line 53, in get_context_data
    meta_data = dataset.meta_data()
  File "/home/maus/bsuir/kp/mysite/ignis/models.py", line 35, in meta_data
    return resolver.get_meta_data()
  File "/home/maus/bsuir/kp/mysite/engine/tool.py", line 18, in get_meta_data
    "types": self.get_existing_types(),
  File "/home/maus/bsuir/kp/mysite/engine/tool.py", line 25, in get_existing_types
    return "\n".join(self.df.dtypes)
TypeError: sequence item 0: expected str instance, numpy.dtype found
ERROR 2019-05-01 14:27:35,304 basehttp "GET /dataset/21 HTTP/1.1" 500 96784
INFO 2019-05-01 14:27:48,419 autoreload /home/maus/bsuir/kp/mysite/engine/tool.py changed, reloading.
INFO 2019-05-01 14:27:49,120 autoreload Watching for file changes with StatReloader
INFO 2019-05-01 14:27:49,821 basehttp "GET /dataset/21 HTTP/1.1" 200 1780
WARNING 2019-05-01 14:27:49,936 basehttp "GET /static/css/styles.css HTTP/1.1" 404 1767
WARNING 2019-05-01 14:27:50,018 basehttp "GET /static/css/styles.css HTTP/1.1" 404 1767
INFO 2019-05-01 14:27:55,716 basehttp "GET /dataset/21 HTTP/1.1" 200 1780
WARNING 2019-05-01 14:27:55,815 basehttp "GET /static/css/styles.css HTTP/1.1" 404 1767
WARNING 2019-05-01 14:27:55,901 basehttp "GET /static/css/styles.css HTTP/1.1" 404 1767
INFO 2019-05-01 14:28:01,885 autoreload /home/maus/bsuir/kp/mysite/engine/tool.py changed, reloading.
INFO 2019-05-01 14:28:02,511 autoreload Watching for file changes with StatReloader
INFO 2019-05-01 14:28:55,922 autoreload /home/maus/bsuir/kp/mysite/engine/tool.py changed, reloading.
INFO 2019-05-01 14:28:56,542 autoreload Watching for file changes with StatReloader
INFO 2019-05-01 14:28:59,800 basehttp "GET /dataset/21 HTTP/1.1" 200 1910
WARNING 2019-05-01 14:28:59,919 basehttp "GET /static/css/styles.css HTTP/1.1" 404 1767
WARNING 2019-05-01 14:29:00,031 basehttp "GET /static/css/styles.css HTTP/1.1" 404 1767
INFO 2019-05-01 14:30:22,208 autoreload /home/maus/bsuir/kp/mysite/engine/tool.py changed, reloading.
INFO 2019-05-01 14:30:22,862 autoreload Watching for file changes with StatReloader
ERROR 2019-05-01 14:30:25,092 log Internal Server Error: /dataset/21
Traceback (most recent call last):
  File "/home/maus/.local/share/virtualenvs/kp-3crlKS4c/lib/python3.7/site-packages/django/core/handlers/exception.py", line 34, in inner
    response = get_response(request)
  File "/home/maus/.local/share/virtualenvs/kp-3crlKS4c/lib/python3.7/site-packages/django/core/handlers/base.py", line 115, in _get_response
    response = self.process_exception_by_middleware(e, request)
  File "/home/maus/.local/share/virtualenvs/kp-3crlKS4c/lib/python3.7/site-packages/django/core/handlers/base.py", line 113, in _get_response
    response = wrapped_callback(request, *callback_args, **callback_kwargs)
  File "/home/maus/.local/share/virtualenvs/kp-3crlKS4c/lib/python3.7/site-packages/django/views/generic/base.py", line 71, in view
    return self.dispatch(request, *args, **kwargs)
  File "/home/maus/.local/share/virtualenvs/kp-3crlKS4c/lib/python3.7/site-packages/django/views/generic/base.py", line 97, in dispatch
    return handler(request, *args, **kwargs)
  File "/home/maus/.local/share/virtualenvs/kp-3crlKS4c/lib/python3.7/site-packages/django/views/generic/detail.py", line 107, in get
    context = self.get_context_data(object=self.object)
  File "/home/maus/bsuir/kp/mysite/ignis/views.py", line 53, in get_context_data
    meta_data = dataset.meta_data()
  File "/home/maus/bsuir/kp/mysite/ignis/models.py", line 35, in meta_data
    return resolver.get_meta_data()
  File "/home/maus/bsuir/kp/mysite/engine/tool.py", line 18, in get_meta_data
    "types": self.get_existing_types(),
  File "/home/maus/bsuir/kp/mysite/engine/tool.py", line 25, in get_existing_types
    print(self.df.dtypes.split())
  File "/home/maus/.local/share/virtualenvs/kp-3crlKS4c/lib/python3.7/site-packages/pandas/core/generic.py", line 5067, in __getattr__
    return object.__getattribute__(self, name)
AttributeError: 'Series' object has no attribute 'split'
ERROR 2019-05-01 14:30:25,094 basehttp "GET /dataset/21 HTTP/1.1" 500 100949
ERROR 2019-05-01 14:30:28,065 log Internal Server Error: /dataset/21
Traceback (most recent call last):
  File "/home/maus/.local/share/virtualenvs/kp-3crlKS4c/lib/python3.7/site-packages/django/core/handlers/exception.py", line 34, in inner
    response = get_response(request)
  File "/home/maus/.local/share/virtualenvs/kp-3crlKS4c/lib/python3.7/site-packages/django/core/handlers/base.py", line 115, in _get_response
    response = self.process_exception_by_middleware(e, request)
  File "/home/maus/.local/share/virtualenvs/kp-3crlKS4c/lib/python3.7/site-packages/django/core/handlers/base.py", line 113, in _get_response
    response = wrapped_callback(request, *callback_args, **callback_kwargs)
  File "/home/maus/.local/share/virtualenvs/kp-3crlKS4c/lib/python3.7/site-packages/django/views/generic/base.py", line 71, in view
    return self.dispatch(request, *args, **kwargs)
  File "/home/maus/.local/share/virtualenvs/kp-3crlKS4c/lib/python3.7/site-packages/django/views/generic/base.py", line 97, in dispatch
    return handler(request, *args, **kwargs)
  File "/home/maus/.local/share/virtualenvs/kp-3crlKS4c/lib/python3.7/site-packages/django/views/generic/detail.py", line 107, in get
    context = self.get_context_data(object=self.object)
  File "/home/maus/bsuir/kp/mysite/ignis/views.py", line 53, in get_context_data
    meta_data = dataset.meta_data()
  File "/home/maus/bsuir/kp/mysite/ignis/models.py", line 35, in meta_data
    return resolver.get_meta_data()
  File "/home/maus/bsuir/kp/mysite/engine/tool.py", line 18, in get_meta_data
    "types": self.get_existing_types(),
  File "/home/maus/bsuir/kp/mysite/engine/tool.py", line 25, in get_existing_types
    print(self.df.dtypes.split())
  File "/home/maus/.local/share/virtualenvs/kp-3crlKS4c/lib/python3.7/site-packages/pandas/core/generic.py", line 5067, in __getattr__
    return object.__getattribute__(self, name)
AttributeError: 'Series' object has no attribute 'split'
ERROR 2019-05-01 14:30:28,066 basehttp "GET /dataset/21 HTTP/1.1" 500 100949
INFO 2019-05-01 14:30:38,850 autoreload /home/maus/bsuir/kp/mysite/engine/tool.py changed, reloading.
INFO 2019-05-01 14:30:39,455 autoreload Watching for file changes with StatReloader
INFO 2019-05-01 14:30:41,771 autoreload /home/maus/bsuir/kp/mysite/engine/tool.py changed, reloading.
INFO 2019-05-01 14:30:42,423 autoreload Watching for file changes with StatReloader
INFO 2019-05-01 14:30:42,652 basehttp "GET /dataset/21 HTTP/1.1" 200 1910
WARNING 2019-05-01 14:30:42,777 basehttp "GET /static/css/styles.css HTTP/1.1" 404 1767
WARNING 2019-05-01 14:30:42,874 basehttp "GET /static/css/styles.css HTTP/1.1" 404 1767
INFO 2019-05-01 14:31:21,189 autoreload /home/maus/bsuir/kp/mysite/engine/tool.py changed, reloading.
INFO 2019-05-01 14:31:21,895 autoreload Watching for file changes with StatReloader
INFO 2019-05-01 14:31:23,749 basehttp "GET /dataset/21 HTTP/1.1" 200 1910
WARNING 2019-05-01 14:31:23,865 basehttp "GET /static/css/styles.css HTTP/1.1" 404 1767
WARNING 2019-05-01 14:31:23,950 basehttp "GET /static/css/styles.css HTTP/1.1" 404 1767
INFO 2019-05-01 14:31:55,531 autoreload /home/maus/bsuir/kp/mysite/engine/tool.py changed, reloading.
INFO 2019-05-01 14:31:56,167 autoreload Watching for file changes with StatReloader
INFO 2019-05-01 14:31:58,365 basehttp "GET /dataset/21 HTTP/1.1" 200 1910
WARNING 2019-05-01 14:31:58,463 basehttp "GET /static/css/styles.css HTTP/1.1" 404 1767
WARNING 2019-05-01 14:31:58,556 basehttp "GET /static/css/styles.css HTTP/1.1" 404 1767
WARNING 2019-05-01 14:31:58,624 log Not Found: /favicon.ico
WARNING 2019-05-01 14:31:58,625 basehttp "GET /favicon.ico HTTP/1.1" 404 3488
INFO 2019-05-01 14:32:39,272 autoreload /home/maus/bsuir/kp/mysite/engine/tool.py changed, reloading.
INFO 2019-05-01 14:32:39,881 autoreload Watching for file changes with StatReloader
INFO 2019-05-01 14:32:41,113 basehttp "GET /dataset/21 HTTP/1.1" 200 2063
WARNING 2019-05-01 14:32:41,263 basehttp "GET /static/css/styles.css HTTP/1.1" 404 1767
WARNING 2019-05-01 14:32:41,378 basehttp "GET /static/css/styles.css HTTP/1.1" 404 1767
INFO 2019-05-01 14:33:08,681 basehttp "GET /dataset/ HTTP/1.1" 200 1729
WARNING 2019-05-01 14:33:08,807 basehttp "GET /static/css/styles.css HTTP/1.1" 404 1767
WARNING 2019-05-01 14:33:08,864 basehttp "GET /static/css/styles.css HTTP/1.1" 404 1767
INFO 2019-05-01 14:33:49,194 basehttp "GET /dataset/21 HTTP/1.1" 200 2063
WARNING 2019-05-01 14:33:49,347 basehttp "GET /static/css/styles.css HTTP/1.1" 404 1767
WARNING 2019-05-01 14:33:49,416 basehttp "GET /static/css/styles.css HTTP/1.1" 404 1767
INFO 2019-05-01 14:33:53,044 views user (root) want to update dataset (valid)
INFO 2019-05-01 14:33:53,168 basehttp "GET /dataset/21/update HTTP/1.1" 200 2027
WARNING 2019-05-01 14:33:53,312 basehttp "GET /static/css/styles.css HTTP/1.1" 404 1767
WARNING 2019-05-01 14:33:53,377 basehttp "GET /static/css/styles.css HTTP/1.1" 404 1767
WARNING 2019-05-01 14:33:58,353 log Not Found: /dataset/21/datasets/cryptowat_btcusd_lmyNrq4.csv
WARNING 2019-05-01 14:33:58,353 basehttp "GET /dataset/21/datasets/cryptowat_btcusd_lmyNrq4.csv HTTP/1.1" 404 3599
INFO 2019-05-01 14:34:32,383 basehttp "GET /dataset/ HTTP/1.1" 200 1729
WARNING 2019-05-01 14:34:32,518 basehttp "GET /static/css/styles.css HTTP/1.1" 404 1767
WARNING 2019-05-01 14:34:32,566 basehttp "GET /static/css/styles.css HTTP/1.1" 404 1767
INFO 2019-05-01 14:34:33,902 basehttp "GET /dataset/21 HTTP/1.1" 200 2063
WARNING 2019-05-01 14:34:34,034 basehttp "GET /static/css/styles.css HTTP/1.1" 404 1767
WARNING 2019-05-01 14:34:34,110 basehttp "GET /static/css/styles.css HTTP/1.1" 404 1767
INFO 2019-05-01 14:35:05,600 basehttp "GET /dataset/ HTTP/1.1" 200 1729
WARNING 2019-05-01 14:35:05,752 basehttp "GET /static/css/styles.css HTTP/1.1" 404 1767
WARNING 2019-05-01 14:35:05,810 basehttp "GET /static/css/styles.css HTTP/1.1" 404 1767
INFO 2019-05-01 14:36:26,305 basehttp "GET /dataset/ HTTP/1.1" 200 1732
WARNING 2019-05-01 14:36:26,428 basehttp "GET /static/css/styles.css HTTP/1.1" 404 1767
WARNING 2019-05-01 14:36:26,545 basehttp "GET /static/css/styles.css HTTP/1.1" 404 1767
INFO 2019-05-01 14:41:09,634 autoreload /home/maus/bsuir/kp/mysite/engine/tool.py changed, reloading.
INFO 2019-05-01 14:41:10,385 autoreload Watching for file changes with StatReloader
INFO 2019-05-01 15:48:11,780 autoreload Watching for file changes with StatReloader
INFO 2019-05-01 15:48:17,031 basehttp "GET /admin/ignis/dataset/ HTTP/1.1" 200 4777
INFO 2019-05-01 15:48:17,372 basehttp "GET /admin/jsi18n/ HTTP/1.1" 200 3223
INFO 2019-05-01 15:48:17,417 basehttp "GET /static/admin/js/jquery.init.js HTTP/1.1" 200 363
INFO 2019-05-01 15:48:17,433 basehttp "GET /static/admin/css/changelists.css HTTP/1.1" 200 6170
INFO 2019-05-01 15:48:17,449 basehttp "GET /static/admin/css/responsive.css HTTP/1.1" 200 17944
INFO 2019-05-01 15:48:17,517 basehttp "GET /static/admin/css/base.css HTTP/1.1" 200 16378
INFO 2019-05-01 15:48:17,518 basehttp "GET /static/admin/js/vendor/jquery/jquery.js HTTP/1.1" 304 0
INFO 2019-05-01 15:48:17,528 basehttp "GET /static/admin/css/fonts.css HTTP/1.1" 200 423
INFO 2019-05-01 15:48:17,531 basehttp "GET /static/admin/js/core.js HTTP/1.1" 304 0
INFO 2019-05-01 15:48:17,536 basehttp "GET /static/admin/js/admin/RelatedObjectLookups.js HTTP/1.1" 304 0
INFO 2019-05-01 15:48:17,538 basehttp "GET /static/admin/js/actions.js HTTP/1.1" 304 0
INFO 2019-05-01 15:48:17,540 basehttp "GET /static/admin/js/urlify.js HTTP/1.1" 304 0
INFO 2019-05-01 15:48:17,544 basehttp "GET /static/admin/js/prepopulate.js HTTP/1.1" 304 0
INFO 2019-05-01 15:48:17,557 basehttp "GET /static/admin/js/vendor/xregexp/xregexp.js HTTP/1.1" 304 0
INFO 2019-05-01 15:48:17,787 basehttp "GET /static/admin/img/tooltag-add.svg HTTP/1.1" 200 331
WARNING 2019-05-01 15:48:18,012 log Not Found: /favicon.ico
WARNING 2019-05-01 15:48:18,012 basehttp "GET /favicon.ico HTTP/1.1" 404 3488
INFO 2019-05-01 15:48:20,395 basehttp "GET /admin/ignis/ HTTP/1.1" 200 2432
INFO 2019-05-01 15:48:20,523 basehttp "GET /static/admin/css/responsive.css HTTP/1.1" 304 0
INFO 2019-05-01 15:48:20,723 basehttp "GET /static/admin/css/dashboard.css HTTP/1.1" 200 412
INFO 2019-05-01 15:48:20,794 basehttp "GET /static/admin/css/fonts.css HTTP/1.1" 304 0
INFO 2019-05-01 15:48:20,921 basehttp "GET /static/admin/img/icon-addlink.svg HTTP/1.1" 200 331
INFO 2019-05-01 15:48:20,922 basehttp "GET /static/admin/img/icon-changelink.svg HTTP/1.1" 200 380
INFO 2019-05-01 15:48:36,894 autoreload /home/maus/bsuir/kp/mysite/ignis/admin.py changed, reloading.
INFO 2019-05-01 15:48:41,862 autoreload Watching for file changes with StatReloader
INFO 2019-05-01 15:48:43,891 basehttp "GET /admin/ignis/ HTTP/1.1" 200 2841
INFO 2019-05-01 15:48:44,045 basehttp "GET /static/admin/css/base.css HTTP/1.1" 304 0
INFO 2019-05-01 15:48:44,046 basehttp "GET /static/admin/css/dashboard.css HTTP/1.1" 304 0
INFO 2019-05-01 15:48:44,046 basehttp "GET /static/admin/css/responsive.css HTTP/1.1" 304 0
INFO 2019-05-01 15:48:44,138 basehttp "GET /static/admin/css/fonts.css HTTP/1.1" 304 0
INFO 2019-05-01 15:48:44,300 basehttp "GET /static/admin/img/icon-addlink.svg HTTP/1.1" 304 0
INFO 2019-05-01 15:48:44,302 basehttp "GET /static/admin/img/icon-changelink.svg HTTP/1.1" 304 0
INFO 2019-05-01 15:48:47,201 basehttp "GET /admin/ignis/nn/ HTTP/1.1" 200 3136
INFO 2019-05-01 15:48:47,328 basehttp "GET /static/admin/js/jquery.init.js HTTP/1.1" 304 0
INFO 2019-05-01 15:48:47,363 basehttp "GET /admin/jsi18n/ HTTP/1.1" 200 3223
INFO 2019-05-01 15:48:49,825 basehttp "GET /admin/ignis/nn/add/ HTTP/1.1" 200 5645
INFO 2019-05-01 15:48:50,018 basehttp "GET /admin/jsi18n/ HTTP/1.1" 200 3223
INFO 2019-05-01 15:48:50,026 basehttp "GET /static/admin/js/calendar.js HTTP/1.1" 200 7777
INFO 2019-05-01 15:48:50,031 basehttp "GET /static/admin/css/forms.css HTTP/1.1" 200 8518
INFO 2019-05-01 15:48:50,139 basehttp "GET /static/admin/js/admin/DateTimeShortcuts.js HTTP/1.1" 200 20274
INFO 2019-05-01 15:48:50,153 basehttp "GET /static/admin/js/change_form.js HTTP/1.1" 200 712
INFO 2019-05-01 15:48:50,154 basehttp "GET /static/admin/js/prepopulate_init.js HTTP/1.1" 200 495
INFO 2019-05-01 15:48:50,164 basehttp "GET /static/admin/css/widgets.css HTTP/1.1" 200 10340
INFO 2019-05-01 15:48:50,404 basehttp "GET /static/admin/img/icon-calendar.svg HTTP/1.1" 200 1086
INFO 2019-05-01 15:48:50,407 basehttp "GET /static/admin/img/icon-clock.svg HTTP/1.1" 200 677
INFO 2019-05-01 15:48:55,886 basehttp "POST /admin/ignis/nn/add/ HTTP/1.1" 302 0
INFO 2019-05-01 15:48:56,020 basehttp "GET /admin/ignis/nn/ HTTP/1.1" 200 4469
INFO 2019-05-01 15:48:56,186 basehttp "GET /admin/jsi18n/ HTTP/1.1" 200 3223
INFO 2019-05-01 15:48:56,335 basehttp "GET /static/admin/img/icon-yes.svg HTTP/1.1" 200 436
INFO 2019-05-01 15:48:59,761 basehttp "GET /admin/ignis/nn/add/ HTTP/1.1" 200 5645
INFO 2019-05-01 15:48:59,905 basehttp "GET /static/admin/js/calendar.js HTTP/1.1" 304 0
INFO 2019-05-01 15:48:59,919 basehttp "GET /admin/jsi18n/ HTTP/1.1" 200 3223
INFO 2019-05-01 15:49:00,210 basehttp "GET /static/admin/img/icon-clock.svg HTTP/1.1" 200 677
INFO 2019-05-01 15:49:03,964 basehttp "POST /admin/ignis/nn/add/ HTTP/1.1" 200 5801
INFO 2019-05-01 15:49:04,101 basehttp "GET /admin/jsi18n/ HTTP/1.1" 200 3223
INFO 2019-05-01 15:49:04,352 basehttp "GET /static/admin/img/icon-clock.svg HTTP/1.1" 304 0
INFO 2019-05-01 15:49:21,960 autoreload /home/maus/bsuir/kp/mysite/ignis/models.py changed, reloading.
INFO 2019-05-01 15:49:33,324 autoreload Watching for file changes with StatReloader
INFO 2019-05-01 15:49:38,268 basehttp "POST /admin/ignis/nn/add/ HTTP/1.1" 302 0
INFO 2019-05-01 15:49:38,378 basehttp "GET /admin/ignis/nn/ HTTP/1.1" 200 4691
INFO 2019-05-01 15:49:38,537 basehttp "GET /static/admin/css/changelists.css HTTP/1.1" 304 0
INFO 2019-05-01 15:49:38,538 basehttp "GET /static/admin/css/base.css HTTP/1.1" 304 0
INFO 2019-05-01 15:49:38,543 basehttp "GET /static/admin/js/vendor/jquery/jquery.js HTTP/1.1" 304 0
INFO 2019-05-01 15:49:38,548 basehttp "GET /static/admin/js/admin/RelatedObjectLookups.js HTTP/1.1" 304 0
INFO 2019-05-01 15:49:38,549 basehttp "GET /static/admin/js/actions.js HTTP/1.1" 304 0
INFO 2019-05-01 15:49:38,552 basehttp "GET /static/admin/js/urlify.js HTTP/1.1" 304 0
INFO 2019-05-01 15:49:38,555 basehttp "GET /static/admin/js/jquery.init.js HTTP/1.1" 304 0
INFO 2019-05-01 15:49:38,559 basehttp "GET /admin/jsi18n/ HTTP/1.1" 200 3223
INFO 2019-05-01 15:49:38,562 basehttp "GET /static/admin/js/core.js HTTP/1.1" 304 0
INFO 2019-05-01 15:49:38,567 basehttp "GET /static/admin/css/responsive.css HTTP/1.1" 304 0
INFO 2019-05-01 15:49:38,567 basehttp "GET /static/admin/js/vendor/xregexp/xregexp.js HTTP/1.1" 304 0
INFO 2019-05-01 15:49:38,568 basehttp "GET /static/admin/js/prepopulate.js HTTP/1.1" 304 0
INFO 2019-05-01 15:49:38,622 basehttp "GET /static/admin/css/fonts.css HTTP/1.1" 304 0
INFO 2019-05-01 15:49:38,757 basehttp "GET /static/admin/img/icon-yes.svg HTTP/1.1" 304 0
INFO 2019-05-01 15:49:38,776 basehttp "GET /static/admin/img/tooltag-add.svg HTTP/1.1" 200 331
INFO 2019-05-01 15:49:40,558 basehttp "GET /admin/ignis/nn/2/change/ HTTP/1.1" 200 5861
INFO 2019-05-01 15:49:40,721 basehttp "GET /admin/jsi18n/ HTTP/1.1" 200 3223
INFO 2019-05-01 15:49:41,771 basehttp "GET /admin/ignis/nn/ HTTP/1.1" 200 4513
INFO 2019-05-01 15:49:43,354 basehttp "GET /admin/ignis/nn/1/change/ HTTP/1.1" 200 5861
INFO 2019-05-01 15:49:43,513 basehttp "GET /admin/jsi18n/ HTTP/1.1" 200 3223
INFO 2019-05-01 15:49:44,474 basehttp "GET /admin/ignis/nn/ HTTP/1.1" 200 4513
INFO 2019-05-01 15:50:04,901 autoreload /home/maus/bsuir/kp/mysite/ignis/models.py changed, reloading.
INFO 2019-05-01 15:50:06,242 autoreload Watching for file changes with StatReloader
INFO 2019-05-01 15:50:28,336 autoreload /home/maus/bsuir/kp/mysite/ignis/models.py changed, reloading.
INFO 2019-05-01 15:50:28,967 autoreload Watching for file changes with StatReloader
INFO 2019-05-01 15:50:35,435 autoreload /home/maus/bsuir/kp/mysite/ignis/models.py changed, reloading.
INFO 2019-05-01 15:50:36,042 autoreload Watching for file changes with StatReloader
INFO 2019-05-01 15:50:59,186 autoreload /home/maus/bsuir/kp/mysite/engine/tool.py changed, reloading.
INFO 2019-05-01 15:50:59,800 autoreload Watching for file changes with StatReloader
INFO 2019-05-01 15:55:24,555 autoreload /home/maus/bsuir/kp/mysite/ignis/urls.py changed, reloading.
INFO 2019-05-01 15:55:25,315 autoreload Watching for file changes with StatReloader
INFO 2019-05-01 15:55:45,405 autoreload /home/maus/bsuir/kp/mysite/ignis/urls.py changed, reloading.
INFO 2019-05-01 15:55:46,081 autoreload Watching for file changes with StatReloader
INFO 2019-05-01 15:56:30,212 autoreload /home/maus/bsuir/kp/mysite/ignis/views.py changed, reloading.
INFO 2019-05-01 15:56:30,896 autoreload Watching for file changes with StatReloader
INFO 2019-05-01 15:56:33,186 autoreload /home/maus/bsuir/kp/mysite/ignis/views.py changed, reloading.
INFO 2019-05-01 15:56:33,932 autoreload Watching for file changes with StatReloader
INFO 2019-05-01 15:56:38,306 autoreload /home/maus/bsuir/kp/mysite/ignis/views.py changed, reloading.
INFO 2019-05-01 15:56:39,079 autoreload Watching for file changes with StatReloader
INFO 2019-05-01 15:56:51,788 autoreload /home/maus/bsuir/kp/mysite/ignis/views.py changed, reloading.
INFO 2019-05-01 15:56:52,493 autoreload Watching for file changes with StatReloader
INFO 2019-05-01 15:56:54,825 autoreload /home/maus/bsuir/kp/mysite/ignis/views.py changed, reloading.
INFO 2019-05-01 15:56:55,521 autoreload Watching for file changes with StatReloader
INFO 2019-05-01 15:56:57,793 autoreload /home/maus/bsuir/kp/mysite/ignis/views.py changed, reloading.
INFO 2019-05-01 15:56:58,624 autoreload Watching for file changes with StatReloader
INFO 2019-05-01 15:57:05,036 autoreload /home/maus/bsuir/kp/mysite/ignis/views.py changed, reloading.
INFO 2019-05-01 15:57:05,703 autoreload Watching for file changes with StatReloader
INFO 2019-05-01 15:57:13,165 autoreload /home/maus/bsuir/kp/mysite/ignis/views.py changed, reloading.
INFO 2019-05-01 15:57:13,834 autoreload Watching for file changes with StatReloader
INFO 2019-05-01 15:57:21,319 autoreload /home/maus/bsuir/kp/mysite/ignis/views.py changed, reloading.
INFO 2019-05-01 15:57:22,012 autoreload Watching for file changes with StatReloader
INFO 2019-05-01 15:57:28,435 autoreload /home/maus/bsuir/kp/mysite/ignis/views.py changed, reloading.
INFO 2019-05-01 15:57:29,198 autoreload Watching for file changes with StatReloader
INFO 2019-05-01 15:57:34,570 autoreload /home/maus/bsuir/kp/mysite/ignis/views.py changed, reloading.
INFO 2019-05-01 15:57:35,248 autoreload Watching for file changes with StatReloader
INFO 2019-05-01 15:57:55,286 autoreload /home/maus/bsuir/kp/mysite/ignis/models.py changed, reloading.
INFO 2019-05-01 15:57:55,961 autoreload Watching for file changes with StatReloader
INFO 2019-05-01 15:58:10,751 autoreload /home/maus/bsuir/kp/mysite/ignis/views.py changed, reloading.
INFO 2019-05-01 15:58:11,403 autoreload Watching for file changes with StatReloader
INFO 2019-05-01 15:58:13,691 autoreload /home/maus/bsuir/kp/mysite/ignis/views.py changed, reloading.
INFO 2019-05-01 15:58:14,453 autoreload Watching for file changes with StatReloader
INFO 2019-05-01 15:58:18,787 autoreload /home/maus/bsuir/kp/mysite/ignis/views.py changed, reloading.
INFO 2019-05-01 15:58:19,461 autoreload Watching for file changes with StatReloader
INFO 2019-05-01 15:58:24,858 autoreload /home/maus/bsuir/kp/mysite/ignis/views.py changed, reloading.
INFO 2019-05-01 15:58:25,732 autoreload Watching for file changes with StatReloader
INFO 2019-05-01 15:58:30,060 autoreload /home/maus/bsuir/kp/mysite/ignis/views.py changed, reloading.
INFO 2019-05-01 15:58:30,754 autoreload Watching for file changes with StatReloader
INFO 2019-05-01 15:58:33,020 autoreload /home/maus/bsuir/kp/mysite/ignis/views.py changed, reloading.
INFO 2019-05-01 15:58:33,672 autoreload Watching for file changes with StatReloader
INFO 2019-05-01 15:58:50,534 autoreload /home/maus/bsuir/kp/mysite/ignis/views.py changed, reloading.
INFO 2019-05-01 15:58:51,439 autoreload Watching for file changes with StatReloader
INFO 2019-05-01 15:59:24,150 autoreload /home/maus/bsuir/kp/mysite/ignis/views.py changed, reloading.
INFO 2019-05-01 15:59:24,847 autoreload Watching for file changes with StatReloader
INFO 2019-05-01 15:59:47,981 autoreload /home/maus/bsuir/kp/mysite/ignis/views.py changed, reloading.
INFO 2019-05-01 15:59:48,687 autoreload Watching for file changes with StatReloader
INFO 2019-05-01 15:59:54,073 autoreload /home/maus/bsuir/kp/mysite/ignis/views.py changed, reloading.
INFO 2019-05-01 15:59:54,794 autoreload Watching for file changes with StatReloader
INFO 2019-05-01 16:00:03,341 autoreload /home/maus/bsuir/kp/mysite/ignis/views.py changed, reloading.
INFO 2019-05-01 16:00:04,021 autoreload Watching for file changes with StatReloader
INFO 2019-05-01 16:00:05,244 autoreload /home/maus/bsuir/kp/mysite/ignis/views.py changed, reloading.
INFO 2019-05-01 16:00:05,930 autoreload Watching for file changes with StatReloader
INFO 2019-05-01 16:00:09,221 autoreload /home/maus/bsuir/kp/mysite/ignis/views.py changed, reloading.
INFO 2019-05-01 16:00:09,896 autoreload Watching for file changes with StatReloader
INFO 2019-05-01 16:00:11,139 autoreload /home/maus/bsuir/kp/mysite/ignis/views.py changed, reloading.
INFO 2019-05-01 16:00:11,918 autoreload Watching for file changes with StatReloader
INFO 2019-05-01 16:00:15,275 autoreload /home/maus/bsuir/kp/mysite/ignis/views.py changed, reloading.
INFO 2019-05-01 16:00:16,008 autoreload Watching for file changes with StatReloader
INFO 2019-05-01 16:00:18,319 autoreload /home/maus/bsuir/kp/mysite/ignis/views.py changed, reloading.
INFO 2019-05-01 16:00:19,128 autoreload Watching for file changes with StatReloader
INFO 2019-05-01 16:00:20,403 autoreload /home/maus/bsuir/kp/mysite/ignis/views.py changed, reloading.
INFO 2019-05-01 16:00:21,075 autoreload Watching for file changes with StatReloader
INFO 2019-05-01 16:00:23,371 autoreload /home/maus/bsuir/kp/mysite/ignis/views.py changed, reloading.
INFO 2019-05-01 16:00:24,331 autoreload Watching for file changes with StatReloader
INFO 2019-05-01 16:00:29,700 autoreload /home/maus/bsuir/kp/mysite/ignis/views.py changed, reloading.
INFO 2019-05-01 16:00:30,543 autoreload Watching for file changes with StatReloader
INFO 2019-05-01 16:00:39,144 autoreload /home/maus/bsuir/kp/mysite/ignis/views.py changed, reloading.
INFO 2019-05-01 16:00:39,841 autoreload Watching for file changes with StatReloader
INFO 2019-05-01 16:00:44,183 autoreload /home/maus/bsuir/kp/mysite/ignis/views.py changed, reloading.
INFO 2019-05-01 16:00:44,819 autoreload Watching for file changes with StatReloader
INFO 2019-05-01 16:00:48,137 autoreload /home/maus/bsuir/kp/mysite/ignis/views.py changed, reloading.
INFO 2019-05-01 16:00:48,801 autoreload Watching for file changes with StatReloader
INFO 2019-05-01 16:00:52,088 autoreload /home/maus/bsuir/kp/mysite/ignis/views.py changed, reloading.
INFO 2019-05-01 16:00:52,741 autoreload Watching for file changes with StatReloader
INFO 2019-05-01 16:01:06,470 autoreload /home/maus/bsuir/kp/mysite/ignis/views.py changed, reloading.
INFO 2019-05-01 16:01:07,212 autoreload Watching for file changes with StatReloader
INFO 2019-05-01 16:05:36,384 autoreload /home/maus/bsuir/kp/mysite/ignis/models.py changed, reloading.
INFO 2019-05-01 16:05:37,896 autoreload Watching for file changes with StatReloader
INFO 2019-05-01 16:07:52,342 autoreload /home/maus/bsuir/kp/mysite/ignis/forms.py changed, reloading.
INFO 2019-05-01 16:07:53,480 autoreload Watching for file changes with StatReloader
INFO 2019-05-01 16:08:46,762 autoreload /home/maus/bsuir/kp/mysite/ignis/models.py changed, reloading.
INFO 2019-05-01 16:08:47,391 autoreload Watching for file changes with StatReloader
ERROR 2019-05-01 16:09:43,837 log Internal Server Error: /admin/ignis/nn/
Traceback (most recent call last):
  File "/home/maus/.local/share/virtualenvs/kp-3crlKS4c/lib/python3.7/site-packages/django/db/backends/utils.py", line 84, in _execute
    return self.cursor.execute(sql, params)
psycopg2.errors.UndefinedColumn: column ignis_nn.name does not exist
LINE 1: SELECT "ignis_nn"."id", "ignis_nn"."name", "ignis_nn"."date"...
                                ^
HINT:  Perhaps you meant to reference the column "ignis_nn.date".


The above exception was the direct cause of the following exception:

Traceback (most recent call last):
  File "/home/maus/.local/share/virtualenvs/kp-3crlKS4c/lib/python3.7/site-packages/django/core/handlers/exception.py", line 34, in inner
    response = get_response(request)
  File "/home/maus/.local/share/virtualenvs/kp-3crlKS4c/lib/python3.7/site-packages/django/core/handlers/base.py", line 115, in _get_response
    response = self.process_exception_by_middleware(e, request)
  File "/home/maus/.local/share/virtualenvs/kp-3crlKS4c/lib/python3.7/site-packages/django/core/handlers/base.py", line 113, in _get_response
    response = wrapped_callback(request, *callback_args, **callback_kwargs)
  File "/home/maus/.local/share/virtualenvs/kp-3crlKS4c/lib/python3.7/site-packages/django/contrib/admin/options.py", line 606, in wrapper
    return self.admin_site.admin_view(view)(*args, **kwargs)
  File "/home/maus/.local/share/virtualenvs/kp-3crlKS4c/lib/python3.7/site-packages/django/utils/decorators.py", line 142, in _wrapped_view
    response = view_func(request, *args, **kwargs)
  File "/home/maus/.local/share/virtualenvs/kp-3crlKS4c/lib/python3.7/site-packages/django/views/decorators/cache.py", line 44, in _wrapped_view_func
    response = view_func(request, *args, **kwargs)
  File "/home/maus/.local/share/virtualenvs/kp-3crlKS4c/lib/python3.7/site-packages/django/contrib/admin/sites.py", line 223, in inner
    return view(request, *args, **kwargs)
  File "/home/maus/.local/share/virtualenvs/kp-3crlKS4c/lib/python3.7/site-packages/django/utils/decorators.py", line 45, in _wrapper
    return bound_method(*args, **kwargs)
  File "/home/maus/.local/share/virtualenvs/kp-3crlKS4c/lib/python3.7/site-packages/django/utils/decorators.py", line 142, in _wrapped_view
    response = view_func(request, *args, **kwargs)
  File "/home/maus/.local/share/virtualenvs/kp-3crlKS4c/lib/python3.7/site-packages/django/contrib/admin/options.py", line 1698, in changelist_view
    response = self.response_action(request, queryset=cl.get_queryset(request))
  File "/home/maus/.local/share/virtualenvs/kp-3crlKS4c/lib/python3.7/site-packages/django/contrib/admin/options.py", line 1397, in response_action
    response = func(self, request, queryset)
  File "/home/maus/.local/share/virtualenvs/kp-3crlKS4c/lib/python3.7/site-packages/django/contrib/admin/actions.py", line 28, in delete_selected
    deletable_objects, model_count, perms_needed, protected = modeladmin.get_deleted_objects(queryset, request)
  File "/home/maus/.local/share/virtualenvs/kp-3crlKS4c/lib/python3.7/site-packages/django/contrib/admin/options.py", line 1820, in get_deleted_objects
    return get_deleted_objects(objs, request, self.admin_site)
  File "/home/maus/.local/share/virtualenvs/kp-3crlKS4c/lib/python3.7/site-packages/django/contrib/admin/utils.py", line 112, in get_deleted_objects
    obj = objs[0]
  File "/home/maus/.local/share/virtualenvs/kp-3crlKS4c/lib/python3.7/site-packages/django/db/models/query.py", line 308, in __getitem__
    qs._fetch_all()
  File "/home/maus/.local/share/virtualenvs/kp-3crlKS4c/lib/python3.7/site-packages/django/db/models/query.py", line 1242, in _fetch_all
    self._result_cache = list(self._iterable_class(self))
  File "/home/maus/.local/share/virtualenvs/kp-3crlKS4c/lib/python3.7/site-packages/django/db/models/query.py", line 55, in __iter__
    results = compiler.execute_sql(chunked_fetch=self.chunked_fetch, chunk_size=self.chunk_size)
  File "/home/maus/.local/share/virtualenvs/kp-3crlKS4c/lib/python3.7/site-packages/django/db/models/sql/compiler.py", line 1100, in execute_sql
    cursor.execute(sql, params)
  File "/home/maus/.local/share/virtualenvs/kp-3crlKS4c/lib/python3.7/site-packages/django/db/backends/utils.py", line 99, in execute
    return super().execute(sql, params)
  File "/home/maus/.local/share/virtualenvs/kp-3crlKS4c/lib/python3.7/site-packages/django/db/backends/utils.py", line 67, in execute
    return self._execute_with_wrappers(sql, params, many=False, executor=self._execute)
  File "/home/maus/.local/share/virtualenvs/kp-3crlKS4c/lib/python3.7/site-packages/django/db/backends/utils.py", line 76, in _execute_with_wrappers
    return executor(sql, params, many, context)
  File "/home/maus/.local/share/virtualenvs/kp-3crlKS4c/lib/python3.7/site-packages/django/db/backends/utils.py", line 84, in _execute
    return self.cursor.execute(sql, params)
  File "/home/maus/.local/share/virtualenvs/kp-3crlKS4c/lib/python3.7/site-packages/django/db/utils.py", line 89, in __exit__
    raise dj_exc_value.with_traceback(traceback) from exc_value
  File "/home/maus/.local/share/virtualenvs/kp-3crlKS4c/lib/python3.7/site-packages/django/db/backends/utils.py", line 84, in _execute
    return self.cursor.execute(sql, params)
django.db.utils.ProgrammingError: column ignis_nn.name does not exist
LINE 1: SELECT "ignis_nn"."id", "ignis_nn"."name", "ignis_nn"."date"...
                                ^
HINT:  Perhaps you meant to reference the column "ignis_nn.date".

ERROR 2019-05-01 16:09:43,847 basehttp "POST /admin/ignis/nn/ HTTP/1.1" 500 180744
INFO 2019-05-01 16:09:59,978 autoreload Watching for file changes with StatReloader
ERROR 2019-05-01 16:10:04,223 log Internal Server Error: /admin/ignis/nn/
Traceback (most recent call last):
  File "/home/maus/.local/share/virtualenvs/kp-3crlKS4c/lib/python3.7/site-packages/django/db/backends/utils.py", line 84, in _execute
    return self.cursor.execute(sql, params)
psycopg2.errors.UndefinedColumn: column ignis_nn.name does not exist
LINE 1: SELECT "ignis_nn"."id", "ignis_nn"."name", "ignis_nn"."date"...
                                ^
HINT:  Perhaps you meant to reference the column "ignis_nn.date".


The above exception was the direct cause of the following exception:

Traceback (most recent call last):
  File "/home/maus/.local/share/virtualenvs/kp-3crlKS4c/lib/python3.7/site-packages/django/core/handlers/exception.py", line 34, in inner
    response = get_response(request)
  File "/home/maus/.local/share/virtualenvs/kp-3crlKS4c/lib/python3.7/site-packages/django/core/handlers/base.py", line 115, in _get_response
    response = self.process_exception_by_middleware(e, request)
  File "/home/maus/.local/share/virtualenvs/kp-3crlKS4c/lib/python3.7/site-packages/django/core/handlers/base.py", line 113, in _get_response
    response = wrapped_callback(request, *callback_args, **callback_kwargs)
  File "/home/maus/.local/share/virtualenvs/kp-3crlKS4c/lib/python3.7/site-packages/django/contrib/admin/options.py", line 606, in wrapper
    return self.admin_site.admin_view(view)(*args, **kwargs)
  File "/home/maus/.local/share/virtualenvs/kp-3crlKS4c/lib/python3.7/site-packages/django/utils/decorators.py", line 142, in _wrapped_view
    response = view_func(request, *args, **kwargs)
  File "/home/maus/.local/share/virtualenvs/kp-3crlKS4c/lib/python3.7/site-packages/django/views/decorators/cache.py", line 44, in _wrapped_view_func
    response = view_func(request, *args, **kwargs)
  File "/home/maus/.local/share/virtualenvs/kp-3crlKS4c/lib/python3.7/site-packages/django/contrib/admin/sites.py", line 223, in inner
    return view(request, *args, **kwargs)
  File "/home/maus/.local/share/virtualenvs/kp-3crlKS4c/lib/python3.7/site-packages/django/utils/decorators.py", line 45, in _wrapper
    return bound_method(*args, **kwargs)
  File "/home/maus/.local/share/virtualenvs/kp-3crlKS4c/lib/python3.7/site-packages/django/utils/decorators.py", line 142, in _wrapped_view
    response = view_func(request, *args, **kwargs)
  File "/home/maus/.local/share/virtualenvs/kp-3crlKS4c/lib/python3.7/site-packages/django/contrib/admin/options.py", line 1698, in changelist_view
    response = self.response_action(request, queryset=cl.get_queryset(request))
  File "/home/maus/.local/share/virtualenvs/kp-3crlKS4c/lib/python3.7/site-packages/django/contrib/admin/options.py", line 1397, in response_action
    response = func(self, request, queryset)
  File "/home/maus/.local/share/virtualenvs/kp-3crlKS4c/lib/python3.7/site-packages/django/contrib/admin/actions.py", line 28, in delete_selected
    deletable_objects, model_count, perms_needed, protected = modeladmin.get_deleted_objects(queryset, request)
  File "/home/maus/.local/share/virtualenvs/kp-3crlKS4c/lib/python3.7/site-packages/django/contrib/admin/options.py", line 1820, in get_deleted_objects
    return get_deleted_objects(objs, request, self.admin_site)
  File "/home/maus/.local/share/virtualenvs/kp-3crlKS4c/lib/python3.7/site-packages/django/contrib/admin/utils.py", line 112, in get_deleted_objects
    obj = objs[0]
  File "/home/maus/.local/share/virtualenvs/kp-3crlKS4c/lib/python3.7/site-packages/django/db/models/query.py", line 308, in __getitem__
    qs._fetch_all()
  File "/home/maus/.local/share/virtualenvs/kp-3crlKS4c/lib/python3.7/site-packages/django/db/models/query.py", line 1242, in _fetch_all
    self._result_cache = list(self._iterable_class(self))
  File "/home/maus/.local/share/virtualenvs/kp-3crlKS4c/lib/python3.7/site-packages/django/db/models/query.py", line 55, in __iter__
    results = compiler.execute_sql(chunked_fetch=self.chunked_fetch, chunk_size=self.chunk_size)
  File "/home/maus/.local/share/virtualenvs/kp-3crlKS4c/lib/python3.7/site-packages/django/db/models/sql/compiler.py", line 1100, in execute_sql
    cursor.execute(sql, params)
  File "/home/maus/.local/share/virtualenvs/kp-3crlKS4c/lib/python3.7/site-packages/django/db/backends/utils.py", line 99, in execute
    return super().execute(sql, params)
  File "/home/maus/.local/share/virtualenvs/kp-3crlKS4c/lib/python3.7/site-packages/django/db/backends/utils.py", line 67, in execute
    return self._execute_with_wrappers(sql, params, many=False, executor=self._execute)
  File "/home/maus/.local/share/virtualenvs/kp-3crlKS4c/lib/python3.7/site-packages/django/db/backends/utils.py", line 76, in _execute_with_wrappers
    return executor(sql, params, many, context)
  File "/home/maus/.local/share/virtualenvs/kp-3crlKS4c/lib/python3.7/site-packages/django/db/backends/utils.py", line 84, in _execute
    return self.cursor.execute(sql, params)
  File "/home/maus/.local/share/virtualenvs/kp-3crlKS4c/lib/python3.7/site-packages/django/db/utils.py", line 89, in __exit__
    raise dj_exc_value.with_traceback(traceback) from exc_value
  File "/home/maus/.local/share/virtualenvs/kp-3crlKS4c/lib/python3.7/site-packages/django/db/backends/utils.py", line 84, in _execute
    return self.cursor.execute(sql, params)
django.db.utils.ProgrammingError: column ignis_nn.name does not exist
LINE 1: SELECT "ignis_nn"."id", "ignis_nn"."name", "ignis_nn"."date"...
                                ^
HINT:  Perhaps you meant to reference the column "ignis_nn.date".

ERROR 2019-05-01 16:10:04,225 basehttp "POST /admin/ignis/nn/ HTTP/1.1" 500 180880
INFO 2019-05-01 16:15:55,714 autoreload Watching for file changes with StatReloader
INFO 2019-05-01 16:16:04,446 basehttp "GET /admin/ HTTP/1.1" 200 6647
INFO 2019-05-01 16:16:05,316 basehttp "GET /static/admin/img/icon-deletelink.svg HTTP/1.1" 200 392
INFO 2019-05-01 16:16:05,545 basehttp "GET /static/admin/fonts/Roboto-Light-webfont.woff HTTP/1.1" 200 85692
INFO 2019-05-01 16:16:05,546 basehttp "GET /static/admin/fonts/Roboto-Bold-webfont.woff HTTP/1.1" 200 86184
INFO 2019-05-01 16:16:05,553 basehttp "GET /static/admin/fonts/Roboto-Regular-webfont.woff HTTP/1.1" 200 85876
ERROR 2019-05-01 16:16:08,365 log Internal Server Error: /admin/ignis/nn/
Traceback (most recent call last):
  File "/home/maus/.local/share/virtualenvs/kp-3crlKS4c/lib/python3.7/site-packages/django/db/backends/utils.py", line 84, in _execute
    return self.cursor.execute(sql, params)
psycopg2.errors.UndefinedTable: relation "ignis_nn" does not exist
LINE 1: SELECT COUNT(*) AS "__count" FROM "ignis_nn"
                                          ^


The above exception was the direct cause of the following exception:

Traceback (most recent call last):
  File "/home/maus/.local/share/virtualenvs/kp-3crlKS4c/lib/python3.7/site-packages/django/core/handlers/exception.py", line 34, in inner
    response = get_response(request)
  File "/home/maus/.local/share/virtualenvs/kp-3crlKS4c/lib/python3.7/site-packages/django/core/handlers/base.py", line 115, in _get_response
    response = self.process_exception_by_middleware(e, request)
  File "/home/maus/.local/share/virtualenvs/kp-3crlKS4c/lib/python3.7/site-packages/django/core/handlers/base.py", line 113, in _get_response
    response = wrapped_callback(request, *callback_args, **callback_kwargs)
  File "/home/maus/.local/share/virtualenvs/kp-3crlKS4c/lib/python3.7/site-packages/django/contrib/admin/options.py", line 606, in wrapper
    return self.admin_site.admin_view(view)(*args, **kwargs)
  File "/home/maus/.local/share/virtualenvs/kp-3crlKS4c/lib/python3.7/site-packages/django/utils/decorators.py", line 142, in _wrapped_view
    response = view_func(request, *args, **kwargs)
  File "/home/maus/.local/share/virtualenvs/kp-3crlKS4c/lib/python3.7/site-packages/django/views/decorators/cache.py", line 44, in _wrapped_view_func
    response = view_func(request, *args, **kwargs)
  File "/home/maus/.local/share/virtualenvs/kp-3crlKS4c/lib/python3.7/site-packages/django/contrib/admin/sites.py", line 223, in inner
    return view(request, *args, **kwargs)
  File "/home/maus/.local/share/virtualenvs/kp-3crlKS4c/lib/python3.7/site-packages/django/utils/decorators.py", line 45, in _wrapper
    return bound_method(*args, **kwargs)
  File "/home/maus/.local/share/virtualenvs/kp-3crlKS4c/lib/python3.7/site-packages/django/utils/decorators.py", line 142, in _wrapped_view
    response = view_func(request, *args, **kwargs)
  File "/home/maus/.local/share/virtualenvs/kp-3crlKS4c/lib/python3.7/site-packages/django/contrib/admin/options.py", line 1672, in changelist_view
    cl = self.get_changelist_instance(request)
  File "/home/maus/.local/share/virtualenvs/kp-3crlKS4c/lib/python3.7/site-packages/django/contrib/admin/options.py", line 744, in get_changelist_instance
    sortable_by,
  File "/home/maus/.local/share/virtualenvs/kp-3crlKS4c/lib/python3.7/site-packages/django/contrib/admin/views/main.py", line 82, in __init__
    self.get_results(request)
  File "/home/maus/.local/share/virtualenvs/kp-3crlKS4c/lib/python3.7/site-packages/django/contrib/admin/views/main.py", line 210, in get_results
    result_count = paginator.count
  File "/home/maus/.local/share/virtualenvs/kp-3crlKS4c/lib/python3.7/site-packages/django/utils/functional.py", line 80, in __get__
    res = instance.__dict__[self.name] = self.func(instance)
  File "/home/maus/.local/share/virtualenvs/kp-3crlKS4c/lib/python3.7/site-packages/django/core/paginator.py", line 91, in count
    return c()
  File "/home/maus/.local/share/virtualenvs/kp-3crlKS4c/lib/python3.7/site-packages/django/db/models/query.py", line 392, in count
    return self.query.get_count(using=self.db)
  File "/home/maus/.local/share/virtualenvs/kp-3crlKS4c/lib/python3.7/site-packages/django/db/models/sql/query.py", line 504, in get_count
    number = obj.get_aggregation(using, ['__count'])['__count']
  File "/home/maus/.local/share/virtualenvs/kp-3crlKS4c/lib/python3.7/site-packages/django/db/models/sql/query.py", line 489, in get_aggregation
    result = compiler.execute_sql(SINGLE)
  File "/home/maus/.local/share/virtualenvs/kp-3crlKS4c/lib/python3.7/site-packages/django/db/models/sql/compiler.py", line 1100, in execute_sql
    cursor.execute(sql, params)
  File "/home/maus/.local/share/virtualenvs/kp-3crlKS4c/lib/python3.7/site-packages/django/db/backends/utils.py", line 99, in execute
    return super().execute(sql, params)
  File "/home/maus/.local/share/virtualenvs/kp-3crlKS4c/lib/python3.7/site-packages/django/db/backends/utils.py", line 67, in execute
    return self._execute_with_wrappers(sql, params, many=False, executor=self._execute)
  File "/home/maus/.local/share/virtualenvs/kp-3crlKS4c/lib/python3.7/site-packages/django/db/backends/utils.py", line 76, in _execute_with_wrappers
    return executor(sql, params, many, context)
  File "/home/maus/.local/share/virtualenvs/kp-3crlKS4c/lib/python3.7/site-packages/django/db/backends/utils.py", line 84, in _execute
    return self.cursor.execute(sql, params)
  File "/home/maus/.local/share/virtualenvs/kp-3crlKS4c/lib/python3.7/site-packages/django/db/utils.py", line 89, in __exit__
    raise dj_exc_value.with_traceback(traceback) from exc_value
  File "/home/maus/.local/share/virtualenvs/kp-3crlKS4c/lib/python3.7/site-packages/django/db/backends/utils.py", line 84, in _execute
    return self.cursor.execute(sql, params)
django.db.utils.ProgrammingError: relation "ignis_nn" does not exist
LINE 1: SELECT COUNT(*) AS "__count" FROM "ignis_nn"
                                          ^

ERROR 2019-05-01 16:16:08,368 basehttp "GET /admin/ignis/nn/ HTTP/1.1" 500 178166
INFO 2019-05-01 16:17:43,840 autoreload Watching for file changes with StatReloader
INFO 2019-05-01 16:17:49,416 basehttp "GET /admin/ignis/nn/ HTTP/1.1" 302 0
INFO 2019-05-01 16:17:49,883 basehttp "GET /admin/login/?next=/admin/ignis/nn/ HTTP/1.1" 200 1837
INFO 2019-05-01 16:17:50,510 basehttp "GET /static/admin/css/base.css HTTP/1.1" 304 0
INFO 2019-05-01 16:17:50,511 basehttp "GET /static/admin/css/responsive.css HTTP/1.1" 304 0
INFO 2019-05-01 16:17:50,531 basehttp "GET /static/admin/css/fonts.css HTTP/1.1" 304 0
INFO 2019-05-01 16:17:50,546 basehttp "GET /static/admin/css/login.css HTTP/1.1" 200 1233
INFO 2019-05-01 16:17:56,860 basehttp "POST /admin/login/?next=/admin/ignis/nn/ HTTP/1.1" 200 1997
INFO 2019-05-01 16:17:57,012 basehttp "GET /static/admin/css/login.css HTTP/1.1" 304 0
INFO 2019-05-01 16:17:57,089 basehttp "GET /static/admin/fonts/Roboto-Regular-webfont.woff HTTP/1.1" 200 8192
INFO 2019-05-01 16:17:57,099 basehttp "GET /static/admin/fonts/Roboto-Light-webfont.woff HTTP/1.1" 200 8192
INFO 2019-05-01 16:17:57,100 basehttp "GET /static/admin/fonts/Roboto-Bold-webfont.woff HTTP/1.1" 200 8192
INFO 2019-05-01 16:18:14,063 autoreload Watching for file changes with StatReloader
INFO 2019-05-01 16:18:17,655 basehttp "POST /admin/login/?next=/admin/ignis/nn/ HTTP/1.1" 302 0
INFO 2019-05-01 16:18:17,768 basehttp "GET /admin/ignis/nn/ HTTP/1.1" 200 3136
INFO 2019-05-01 16:18:18,038 basehttp "GET /admin/jsi18n/ HTTP/1.1" 200 3223
INFO 2019-05-01 16:18:18,330 basehttp "GET /static/admin/img/tooltag-add.svg HTTP/1.1" 200 331
INFO 2019-05-01 16:18:23,432 basehttp "GET /admin/ignis/nn/add/ HTTP/1.1" 200 7972
INFO 2019-05-01 16:18:23,572 basehttp "GET /admin/jsi18n/ HTTP/1.1" 200 3223
INFO 2019-05-01 16:18:23,944 basehttp "GET /static/admin/img/icon-calendar.svg HTTP/1.1" 200 1086
INFO 2019-05-01 16:18:29,466 basehttp "GET /admin/ignis/dataset/add/?_to_field=id&_popup=1 HTTP/1.1" 200 5965
INFO 2019-05-01 16:18:29,606 basehttp "GET /admin/jsi18n/ HTTP/1.1" 200 3223
INFO 2019-05-01 16:18:46,596 basehttp "POST /admin/ignis/dataset/add/?_to_field=id&_popup=1 HTTP/1.1" 200 359
INFO 2019-05-01 16:18:47,019 basehttp "GET /static/admin/js/popup_response.js HTTP/1.1" 200 569
INFO 2019-05-01 16:18:56,444 basehttp "POST /admin/ignis/nn/add/ HTTP/1.1" 200 8171
INFO 2019-05-01 16:18:56,629 basehttp "GET /admin/jsi18n/ HTTP/1.1" 200 3223
INFO 2019-05-01 16:19:08,569 basehttp "POST /admin/ignis/nn/add/ HTTP/1.1" 302 0
INFO 2019-05-01 16:19:08,672 basehttp "GET /admin/ignis/nn/ HTTP/1.1" 200 4451
INFO 2019-05-01 16:19:08,883 basehttp "GET /admin/jsi18n/ HTTP/1.1" 200 3223
INFO 2019-05-01 16:19:09,008 basehttp "GET /static/admin/img/tooltag-add.svg HTTP/1.1" 200 331
INFO 2019-05-01 16:19:09,039 basehttp "GET /static/admin/img/icon-yes.svg HTTP/1.1" 200 436
INFO 2019-05-01 16:19:12,632 basehttp "GET /dataset/ HTTP/1.1" 200 1516
WARNING 2019-05-01 16:19:13,914 basehttp "GET /static/css/styles.css HTTP/1.1" 404 1767
WARNING 2019-05-01 16:19:14,726 basehttp "GET /static/css/styles.css HTTP/1.1" 404 1767
INFO 2019-05-01 16:19:18,842 basehttp "GET /nn/ HTTP/1.1" 200 1508
WARNING 2019-05-01 16:19:18,948 basehttp "GET /static/css/styles.css HTTP/1.1" 404 1767
WARNING 2019-05-01 16:19:19,090 basehttp "GET /static/css/styles.css HTTP/1.1" 404 1767
ERROR 2019-05-01 16:21:47,575 log Internal Server Error: /nn/1
Traceback (most recent call last):
  File "/home/maus/.local/share/virtualenvs/kp-3crlKS4c/lib/python3.7/site-packages/django/core/handlers/exception.py", line 34, in inner
    response = get_response(request)
  File "/home/maus/.local/share/virtualenvs/kp-3crlKS4c/lib/python3.7/site-packages/django/core/handlers/base.py", line 115, in _get_response
    response = self.process_exception_by_middleware(e, request)
  File "/home/maus/.local/share/virtualenvs/kp-3crlKS4c/lib/python3.7/site-packages/django/core/handlers/base.py", line 113, in _get_response
    response = wrapped_callback(request, *callback_args, **callback_kwargs)
  File "/home/maus/.local/share/virtualenvs/kp-3crlKS4c/lib/python3.7/site-packages/django/views/generic/base.py", line 71, in view
    return self.dispatch(request, *args, **kwargs)
  File "/home/maus/.local/share/virtualenvs/kp-3crlKS4c/lib/python3.7/site-packages/django/views/generic/base.py", line 97, in dispatch
    return handler(request, *args, **kwargs)
  File "/home/maus/.local/share/virtualenvs/kp-3crlKS4c/lib/python3.7/site-packages/django/views/generic/detail.py", line 107, in get
    context = self.get_context_data(object=self.object)
  File "/home/maus/bsuir/kp/mysite/ignis/views.py", line 178, in get_context_data
    meta_data = dataset.meta_data()
  File "/home/maus/bsuir/kp/mysite/ignis/models.py", line 63, in meta_data
    resolver = NNResolver(self.file)
AttributeError: 'NN' object has no attribute 'file'
ERROR 2019-05-01 16:21:47,576 basehttp "GET /nn/1 HTTP/1.1" 500 89403
INFO 2019-05-01 16:24:48,196 autoreload /home/maus/bsuir/kp/mysite/ignis/models.py changed, reloading.
INFO 2019-05-01 16:24:58,652 autoreload Watching for file changes with StatReloader
ERROR 2019-05-01 16:25:01,042 log Internal Server Error: /nn/1
Traceback (most recent call last):
  File "/home/maus/.local/share/virtualenvs/kp-3crlKS4c/lib/python3.7/site-packages/django/core/handlers/exception.py", line 34, in inner
    response = get_response(request)
  File "/home/maus/.local/share/virtualenvs/kp-3crlKS4c/lib/python3.7/site-packages/django/core/handlers/base.py", line 115, in _get_response
    response = self.process_exception_by_middleware(e, request)
  File "/home/maus/.local/share/virtualenvs/kp-3crlKS4c/lib/python3.7/site-packages/django/core/handlers/base.py", line 113, in _get_response
    response = wrapped_callback(request, *callback_args, **callback_kwargs)
  File "/home/maus/.local/share/virtualenvs/kp-3crlKS4c/lib/python3.7/site-packages/django/views/generic/base.py", line 71, in view
    return self.dispatch(request, *args, **kwargs)
  File "/home/maus/.local/share/virtualenvs/kp-3crlKS4c/lib/python3.7/site-packages/django/views/generic/base.py", line 97, in dispatch
    return handler(request, *args, **kwargs)
  File "/home/maus/.local/share/virtualenvs/kp-3crlKS4c/lib/python3.7/site-packages/django/views/generic/detail.py", line 107, in get
    context = self.get_context_data(object=self.object)
  File "/home/maus/bsuir/kp/mysite/ignis/views.py", line 178, in get_context_data
    meta_data = dataset.meta_data()
  File "/home/maus/bsuir/kp/mysite/ignis/models.py", line 64, in meta_data
    return resolver.get_meta_data()
AttributeError: 'NNResolver' object has no attribute 'get_meta_data'
ERROR 2019-05-01 16:25:01,043 basehttp "GET /nn/1 HTTP/1.1" 500 89529
INFO 2019-05-01 16:25:46,992 autoreload /home/maus/bsuir/kp/mysite/engine/tool.py changed, reloading.
INFO 2019-05-01 16:25:47,618 autoreload Watching for file changes with StatReloader
ERROR 2019-05-01 16:25:49,884 log Internal Server Error: /nn/1
Traceback (most recent call last):
  File "/home/maus/.local/share/virtualenvs/kp-3crlKS4c/lib/python3.7/site-packages/django/core/handlers/exception.py", line 34, in inner
    response = get_response(request)
  File "/home/maus/.local/share/virtualenvs/kp-3crlKS4c/lib/python3.7/site-packages/django/core/handlers/base.py", line 115, in _get_response
    response = self.process_exception_by_middleware(e, request)
  File "/home/maus/.local/share/virtualenvs/kp-3crlKS4c/lib/python3.7/site-packages/django/core/handlers/base.py", line 113, in _get_response
    response = wrapped_callback(request, *callback_args, **callback_kwargs)
  File "/home/maus/.local/share/virtualenvs/kp-3crlKS4c/lib/python3.7/site-packages/django/views/generic/base.py", line 71, in view
    return self.dispatch(request, *args, **kwargs)
  File "/home/maus/.local/share/virtualenvs/kp-3crlKS4c/lib/python3.7/site-packages/django/views/generic/base.py", line 97, in dispatch
    return handler(request, *args, **kwargs)
  File "/home/maus/.local/share/virtualenvs/kp-3crlKS4c/lib/python3.7/site-packages/django/views/generic/detail.py", line 107, in get
    context = self.get_context_data(object=self.object)
  File "/home/maus/bsuir/kp/mysite/ignis/views.py", line 180, in get_context_data
    if meta_data["valid"]:
TypeError: 'NoneType' object is not subscriptable
ERROR 2019-05-01 16:25:49,885 basehttp "GET /nn/1 HTTP/1.1" 500 87066
ERROR 2019-05-01 16:25:53,119 log Internal Server Error: /nn/1
Traceback (most recent call last):
  File "/home/maus/.local/share/virtualenvs/kp-3crlKS4c/lib/python3.7/site-packages/django/core/handlers/exception.py", line 34, in inner
    response = get_response(request)
  File "/home/maus/.local/share/virtualenvs/kp-3crlKS4c/lib/python3.7/site-packages/django/core/handlers/base.py", line 115, in _get_response
    response = self.process_exception_by_middleware(e, request)
  File "/home/maus/.local/share/virtualenvs/kp-3crlKS4c/lib/python3.7/site-packages/django/core/handlers/base.py", line 113, in _get_response
    response = wrapped_callback(request, *callback_args, **callback_kwargs)
  File "/home/maus/.local/share/virtualenvs/kp-3crlKS4c/lib/python3.7/site-packages/django/views/generic/base.py", line 71, in view
    return self.dispatch(request, *args, **kwargs)
  File "/home/maus/.local/share/virtualenvs/kp-3crlKS4c/lib/python3.7/site-packages/django/views/generic/base.py", line 97, in dispatch
    return handler(request, *args, **kwargs)
  File "/home/maus/.local/share/virtualenvs/kp-3crlKS4c/lib/python3.7/site-packages/django/views/generic/detail.py", line 107, in get
    context = self.get_context_data(object=self.object)
  File "/home/maus/bsuir/kp/mysite/ignis/views.py", line 180, in get_context_data
    if meta_data["valid"]:
TypeError: 'NoneType' object is not subscriptable
ERROR 2019-05-01 16:25:53,121 basehttp "GET /nn/1 HTTP/1.1" 500 87066
ERROR 2019-05-01 16:25:55,204 log Internal Server Error: /nn/1
Traceback (most recent call last):
  File "/home/maus/.local/share/virtualenvs/kp-3crlKS4c/lib/python3.7/site-packages/django/core/handlers/exception.py", line 34, in inner
    response = get_response(request)
  File "/home/maus/.local/share/virtualenvs/kp-3crlKS4c/lib/python3.7/site-packages/django/core/handlers/base.py", line 115, in _get_response
    response = self.process_exception_by_middleware(e, request)
  File "/home/maus/.local/share/virtualenvs/kp-3crlKS4c/lib/python3.7/site-packages/django/core/handlers/base.py", line 113, in _get_response
    response = wrapped_callback(request, *callback_args, **callback_kwargs)
  File "/home/maus/.local/share/virtualenvs/kp-3crlKS4c/lib/python3.7/site-packages/django/views/generic/base.py", line 71, in view
    return self.dispatch(request, *args, **kwargs)
  File "/home/maus/.local/share/virtualenvs/kp-3crlKS4c/lib/python3.7/site-packages/django/views/generic/base.py", line 97, in dispatch
    return handler(request, *args, **kwargs)
  File "/home/maus/.local/share/virtualenvs/kp-3crlKS4c/lib/python3.7/site-packages/django/views/generic/detail.py", line 107, in get
    context = self.get_context_data(object=self.object)
  File "/home/maus/bsuir/kp/mysite/ignis/views.py", line 180, in get_context_data
    if meta_data["valid"]:
TypeError: 'NoneType' object is not subscriptable
ERROR 2019-05-01 16:25:55,204 basehttp "GET /nn/1 HTTP/1.1" 500 87066
INFO 2019-05-01 16:26:12,972 autoreload /home/maus/bsuir/kp/mysite/ignis/views.py changed, reloading.
INFO 2019-05-01 16:26:14,472 autoreload Watching for file changes with StatReloader
INFO 2019-05-01 16:27:47,887 basehttp "GET /nn/1 HTTP/1.1" 200 1601
WARNING 2019-05-01 16:27:48,003 basehttp "GET /static/css/styles.css HTTP/1.1" 404 1767
WARNING 2019-05-01 16:27:48,247 basehttp "GET /static/css/styles.css HTTP/1.1" 404 1767
INFO 2019-05-01 16:28:58,271 basehttp "GET /nn/1 HTTP/1.1" 200 1668
WARNING 2019-05-01 16:28:58,402 basehttp "GET /static/css/styles.css HTTP/1.1" 404 1767
WARNING 2019-05-01 16:28:58,499 basehttp "GET /static/css/styles.css HTTP/1.1" 404 1767
INFO 2019-05-01 16:29:48,447 autoreload /home/maus/bsuir/kp/mysite/ignis/models.py changed, reloading.
INFO 2019-05-01 16:29:49,110 autoreload Watching for file changes with StatReloader
INFO 2019-05-01 16:30:34,526 autoreload Watching for file changes with StatReloader
INFO 2019-05-01 16:30:39,162 basehttp "GET /nn/1 HTTP/1.1" 200 1668
WARNING 2019-05-01 16:30:39,284 basehttp "GET /static/css/styles.css HTTP/1.1" 404 1767
WARNING 2019-05-01 16:30:39,384 basehttp "GET /static/css/styles.css HTTP/1.1" 404 1767
INFO 2019-05-01 16:30:43,567 views user (root) want to update nn (test)
INFO 2019-05-01 16:30:43,753 basehttp "GET /nn/1/update HTTP/1.1" 200 2130
WARNING 2019-05-01 16:30:43,872 basehttp "GET /static/css/styles.css HTTP/1.1" 404 1767
WARNING 2019-05-01 16:30:43,941 basehttp "GET /static/css/styles.css HTTP/1.1" 404 1767
INFO 2019-05-01 16:31:11,253 autoreload /home/maus/bsuir/kp/mysite/ignis/views.py changed, reloading.
INFO 2019-05-01 16:31:11,857 autoreload Watching for file changes with StatReloader
INFO 2019-05-01 16:31:13,800 views user (root) want to update nn (test)
INFO 2019-05-01 16:31:13,860 basehttp "GET /nn/1/update HTTP/1.1" 200 2298
WARNING 2019-05-01 16:31:13,964 basehttp "GET /static/css/styles.css HTTP/1.1" 404 1767
WARNING 2019-05-01 16:31:14,047 basehttp "GET /static/css/styles.css HTTP/1.1" 404 1767
INFO 2019-05-01 17:45:09,409 autoreload Watching for file changes with StatReloader
INFO 2019-05-01 17:45:15,180 basehttp "GET / HTTP/1.1" 200 1331
INFO 2019-05-01 17:45:15,180 basehttp "GET / HTTP/1.1" 200 1331
WARNING 2019-05-01 17:45:15,556 basehttp "GET /static/css/styles.css HTTP/1.1" 404 1767
WARNING 2019-05-01 17:45:15,689 basehttp "GET /static/css/styles.css HTTP/1.1" 404 1767
WARNING 2019-05-01 17:45:15,738 log Not Found: /favicon.ico
WARNING 2019-05-01 17:45:15,739 basehttp "GET /favicon.ico HTTP/1.1" 404 4388
INFO 2019-05-01 17:45:20,978 basehttp "GET /nn/ HTTP/1.1" 200 1508
WARNING 2019-05-01 17:45:21,090 basehttp "GET /static/css/styles.css HTTP/1.1" 404 1767
WARNING 2019-05-01 17:45:21,172 basehttp "GET /static/css/styles.css HTTP/1.1" 404 1767
INFO 2019-05-01 17:45:23,707 basehttp "GET /nn/1 HTTP/1.1" 200 1668
WARNING 2019-05-01 17:45:23,836 basehttp "GET /static/css/styles.css HTTP/1.1" 404 1767
WARNING 2019-05-01 17:45:23,902 basehttp "GET /static/css/styles.css HTTP/1.1" 404 1767
INFO 2019-05-01 17:45:43,098 autoreload /home/maus/bsuir/kp/ignis/views.py changed, reloading.
INFO 2019-05-01 17:45:44,467 autoreload Watching for file changes with StatReloader
ERROR 2019-05-01 17:46:07,912 log Internal Server Error: /nn/1
Traceback (most recent call last):
  File "/home/maus/.local/share/virtualenvs/kp-3crlKS4c/lib/python3.7/site-packages/django/core/handlers/exception.py", line 34, in inner
    response = get_response(request)
  File "/home/maus/.local/share/virtualenvs/kp-3crlKS4c/lib/python3.7/site-packages/django/core/handlers/base.py", line 115, in _get_response
    response = self.process_exception_by_middleware(e, request)
  File "/home/maus/.local/share/virtualenvs/kp-3crlKS4c/lib/python3.7/site-packages/django/core/handlers/base.py", line 113, in _get_response
    response = wrapped_callback(request, *callback_args, **callback_kwargs)
  File "/home/maus/.local/share/virtualenvs/kp-3crlKS4c/lib/python3.7/site-packages/django/views/generic/base.py", line 71, in view
    return self.dispatch(request, *args, **kwargs)
  File "/home/maus/.local/share/virtualenvs/kp-3crlKS4c/lib/python3.7/site-packages/django/views/generic/base.py", line 97, in dispatch
    return handler(request, *args, **kwargs)
  File "/home/maus/.local/share/virtualenvs/kp-3crlKS4c/lib/python3.7/site-packages/django/views/generic/detail.py", line 107, in get
    context = self.get_context_data(object=self.object)
  File "/home/maus/bsuir/kp/ignis/views.py", line 178, in get_context_data
    meta_data = dataset.meta_data()
  File "/home/maus/bsuir/kp/ignis/models.py", line 64, in meta_data
    return resolver.get_meta_data()
TypeError: get_meta_data() missing 1 required positional argument: 'nn'
ERROR 2019-05-01 17:46:07,913 basehttp "GET /nn/1 HTTP/1.1" 500 87913
INFO 2019-05-01 17:46:25,498 autoreload /home/maus/bsuir/kp/ignis/views.py changed, reloading.
INFO 2019-05-01 17:46:26,339 autoreload Watching for file changes with StatReloader
ERROR 2019-05-01 17:46:27,718 log Internal Server Error: /nn/1
Traceback (most recent call last):
  File "/home/maus/.local/share/virtualenvs/kp-3crlKS4c/lib/python3.7/site-packages/django/core/handlers/exception.py", line 34, in inner
    response = get_response(request)
  File "/home/maus/.local/share/virtualenvs/kp-3crlKS4c/lib/python3.7/site-packages/django/core/handlers/base.py", line 115, in _get_response
    response = self.process_exception_by_middleware(e, request)
  File "/home/maus/.local/share/virtualenvs/kp-3crlKS4c/lib/python3.7/site-packages/django/core/handlers/base.py", line 113, in _get_response
    response = wrapped_callback(request, *callback_args, **callback_kwargs)
  File "/home/maus/.local/share/virtualenvs/kp-3crlKS4c/lib/python3.7/site-packages/django/views/generic/base.py", line 71, in view
    return self.dispatch(request, *args, **kwargs)
  File "/home/maus/.local/share/virtualenvs/kp-3crlKS4c/lib/python3.7/site-packages/django/views/generic/base.py", line 97, in dispatch
    return handler(request, *args, **kwargs)
  File "/home/maus/.local/share/virtualenvs/kp-3crlKS4c/lib/python3.7/site-packages/django/views/generic/detail.py", line 107, in get
    context = self.get_context_data(object=self.object)
  File "/home/maus/bsuir/kp/ignis/views.py", line 178, in get_context_data
    meta_data = dataset.meta_data(dataset)
TypeError: meta_data() takes 1 positional argument but 2 were given
ERROR 2019-05-01 17:46:27,719 basehttp "GET /nn/1 HTTP/1.1" 500 85264
INFO 2019-05-01 17:47:04,096 autoreload /home/maus/bsuir/kp/ignis/views.py changed, reloading.
INFO 2019-05-01 17:47:04,784 autoreload Watching for file changes with StatReloader
INFO 2019-05-01 17:47:14,402 autoreload /home/maus/bsuir/kp/ignis/models.py changed, reloading.
INFO 2019-05-01 17:47:15,022 autoreload Watching for file changes with StatReloader
ERROR 2019-05-01 17:47:26,289 log Internal Server Error: /nn/1
Traceback (most recent call last):
  File "/home/maus/.local/share/virtualenvs/kp-3crlKS4c/lib/python3.7/site-packages/django/core/handlers/exception.py", line 34, in inner
    response = get_response(request)
  File "/home/maus/.local/share/virtualenvs/kp-3crlKS4c/lib/python3.7/site-packages/django/core/handlers/base.py", line 115, in _get_response
    response = self.process_exception_by_middleware(e, request)
  File "/home/maus/.local/share/virtualenvs/kp-3crlKS4c/lib/python3.7/site-packages/django/core/handlers/base.py", line 113, in _get_response
    response = wrapped_callback(request, *callback_args, **callback_kwargs)
  File "/home/maus/.local/share/virtualenvs/kp-3crlKS4c/lib/python3.7/site-packages/django/views/generic/base.py", line 71, in view
    return self.dispatch(request, *args, **kwargs)
  File "/home/maus/.local/share/virtualenvs/kp-3crlKS4c/lib/python3.7/site-packages/django/views/generic/base.py", line 97, in dispatch
    return handler(request, *args, **kwargs)
  File "/home/maus/.local/share/virtualenvs/kp-3crlKS4c/lib/python3.7/site-packages/django/views/generic/detail.py", line 107, in get
    context = self.get_context_data(object=self.object)
  File "/home/maus/bsuir/kp/ignis/views.py", line 178, in get_context_data
    meta_data = dataset.meta_data()
  File "/home/maus/bsuir/kp/ignis/models.py", line 63, in meta_data
    resolver = NNResolver(self)
TypeError: NNResolver() takes no arguments
ERROR 2019-05-01 17:47:26,290 basehttp "GET /nn/1 HTTP/1.1" 500 87830
INFO 2019-05-01 17:48:15,845 autoreload /home/maus/bsuir/kp/engine/tool.py changed, reloading.
INFO 2019-05-01 17:48:16,495 autoreload Watching for file changes with StatReloader
INFO 2019-05-01 17:48:19,763 autoreload Watching for file changes with StatReloader
ERROR 2019-05-01 17:48:21,623 log Internal Server Error: /nn/1
Traceback (most recent call last):
  File "/home/maus/.local/share/virtualenvs/kp-3crlKS4c/lib/python3.7/site-packages/django/core/handlers/exception.py", line 34, in inner
    response = get_response(request)
  File "/home/maus/.local/share/virtualenvs/kp-3crlKS4c/lib/python3.7/site-packages/django/core/handlers/base.py", line 115, in _get_response
    response = self.process_exception_by_middleware(e, request)
  File "/home/maus/.local/share/virtualenvs/kp-3crlKS4c/lib/python3.7/site-packages/django/core/handlers/base.py", line 113, in _get_response
    response = wrapped_callback(request, *callback_args, **callback_kwargs)
  File "/home/maus/.local/share/virtualenvs/kp-3crlKS4c/lib/python3.7/site-packages/django/views/generic/base.py", line 71, in view
    return self.dispatch(request, *args, **kwargs)
  File "/home/maus/.local/share/virtualenvs/kp-3crlKS4c/lib/python3.7/site-packages/django/views/generic/base.py", line 97, in dispatch
    return handler(request, *args, **kwargs)
  File "/home/maus/.local/share/virtualenvs/kp-3crlKS4c/lib/python3.7/site-packages/django/views/generic/detail.py", line 107, in get
    context = self.get_context_data(object=self.object)
  File "/home/maus/bsuir/kp/ignis/views.py", line 178, in get_context_data
    meta_data = dataset.meta_data()
  File "/home/maus/bsuir/kp/ignis/models.py", line 63, in meta_data
    resolver = NNResolver(self)
TypeError: NNResolver() takes no arguments
ERROR 2019-05-01 17:48:21,624 basehttp "GET /nn/1 HTTP/1.1" 500 87830
INFO 2019-05-01 17:49:13,326 autoreload /home/maus/bsuir/kp/engine/tool.py changed, reloading.
INFO 2019-05-01 17:49:14,643 autoreload Watching for file changes with StatReloader
INFO 2019-05-01 17:49:16,960 autoreload /home/maus/bsuir/kp/engine/tool.py changed, reloading.
INFO 2019-05-01 17:49:17,668 autoreload Watching for file changes with StatReloader
INFO 2019-05-01 17:49:26,249 autoreload /home/maus/bsuir/kp/engine/tool.py changed, reloading.
INFO 2019-05-01 17:49:26,873 autoreload Watching for file changes with StatReloader
INFO 2019-05-01 17:49:30,971 basehttp "GET /nn/1 HTTP/1.1" 200 1667
WARNING 2019-05-01 17:49:31,051 basehttp "GET /static/css/styles.css HTTP/1.1" 404 1767
WARNING 2019-05-01 17:49:31,524 basehttp "GET /static/css/styles.css HTTP/1.1" 404 1767
INFO 2019-05-01 17:49:43,812 autoreload /home/maus/bsuir/kp/engine/tool.py changed, reloading.
INFO 2019-05-01 17:49:44,440 autoreload Watching for file changes with StatReloader
INFO 2019-05-01 17:49:45,366 basehttp "GET /nn/1 HTTP/1.1" 200 1667
WARNING 2019-05-01 17:49:45,416 basehttp "GET /static/css/styles.css HTTP/1.1" 404 1767
WARNING 2019-05-01 17:49:45,612 basehttp "GET /static/css/styles.css HTTP/1.1" 404 1767
INFO 2019-05-01 17:51:14,419 autoreload /home/maus/bsuir/kp/engine/tool.py changed, reloading.
INFO 2019-05-01 17:51:14,814 autoreload Watching for file changes with StatReloader
INFO 2019-05-01 17:51:39,065 autoreload Watching for file changes with StatReloader
INFO 2019-05-01 17:52:25,562 autoreload /home/maus/bsuir/kp/engine/tool.py changed, reloading.
INFO 2019-05-01 17:52:26,137 autoreload Watching for file changes with StatReloader
INFO 2019-05-01 17:52:28,535 basehttp "GET /nn/1 HTTP/1.1" 200 1667
WARNING 2019-05-01 17:52:28,647 basehttp "GET /static/css/styles.css HTTP/1.1" 404 1767
WARNING 2019-05-01 17:52:28,733 basehttp "GET /static/css/styles.css HTTP/1.1" 404 1767
INFO 2019-05-01 17:53:05,092 autoreload /home/maus/bsuir/kp/engine/tool.py changed, reloading.
INFO 2019-05-01 17:53:05,740 autoreload Watching for file changes with StatReloader
INFO 2019-05-01 17:53:15,384 autoreload /home/maus/bsuir/kp/engine/tool.py changed, reloading.
INFO 2019-05-01 17:53:15,736 autoreload Watching for file changes with StatReloader
INFO 2019-05-01 17:53:20,916 autoreload /home/maus/bsuir/kp/engine/tool.py changed, reloading.
INFO 2019-05-01 17:53:21,505 autoreload Watching for file changes with StatReloader
INFO 2019-05-01 17:53:35,334 autoreload /home/maus/bsuir/kp/engine/tool.py changed, reloading.
INFO 2019-05-01 17:53:36,026 autoreload Watching for file changes with StatReloader
INFO 2019-05-01 17:53:43,605 autoreload /home/maus/bsuir/kp/engine/tool.py changed, reloading.
INFO 2019-05-01 17:53:44,001 autoreload Watching for file changes with StatReloader
INFO 2019-05-01 17:53:47,166 autoreload /home/maus/bsuir/kp/engine/tool.py changed, reloading.
INFO 2019-05-01 17:53:47,512 autoreload Watching for file changes with StatReloader
INFO 2019-05-01 17:54:00,755 autoreload /home/maus/bsuir/kp/engine/tool.py changed, reloading.
INFO 2019-05-01 17:54:01,074 autoreload Watching for file changes with StatReloader
INFO 2019-05-01 17:54:08,262 autoreload /home/maus/bsuir/kp/engine/tool.py changed, reloading.
INFO 2019-05-01 17:54:08,576 autoreload Watching for file changes with StatReloader
INFO 2019-05-01 17:54:17,786 autoreload /home/maus/bsuir/kp/engine/tool.py changed, reloading.
INFO 2019-05-01 17:54:18,356 autoreload Watching for file changes with StatReloader
INFO 2019-05-01 17:54:31,104 autoreload /home/maus/bsuir/kp/engine/tool.py changed, reloading.
INFO 2019-05-01 17:54:31,588 autoreload Watching for file changes with StatReloader
INFO 2019-05-01 18:00:44,536 autoreload /home/maus/bsuir/kp/engine/tool.py changed, reloading.
INFO 2019-05-01 18:00:52,040 autoreload Watching for file changes with StatReloader
INFO 2019-05-01 18:00:55,080 autoreload /home/maus/bsuir/kp/engine/tool.py changed, reloading.
INFO 2019-05-01 18:00:55,440 autoreload Watching for file changes with StatReloader
INFO 2019-05-01 18:01:12,706 autoreload /home/maus/bsuir/kp/engine/tool.py changed, reloading.
INFO 2019-05-01 18:01:13,298 autoreload Watching for file changes with StatReloader
INFO 2019-05-01 18:11:53,851 autoreload Watching for file changes with StatReloader
INFO 2019-05-01 18:11:59,121 basehttp "GET /nn/1 HTTP/1.1" 200 1667
WARNING 2019-05-01 18:11:59,312 basehttp "GET /static/css/styles.css HTTP/1.1" 404 1767
WARNING 2019-05-01 18:11:59,410 basehttp "GET /static/css/styles.css HTTP/1.1" 404 1767
WARNING 2019-05-01 18:11:59,458 log Not Found: /favicon.ico
WARNING 2019-05-01 18:11:59,458 basehttp "GET /favicon.ico HTTP/1.1" 404 4388
INFO 2019-05-01 18:12:29,803 autoreload /home/maus/bsuir/kp/engine/tool.py changed, reloading.
INFO 2019-05-01 18:12:30,534 autoreload Watching for file changes with StatReloader
ERROR 2019-05-01 18:12:33,220 tool error
Traceback (most recent call last):
  File "/home/maus/bsuir/kp/engine/tool.py", line 55, in prepare_sandbox
    with open("sandboxes/" + self.filename, "w") as output:
AttributeError: 'NNResolver' object has no attribute 'filename'
ERROR 2019-05-01 18:12:33,315 log Internal Server Error: /nn/1
Traceback (most recent call last):
  File "/home/maus/.local/share/virtualenvs/kp-3crlKS4c/lib/python3.7/site-packages/django/core/handlers/exception.py", line 34, in inner
    response = get_response(request)
  File "/home/maus/.local/share/virtualenvs/kp-3crlKS4c/lib/python3.7/site-packages/django/core/handlers/base.py", line 115, in _get_response
    response = self.process_exception_by_middleware(e, request)
  File "/home/maus/.local/share/virtualenvs/kp-3crlKS4c/lib/python3.7/site-packages/django/core/handlers/base.py", line 113, in _get_response
    response = wrapped_callback(request, *callback_args, **callback_kwargs)
  File "/home/maus/.local/share/virtualenvs/kp-3crlKS4c/lib/python3.7/site-packages/django/views/generic/base.py", line 71, in view
    return self.dispatch(request, *args, **kwargs)
  File "/home/maus/.local/share/virtualenvs/kp-3crlKS4c/lib/python3.7/site-packages/django/views/generic/base.py", line 97, in dispatch
    return handler(request, *args, **kwargs)
  File "/home/maus/.local/share/virtualenvs/kp-3crlKS4c/lib/python3.7/site-packages/django/views/generic/detail.py", line 107, in get
    context = self.get_context_data(object=self.object)
  File "/home/maus/bsuir/kp/ignis/views.py", line 178, in get_context_data
    meta_data = dataset.meta_data()
  File "/home/maus/bsuir/kp/ignis/models.py", line 64, in meta_data
    return resolver.get_meta_data()
  File "/home/maus/bsuir/kp/engine/tool.py", line 51, in get_meta_data
    result = self.run()
TypeError: run() takes 0 positional arguments but 1 was given
ERROR 2019-05-01 18:12:33,316 basehttp "GET /nn/1 HTTP/1.1" 500 91357
INFO 2019-05-01 18:12:43,446 autoreload /home/maus/bsuir/kp/engine/tool.py changed, reloading.
INFO 2019-05-01 18:12:44,148 autoreload Watching for file changes with StatReloader
ERROR 2019-05-01 18:12:46,873 tool error
Traceback (most recent call last):
  File "/home/maus/bsuir/kp/engine/tool.py", line 55, in prepare_sandbox
    with open("sandboxes/" + self.filename, "w") as output:
AttributeError: 'NNResolver' object has no attribute 'filename'
ERROR 2019-05-01 18:12:46,920 log Internal Server Error: /nn/1
Traceback (most recent call last):
  File "/home/maus/.local/share/virtualenvs/kp-3crlKS4c/lib/python3.7/site-packages/django/core/handlers/exception.py", line 34, in inner
    response = get_response(request)
  File "/home/maus/.local/share/virtualenvs/kp-3crlKS4c/lib/python3.7/site-packages/django/core/handlers/base.py", line 115, in _get_response
    response = self.process_exception_by_middleware(e, request)
  File "/home/maus/.local/share/virtualenvs/kp-3crlKS4c/lib/python3.7/site-packages/django/core/handlers/base.py", line 113, in _get_response
    response = wrapped_callback(request, *callback_args, **callback_kwargs)
  File "/home/maus/.local/share/virtualenvs/kp-3crlKS4c/lib/python3.7/site-packages/django/views/generic/base.py", line 71, in view
    return self.dispatch(request, *args, **kwargs)
  File "/home/maus/.local/share/virtualenvs/kp-3crlKS4c/lib/python3.7/site-packages/django/views/generic/base.py", line 97, in dispatch
    return handler(request, *args, **kwargs)
  File "/home/maus/.local/share/virtualenvs/kp-3crlKS4c/lib/python3.7/site-packages/django/views/generic/detail.py", line 107, in get
    context = self.get_context_data(object=self.object)
  File "/home/maus/bsuir/kp/ignis/views.py", line 178, in get_context_data
    meta_data = dataset.meta_data()
  File "/home/maus/bsuir/kp/ignis/models.py", line 64, in meta_data
    return resolver.get_meta_data()
  File "/home/maus/bsuir/kp/engine/tool.py", line 51, in get_meta_data
    result = self.run()
  File "/home/maus/bsuir/kp/engine/tool.py", line 76, in run
    args, preexec_fn=demote(user_uid, user_gid), cwd=cwd, env=env
NameError: name 'demote' is not defined
ERROR 2019-05-01 18:12:46,921 basehttp "GET /nn/1 HTTP/1.1" 500 101387
INFO 2019-05-01 18:12:58,027 autoreload /home/maus/bsuir/kp/engine/tool.py changed, reloading.
INFO 2019-05-01 18:12:58,679 autoreload Watching for file changes with StatReloader
INFO 2019-05-01 18:13:05,211 autoreload /home/maus/bsuir/kp/engine/tool.py changed, reloading.
INFO 2019-05-01 18:13:06,023 autoreload Watching for file changes with StatReloader
ERROR 2019-05-01 18:13:07,898 tool error
Traceback (most recent call last):
  File "/home/maus/bsuir/kp/engine/tool.py", line 65, in prepare_sandbox
    with open("sandboxes/" + self.filename, "w") as output:
AttributeError: 'NNResolver' object has no attribute 'filename'
ERROR 2019-05-01 18:13:08,016 log Internal Server Error: /nn/1
Traceback (most recent call last):
  File "/home/maus/.local/share/virtualenvs/kp-3crlKS4c/lib/python3.7/site-packages/django/core/handlers/exception.py", line 34, in inner
    response = get_response(request)
  File "/home/maus/.local/share/virtualenvs/kp-3crlKS4c/lib/python3.7/site-packages/django/core/handlers/base.py", line 115, in _get_response
    response = self.process_exception_by_middleware(e, request)
  File "/home/maus/.local/share/virtualenvs/kp-3crlKS4c/lib/python3.7/site-packages/django/core/handlers/base.py", line 113, in _get_response
    response = wrapped_callback(request, *callback_args, **callback_kwargs)
  File "/home/maus/.local/share/virtualenvs/kp-3crlKS4c/lib/python3.7/site-packages/django/views/generic/base.py", line 71, in view
    return self.dispatch(request, *args, **kwargs)
  File "/home/maus/.local/share/virtualenvs/kp-3crlKS4c/lib/python3.7/site-packages/django/views/generic/base.py", line 97, in dispatch
    return handler(request, *args, **kwargs)
  File "/home/maus/.local/share/virtualenvs/kp-3crlKS4c/lib/python3.7/site-packages/django/views/generic/detail.py", line 107, in get
    context = self.get_context_data(object=self.object)
  File "/home/maus/bsuir/kp/ignis/views.py", line 178, in get_context_data
    meta_data = dataset.meta_data()
  File "/home/maus/bsuir/kp/ignis/models.py", line 64, in meta_data
    return resolver.get_meta_data()
  File "/home/maus/bsuir/kp/engine/tool.py", line 61, in get_meta_data
    result = self.run()
  File "/home/maus/bsuir/kp/engine/tool.py", line 86, in run
    args, preexec_fn=demote(user_uid, user_gid), cwd=cwd, env=env
  File "/usr/lib/python3.7/subprocess.py", line 775, in __init__
    restore_signals, start_new_session)
  File "/usr/lib/python3.7/subprocess.py", line 1522, in _execute_child
    raise child_exception_type(errno_num, err_msg, err_filename)
FileNotFoundError: [Errno 2] No such file or directory: 'pipenv run python': 'pipenv run python'
ERROR 2019-05-01 18:13:08,018 basehttp "GET /nn/1 HTTP/1.1" 500 134481
INFO 2019-05-01 18:16:05,928 autoreload /home/maus/bsuir/kp/engine/tool.py changed, reloading.
INFO 2019-05-01 18:16:30,465 autoreload Watching for file changes with StatReloader
ERROR 2019-05-01 18:16:36,372 tool error
Traceback (most recent call last):
  File "/home/maus/bsuir/kp/engine/tool.py", line 65, in prepare_sandbox
    with open("sandboxes/" + self.filename, "w") as output:
AttributeError: 'NNResolver' object has no attribute 'filename'
ERROR 2019-05-01 18:16:36,785 log Internal Server Error: /nn/1
Traceback (most recent call last):
  File "/home/maus/.local/share/virtualenvs/kp-3crlKS4c/lib/python3.7/site-packages/django/core/handlers/exception.py", line 34, in inner
    response = get_response(request)
  File "/home/maus/.local/share/virtualenvs/kp-3crlKS4c/lib/python3.7/site-packages/django/core/handlers/base.py", line 115, in _get_response
    response = self.process_exception_by_middleware(e, request)
  File "/home/maus/.local/share/virtualenvs/kp-3crlKS4c/lib/python3.7/site-packages/django/core/handlers/base.py", line 113, in _get_response
    response = wrapped_callback(request, *callback_args, **callback_kwargs)
  File "/home/maus/.local/share/virtualenvs/kp-3crlKS4c/lib/python3.7/site-packages/django/views/generic/base.py", line 71, in view
    return self.dispatch(request, *args, **kwargs)
  File "/home/maus/.local/share/virtualenvs/kp-3crlKS4c/lib/python3.7/site-packages/django/views/generic/base.py", line 97, in dispatch
    return handler(request, *args, **kwargs)
  File "/home/maus/.local/share/virtualenvs/kp-3crlKS4c/lib/python3.7/site-packages/django/views/generic/detail.py", line 107, in get
    context = self.get_context_data(object=self.object)
  File "/home/maus/bsuir/kp/ignis/views.py", line 178, in get_context_data
    meta_data = dataset.meta_data()
  File "/home/maus/bsuir/kp/ignis/models.py", line 64, in meta_data
    return resolver.get_meta_data()
  File "/home/maus/bsuir/kp/engine/tool.py", line 61, in get_meta_data
    result = self.run()
  File "/home/maus/bsuir/kp/engine/tool.py", line 87, in run
    args, preexec_fn=demote(user_uid, user_gid), cwd=cwd, env=env
  File "/usr/lib/python3.7/subprocess.py", line 775, in __init__
    restore_signals, start_new_session)
  File "/usr/lib/python3.7/subprocess.py", line 1522, in _execute_child
    raise child_exception_type(errno_num, err_msg, err_filename)
FileNotFoundError: [Errno 2] No such file or directory: 'pipenv run python': 'pipenv run python'
ERROR 2019-05-01 18:16:36,787 basehttp "GET /nn/1 HTTP/1.1" 500 134544
WARNING 2019-05-01 18:16:37,027 log Not Found: /favicon.ico
WARNING 2019-05-01 18:16:37,027 basehttp "GET /favicon.ico HTTP/1.1" 404 4388
INFO 2019-05-01 18:17:09,542 autoreload Watching for file changes with StatReloader
ERROR 2019-05-01 18:17:10,872 tool error
Traceback (most recent call last):
  File "/home/maus/bsuir/kp/engine/tool.py", line 65, in prepare_sandbox
    with open("sandboxes/" + self.filename, "w") as output:
AttributeError: 'NNResolver' object has no attribute 'filename'
ERROR 2019-05-01 18:17:10,940 log Internal Server Error: /nn/1
Traceback (most recent call last):
  File "/home/maus/.local/share/virtualenvs/kp-3crlKS4c/lib/python3.7/site-packages/django/core/handlers/exception.py", line 34, in inner
    response = get_response(request)
  File "/home/maus/.local/share/virtualenvs/kp-3crlKS4c/lib/python3.7/site-packages/django/core/handlers/base.py", line 115, in _get_response
    response = self.process_exception_by_middleware(e, request)
  File "/home/maus/.local/share/virtualenvs/kp-3crlKS4c/lib/python3.7/site-packages/django/core/handlers/base.py", line 113, in _get_response
    response = wrapped_callback(request, *callback_args, **callback_kwargs)
  File "/home/maus/.local/share/virtualenvs/kp-3crlKS4c/lib/python3.7/site-packages/django/views/generic/base.py", line 71, in view
    return self.dispatch(request, *args, **kwargs)
  File "/home/maus/.local/share/virtualenvs/kp-3crlKS4c/lib/python3.7/site-packages/django/views/generic/base.py", line 97, in dispatch
    return handler(request, *args, **kwargs)
  File "/home/maus/.local/share/virtualenvs/kp-3crlKS4c/lib/python3.7/site-packages/django/views/generic/detail.py", line 107, in get
    context = self.get_context_data(object=self.object)
  File "/home/maus/bsuir/kp/ignis/views.py", line 178, in get_context_data
    meta_data = dataset.meta_data()
  File "/home/maus/bsuir/kp/ignis/models.py", line 64, in meta_data
    return resolver.get_meta_data()
  File "/home/maus/bsuir/kp/engine/tool.py", line 61, in get_meta_data
    result = self.run()
  File "/home/maus/bsuir/kp/engine/tool.py", line 93, in run
    args, preexec_fn=demote(user_uid, user_gid), cwd=cwd, env=env
  File "/usr/lib/python3.7/subprocess.py", line 775, in __init__
    restore_signals, start_new_session)
  File "/usr/lib/python3.7/subprocess.py", line 1522, in _execute_child
    raise child_exception_type(errno_num, err_msg, err_filename)
FileNotFoundError: [Errno 2] No such file or directory: 'pipenv run python': 'pipenv run python'
ERROR 2019-05-01 18:17:10,941 basehttp "GET /nn/1 HTTP/1.1" 500 134425
INFO 2019-05-01 18:17:22,320 autoreload /home/maus/bsuir/kp/engine/tool.py changed, reloading.
INFO 2019-05-01 18:17:22,990 autoreload Watching for file changes with StatReloader
INFO 2019-05-01 18:17:39,917 autoreload /home/maus/bsuir/kp/engine/tool.py changed, reloading.
INFO 2019-05-01 18:17:40,559 autoreload Watching for file changes with StatReloader
ERROR 2019-05-01 18:18:53,365 tool error
Traceback (most recent call last):
  File "/home/maus/bsuir/kp/engine/tool.py", line 65, in prepare_sandbox
    with open("sandboxes/" + self.filename, "w") as output:
AttributeError: 'NNResolver' object has no attribute 'filename'
ERROR 2019-05-01 18:18:53,429 log Internal Server Error: /nn/1
Traceback (most recent call last):
  File "/home/maus/.local/share/virtualenvs/kp-3crlKS4c/lib/python3.7/site-packages/django/core/handlers/exception.py", line 34, in inner
    response = get_response(request)
  File "/home/maus/.local/share/virtualenvs/kp-3crlKS4c/lib/python3.7/site-packages/django/core/handlers/base.py", line 115, in _get_response
    response = self.process_exception_by_middleware(e, request)
  File "/home/maus/.local/share/virtualenvs/kp-3crlKS4c/lib/python3.7/site-packages/django/core/handlers/base.py", line 113, in _get_response
    response = wrapped_callback(request, *callback_args, **callback_kwargs)
  File "/home/maus/.local/share/virtualenvs/kp-3crlKS4c/lib/python3.7/site-packages/django/views/generic/base.py", line 71, in view
    return self.dispatch(request, *args, **kwargs)
  File "/home/maus/.local/share/virtualenvs/kp-3crlKS4c/lib/python3.7/site-packages/django/views/generic/base.py", line 97, in dispatch
    return handler(request, *args, **kwargs)
  File "/home/maus/.local/share/virtualenvs/kp-3crlKS4c/lib/python3.7/site-packages/django/views/generic/detail.py", line 107, in get
    context = self.get_context_data(object=self.object)
  File "/home/maus/bsuir/kp/ignis/views.py", line 178, in get_context_data
    meta_data = dataset.meta_data()
  File "/home/maus/bsuir/kp/ignis/models.py", line 64, in meta_data
    return resolver.get_meta_data()
  File "/home/maus/bsuir/kp/engine/tool.py", line 61, in get_meta_data
    result = self.run()
  File "/home/maus/bsuir/kp/engine/tool.py", line 88, in run
    args, preexec_fn=demote(user_uid, user_gid), cwd=cwd, env=env
  File "/usr/lib/python3.7/subprocess.py", line 775, in __init__
    restore_signals, start_new_session)
  File "/usr/lib/python3.7/subprocess.py", line 1522, in _execute_child
    raise child_exception_type(errno_num, err_msg, err_filename)
FileNotFoundError: [Errno 2] No such file or directory: 'pipenv run python': 'pipenv run python'
ERROR 2019-05-01 18:18:53,431 basehttp "GET /nn/1 HTTP/1.1" 500 134581
INFO 2019-05-01 18:20:38,929 autoreload /home/maus/bsuir/kp/engine/tool.py changed, reloading.
INFO 2019-05-01 18:20:39,605 autoreload Watching for file changes with StatReloader
INFO 2019-05-01 18:20:49,244 autoreload /home/maus/bsuir/kp/engine/tool.py changed, reloading.
INFO 2019-05-01 18:20:49,883 autoreload Watching for file changes with StatReloader
ERROR 2019-05-01 18:21:00,616 tool error
Traceback (most recent call last):
  File "/home/maus/bsuir/kp/engine/tool.py", line 65, in prepare_sandbox
    with open("sandboxes/" + self.filename, "w") as output:
AttributeError: 'NNResolver' object has no attribute 'filename'
INFO 2019-05-01 18:23:15,456 autoreload Watching for file changes with StatReloader
ERROR 2019-05-01 18:23:19,877 tool error
Traceback (most recent call last):
  File "/home/maus/bsuir/kp/engine/tool.py", line 65, in prepare_sandbox
    with open("sandboxes/" + self.filename, "w") as output:
AttributeError: 'NNResolver' object has no attribute 'filename'
ERROR 2019-05-01 18:23:20,012 log Internal Server Error: /nn/1
Traceback (most recent call last):
  File "/home/maus/.local/share/virtualenvs/kp-3crlKS4c/lib/python3.7/site-packages/django/core/handlers/exception.py", line 34, in inner
    response = get_response(request)
  File "/home/maus/.local/share/virtualenvs/kp-3crlKS4c/lib/python3.7/site-packages/django/core/handlers/base.py", line 115, in _get_response
    response = self.process_exception_by_middleware(e, request)
  File "/home/maus/.local/share/virtualenvs/kp-3crlKS4c/lib/python3.7/site-packages/django/core/handlers/base.py", line 113, in _get_response
    response = wrapped_callback(request, *callback_args, **callback_kwargs)
  File "/home/maus/.local/share/virtualenvs/kp-3crlKS4c/lib/python3.7/site-packages/django/views/generic/base.py", line 71, in view
    return self.dispatch(request, *args, **kwargs)
  File "/home/maus/.local/share/virtualenvs/kp-3crlKS4c/lib/python3.7/site-packages/django/views/generic/base.py", line 97, in dispatch
    return handler(request, *args, **kwargs)
  File "/home/maus/.local/share/virtualenvs/kp-3crlKS4c/lib/python3.7/site-packages/django/views/generic/detail.py", line 107, in get
    context = self.get_context_data(object=self.object)
  File "/home/maus/bsuir/kp/ignis/views.py", line 178, in get_context_data
    meta_data = dataset.meta_data()
  File "/home/maus/bsuir/kp/ignis/models.py", line 64, in meta_data
    return resolver.get_meta_data()
  File "/home/maus/bsuir/kp/engine/tool.py", line 61, in get_meta_data
    result = self.run()
  File "/home/maus/bsuir/kp/engine/tool.py", line 78, in run
    process = subprocess.Popen("python " + self.name, shell=True, env=env)
NameError: name 'env' is not defined
ERROR 2019-05-01 18:23:20,013 basehttp "GET /nn/1 HTTP/1.1" 500 94888
INFO 2019-05-01 18:23:27,225 autoreload /home/maus/bsuir/kp/engine/tool.py changed, reloading.
INFO 2019-05-01 18:23:27,888 autoreload Watching for file changes with StatReloader
ERROR 2019-05-01 18:23:29,970 tool error
Traceback (most recent call last):
  File "/home/maus/bsuir/kp/engine/tool.py", line 65, in prepare_sandbox
    with open("sandboxes/" + self.filename, "w") as output:
AttributeError: 'NNResolver' object has no attribute 'filename'
INFO 2019-05-01 18:23:30,288 basehttp "GET /nn/1 HTTP/1.1" 200 1667
WARNING 2019-05-01 18:23:30,452 basehttp "GET /static/css/styles.css HTTP/1.1" 404 1767
WARNING 2019-05-01 18:23:30,606 basehttp "GET /static/css/styles.css HTTP/1.1" 404 1767
INFO 2019-05-01 18:24:03,688 autoreload /home/maus/bsuir/kp/engine/tool.py changed, reloading.
INFO 2019-05-01 18:24:04,315 autoreload Watching for file changes with StatReloader
INFO 2019-05-01 18:24:11,836 autoreload /home/maus/bsuir/kp/engine/tool.py changed, reloading.
INFO 2019-05-01 18:24:12,469 autoreload Watching for file changes with StatReloader
ERROR 2019-05-01 18:24:15,765 tool error
Traceback (most recent call last):
  File "/home/maus/bsuir/kp/engine/tool.py", line 65, in prepare_sandbox
    with open("sandboxes/" + self.filename, "w") as output:
AttributeError: 'NNResolver' object has no attribute 'filename'
INFO 2019-05-01 18:24:15,828 basehttp "GET /nn/1 HTTP/1.1" 200 1667
WARNING 2019-05-01 18:24:15,956 basehttp "GET /static/css/styles.css HTTP/1.1" 404 1767
WARNING 2019-05-01 18:24:16,048 basehttp "GET /static/css/styles.css HTTP/1.1" 404 1767
INFO 2019-05-01 18:27:58,902 autoreload /home/maus/bsuir/kp/engine/tool.py changed, reloading.
INFO 2019-05-01 18:27:59,349 autoreload Watching for file changes with StatReloader
INFO 2019-05-01 18:28:31,724 autoreload /home/maus/bsuir/kp/engine/tool.py changed, reloading.
INFO 2019-05-01 18:28:32,092 autoreload Watching for file changes with StatReloader
INFO 2019-05-01 18:28:40,295 autoreload /home/maus/bsuir/kp/engine/tool.py changed, reloading.
INFO 2019-05-01 18:28:40,629 autoreload Watching for file changes with StatReloader
INFO 2019-05-01 18:28:50,864 autoreload /home/maus/bsuir/kp/engine/tool.py changed, reloading.
INFO 2019-05-01 18:28:51,173 autoreload Watching for file changes with StatReloader
INFO 2019-05-01 18:28:57,362 autoreload /home/maus/bsuir/kp/engine/tool.py changed, reloading.
INFO 2019-05-01 18:28:57,707 autoreload Watching for file changes with StatReloader
INFO 2019-05-01 18:29:02,897 autoreload /home/maus/bsuir/kp/engine/tool.py changed, reloading.
INFO 2019-05-01 18:29:03,217 autoreload Watching for file changes with StatReloader
INFO 2019-05-01 18:29:04,369 autoreload /home/maus/bsuir/kp/engine/tool.py changed, reloading.
INFO 2019-05-01 18:29:04,737 autoreload Watching for file changes with StatReloader
INFO 2019-05-01 18:29:14,946 autoreload /home/maus/bsuir/kp/engine/tool.py changed, reloading.
INFO 2019-05-01 18:29:15,254 autoreload Watching for file changes with StatReloader
INFO 2019-05-01 18:30:03,745 autoreload /home/maus/bsuir/kp/engine/tool.py changed, reloading.
INFO 2019-05-01 18:30:04,069 autoreload Watching for file changes with StatReloader
INFO 2019-05-01 18:30:08,240 autoreload /home/maus/bsuir/kp/engine/tool.py changed, reloading.
INFO 2019-05-01 18:30:08,856 autoreload Watching for file changes with StatReloader
ERROR 2019-05-01 18:30:19,095 log Internal Server Error: /nn/1
Traceback (most recent call last):
  File "/home/maus/.local/share/virtualenvs/kp-3crlKS4c/lib/python3.7/site-packages/django/core/handlers/exception.py", line 34, in inner
    response = get_response(request)
  File "/home/maus/.local/share/virtualenvs/kp-3crlKS4c/lib/python3.7/site-packages/django/core/handlers/base.py", line 115, in _get_response
    response = self.process_exception_by_middleware(e, request)
  File "/home/maus/.local/share/virtualenvs/kp-3crlKS4c/lib/python3.7/site-packages/django/core/handlers/base.py", line 113, in _get_response
    response = wrapped_callback(request, *callback_args, **callback_kwargs)
  File "/home/maus/.local/share/virtualenvs/kp-3crlKS4c/lib/python3.7/site-packages/django/views/generic/base.py", line 71, in view
    return self.dispatch(request, *args, **kwargs)
  File "/home/maus/.local/share/virtualenvs/kp-3crlKS4c/lib/python3.7/site-packages/django/views/generic/base.py", line 97, in dispatch
    return handler(request, *args, **kwargs)
  File "/home/maus/.local/share/virtualenvs/kp-3crlKS4c/lib/python3.7/site-packages/django/views/generic/detail.py", line 107, in get
    context = self.get_context_data(object=self.object)
  File "/home/maus/bsuir/kp/ignis/views.py", line 178, in get_context_data
    meta_data = dataset.meta_data()
  File "/home/maus/bsuir/kp/ignis/models.py", line 64, in meta_data
    return resolver.get_meta_data()
  File "/home/maus/bsuir/kp/engine/tool.py", line 61, in get_meta_data
    result = self.run()
  File "/home/maus/bsuir/kp/engine/tool.py", line 100, in run
    "result.txt",
  File "/usr/lib/python3.7/subprocess.py", line 728, in __init__
    errread, errwrite) = self._get_handles(stdin, stdout, stderr)
  File "/usr/lib/python3.7/subprocess.py", line 1359, in _get_handles
    c2pwrite = stdout.fileno()
AttributeError: 'str' object has no attribute 'fileno'
ERROR 2019-05-01 18:30:19,096 basehttp "GET /nn/1 HTTP/1.1" 500 107192
WARNING 2019-05-01 18:30:19,332 log Not Found: /favicon.ico
WARNING 2019-05-01 18:30:19,334 basehttp "GET /favicon.ico HTTP/1.1" 404 4388
INFO 2019-05-01 18:30:44,579 autoreload /home/maus/bsuir/kp/engine/tool.py changed, reloading.
INFO 2019-05-01 18:30:45,282 autoreload Watching for file changes with StatReloader
INFO 2019-05-01 18:30:50,725 autoreload /home/maus/bsuir/kp/engine/tool.py changed, reloading.
INFO 2019-05-01 18:30:51,402 autoreload Watching for file changes with StatReloader
ERROR 2019-05-01 18:31:10,886 tool error
Traceback (most recent call last):
  File "/home/maus/bsuir/kp/engine/tool.py", line 69, in prepare_sandbox
    self.name,
  File "/home/maus/.local/share/virtualenvs/kp-3crlKS4c/lib/python3.7/os.py", line 221, in makedirs
    mkdir(name, mode)
FileExistsError: [Errno 17] File exists: '/home/maus/bsuir/kp/sandboxes/test2019-05-01 16:18:23+00:00'
ERROR 2019-05-01 18:31:10,994 log Internal Server Error: /nn/1
Traceback (most recent call last):
  File "/home/maus/.local/share/virtualenvs/kp-3crlKS4c/lib/python3.7/site-packages/django/core/handlers/exception.py", line 34, in inner
    response = get_response(request)
  File "/home/maus/.local/share/virtualenvs/kp-3crlKS4c/lib/python3.7/site-packages/django/core/handlers/base.py", line 115, in _get_response
    response = self.process_exception_by_middleware(e, request)
  File "/home/maus/.local/share/virtualenvs/kp-3crlKS4c/lib/python3.7/site-packages/django/core/handlers/base.py", line 113, in _get_response
    response = wrapped_callback(request, *callback_args, **callback_kwargs)
  File "/home/maus/.local/share/virtualenvs/kp-3crlKS4c/lib/python3.7/site-packages/django/views/generic/base.py", line 71, in view
    return self.dispatch(request, *args, **kwargs)
  File "/home/maus/.local/share/virtualenvs/kp-3crlKS4c/lib/python3.7/site-packages/django/views/generic/base.py", line 97, in dispatch
    return handler(request, *args, **kwargs)
  File "/home/maus/.local/share/virtualenvs/kp-3crlKS4c/lib/python3.7/site-packages/django/views/generic/detail.py", line 107, in get
    context = self.get_context_data(object=self.object)
  File "/home/maus/bsuir/kp/ignis/views.py", line 178, in get_context_data
    meta_data = dataset.meta_data()
  File "/home/maus/bsuir/kp/ignis/models.py", line 64, in meta_data
    return resolver.get_meta_data()
  File "/home/maus/bsuir/kp/engine/tool.py", line 61, in get_meta_data
    result = self.run()
  File "/home/maus/bsuir/kp/engine/tool.py", line 100, in run
    "result.txt",
  File "/usr/lib/python3.7/subprocess.py", line 728, in __init__
    errread, errwrite) = self._get_handles(stdin, stdout, stderr)
  File "/usr/lib/python3.7/subprocess.py", line 1359, in _get_handles
    c2pwrite = stdout.fileno()
AttributeError: 'str' object has no attribute 'fileno'
ERROR 2019-05-01 18:31:10,996 basehttp "GET /nn/1 HTTP/1.1" 500 107195
ERROR 2019-05-01 18:31:26,334 log Internal Server Error: /nn/1
Traceback (most recent call last):
  File "/home/maus/.local/share/virtualenvs/kp-3crlKS4c/lib/python3.7/site-packages/django/core/handlers/exception.py", line 34, in inner
    response = get_response(request)
  File "/home/maus/.local/share/virtualenvs/kp-3crlKS4c/lib/python3.7/site-packages/django/core/handlers/base.py", line 115, in _get_response
    response = self.process_exception_by_middleware(e, request)
  File "/home/maus/.local/share/virtualenvs/kp-3crlKS4c/lib/python3.7/site-packages/django/core/handlers/base.py", line 113, in _get_response
    response = wrapped_callback(request, *callback_args, **callback_kwargs)
  File "/home/maus/.local/share/virtualenvs/kp-3crlKS4c/lib/python3.7/site-packages/django/views/generic/base.py", line 71, in view
    return self.dispatch(request, *args, **kwargs)
  File "/home/maus/.local/share/virtualenvs/kp-3crlKS4c/lib/python3.7/site-packages/django/views/generic/base.py", line 97, in dispatch
    return handler(request, *args, **kwargs)
  File "/home/maus/.local/share/virtualenvs/kp-3crlKS4c/lib/python3.7/site-packages/django/views/generic/detail.py", line 107, in get
    context = self.get_context_data(object=self.object)
  File "/home/maus/bsuir/kp/ignis/views.py", line 178, in get_context_data
    meta_data = dataset.meta_data()
  File "/home/maus/bsuir/kp/ignis/models.py", line 64, in meta_data
    return resolver.get_meta_data()
  File "/home/maus/bsuir/kp/engine/tool.py", line 61, in get_meta_data
    result = self.run()
  File "/home/maus/bsuir/kp/engine/tool.py", line 100, in run
    "result.txt",
  File "/usr/lib/python3.7/subprocess.py", line 728, in __init__
    errread, errwrite) = self._get_handles(stdin, stdout, stderr)
  File "/usr/lib/python3.7/subprocess.py", line 1359, in _get_handles
    c2pwrite = stdout.fileno()
AttributeError: 'str' object has no attribute 'fileno'
ERROR 2019-05-01 18:31:26,335 basehttp "GET /nn/1 HTTP/1.1" 500 107195
INFO 2019-05-01 18:31:42,792 autoreload /home/maus/bsuir/kp/engine/tool.py changed, reloading.
INFO 2019-05-01 18:31:43,528 autoreload Watching for file changes with StatReloader
INFO 2019-05-01 18:32:10,856 autoreload /home/maus/bsuir/kp/engine/tool.py changed, reloading.
INFO 2019-05-01 18:32:11,241 autoreload Watching for file changes with StatReloader
INFO 2019-05-01 18:32:21,460 autoreload /home/maus/bsuir/kp/engine/tool.py changed, reloading.
INFO 2019-05-01 18:32:22,048 autoreload Watching for file changes with StatReloader
ERROR 2019-05-01 18:32:24,924 log Internal Server Error: /nn/1
Traceback (most recent call last):
  File "/home/maus/.local/share/virtualenvs/kp-3crlKS4c/lib/python3.7/site-packages/django/core/handlers/exception.py", line 34, in inner
    response = get_response(request)
  File "/home/maus/.local/share/virtualenvs/kp-3crlKS4c/lib/python3.7/site-packages/django/core/handlers/base.py", line 115, in _get_response
    response = self.process_exception_by_middleware(e, request)
  File "/home/maus/.local/share/virtualenvs/kp-3crlKS4c/lib/python3.7/site-packages/django/core/handlers/base.py", line 113, in _get_response
    response = wrapped_callback(request, *callback_args, **callback_kwargs)
  File "/home/maus/.local/share/virtualenvs/kp-3crlKS4c/lib/python3.7/site-packages/django/views/generic/base.py", line 71, in view
    return self.dispatch(request, *args, **kwargs)
  File "/home/maus/.local/share/virtualenvs/kp-3crlKS4c/lib/python3.7/site-packages/django/views/generic/base.py", line 97, in dispatch
    return handler(request, *args, **kwargs)
  File "/home/maus/.local/share/virtualenvs/kp-3crlKS4c/lib/python3.7/site-packages/django/views/generic/detail.py", line 107, in get
    context = self.get_context_data(object=self.object)
  File "/home/maus/bsuir/kp/ignis/views.py", line 178, in get_context_data
    meta_data = dataset.meta_data()
  File "/home/maus/bsuir/kp/ignis/models.py", line 64, in meta_data
    return resolver.get_meta_data()
  File "/home/maus/bsuir/kp/engine/tool.py", line 61, in get_meta_data
    result = self.run()
  File "/home/maus/bsuir/kp/engine/tool.py", line 101, in run
    "/result.txt",
  File "/usr/lib/python3.7/subprocess.py", line 728, in __init__
    errread, errwrite) = self._get_handles(stdin, stdout, stderr)
  File "/usr/lib/python3.7/subprocess.py", line 1359, in _get_handles
    c2pwrite = stdout.fileno()
AttributeError: 'str' object has no attribute 'fileno'
ERROR 2019-05-01 18:32:24,925 basehttp "GET /nn/1 HTTP/1.1" 500 107151
INFO 2019-05-01 18:32:40,090 autoreload /home/maus/bsuir/kp/engine/tool.py changed, reloading.
INFO 2019-05-01 18:32:40,727 autoreload Watching for file changes with StatReloader
ERROR 2019-05-01 18:32:43,839 log Internal Server Error: /nn/1
Traceback (most recent call last):
  File "/home/maus/.local/share/virtualenvs/kp-3crlKS4c/lib/python3.7/site-packages/django/core/handlers/exception.py", line 34, in inner
    response = get_response(request)
  File "/home/maus/.local/share/virtualenvs/kp-3crlKS4c/lib/python3.7/site-packages/django/core/handlers/base.py", line 115, in _get_response
    response = self.process_exception_by_middleware(e, request)
  File "/home/maus/.local/share/virtualenvs/kp-3crlKS4c/lib/python3.7/site-packages/django/core/handlers/base.py", line 113, in _get_response
    response = wrapped_callback(request, *callback_args, **callback_kwargs)
  File "/home/maus/.local/share/virtualenvs/kp-3crlKS4c/lib/python3.7/site-packages/django/views/generic/base.py", line 71, in view
    return self.dispatch(request, *args, **kwargs)
  File "/home/maus/.local/share/virtualenvs/kp-3crlKS4c/lib/python3.7/site-packages/django/views/generic/base.py", line 97, in dispatch
    return handler(request, *args, **kwargs)
  File "/home/maus/.local/share/virtualenvs/kp-3crlKS4c/lib/python3.7/site-packages/django/views/generic/detail.py", line 107, in get
    context = self.get_context_data(object=self.object)
  File "/home/maus/bsuir/kp/ignis/views.py", line 178, in get_context_data
    meta_data = dataset.meta_data()
  File "/home/maus/bsuir/kp/ignis/models.py", line 64, in meta_data
    return resolver.get_meta_data()
  File "/home/maus/bsuir/kp/engine/tool.py", line 61, in get_meta_data
    result = self.run()
  File "/home/maus/bsuir/kp/engine/tool.py", line 102, in run
    "/result.txt",
  File "/usr/lib/python3.7/subprocess.py", line 728, in __init__
    errread, errwrite) = self._get_handles(stdin, stdout, stderr)
  File "/usr/lib/python3.7/subprocess.py", line 1359, in _get_handles
    c2pwrite = stdout.fileno()
AttributeError: 'str' object has no attribute 'fileno'
ERROR 2019-05-01 18:32:43,840 basehttp "GET /nn/1 HTTP/1.1" 500 107151
INFO 2019-05-01 18:33:41,570 autoreload /home/maus/bsuir/kp/engine/tool.py changed, reloading.
INFO 2019-05-01 18:33:42,274 autoreload Watching for file changes with StatReloader
ERROR 2019-05-01 18:33:50,241 log Internal Server Error: /nn/1
Traceback (most recent call last):
  File "/home/maus/.local/share/virtualenvs/kp-3crlKS4c/lib/python3.7/site-packages/django/core/handlers/exception.py", line 34, in inner
    response = get_response(request)
  File "/home/maus/.local/share/virtualenvs/kp-3crlKS4c/lib/python3.7/site-packages/django/core/handlers/base.py", line 115, in _get_response
    response = self.process_exception_by_middleware(e, request)
  File "/home/maus/.local/share/virtualenvs/kp-3crlKS4c/lib/python3.7/site-packages/django/core/handlers/base.py", line 113, in _get_response
    response = wrapped_callback(request, *callback_args, **callback_kwargs)
  File "/home/maus/.local/share/virtualenvs/kp-3crlKS4c/lib/python3.7/site-packages/django/views/generic/base.py", line 71, in view
    return self.dispatch(request, *args, **kwargs)
  File "/home/maus/.local/share/virtualenvs/kp-3crlKS4c/lib/python3.7/site-packages/django/views/generic/base.py", line 97, in dispatch
    return handler(request, *args, **kwargs)
  File "/home/maus/.local/share/virtualenvs/kp-3crlKS4c/lib/python3.7/site-packages/django/views/generic/detail.py", line 107, in get
    context = self.get_context_data(object=self.object)
  File "/home/maus/bsuir/kp/ignis/views.py", line 178, in get_context_data
    meta_data = dataset.meta_data()
  File "/home/maus/bsuir/kp/ignis/models.py", line 64, in meta_data
    return resolver.get_meta_data()
  File "/home/maus/bsuir/kp/engine/tool.py", line 61, in get_meta_data
    result = self.run()
  File "/home/maus/bsuir/kp/engine/tool.py", line 102, in run
    "/result.txt",
  File "/usr/lib/python3.7/subprocess.py", line 728, in __init__
    errread, errwrite) = self._get_handles(stdin, stdout, stderr)
  File "/usr/lib/python3.7/subprocess.py", line 1359, in _get_handles
    c2pwrite = stdout.fileno()
AttributeError: 'str' object has no attribute 'fileno'
ERROR 2019-05-01 18:33:50,242 basehttp "GET /nn/1 HTTP/1.1" 500 107151
INFO 2019-05-01 18:35:06,081 autoreload /home/maus/bsuir/kp/engine/tool.py changed, reloading.
INFO 2019-05-01 18:35:06,443 autoreload Watching for file changes with StatReloader
INFO 2019-05-01 18:35:09,604 autoreload /home/maus/bsuir/kp/engine/tool.py changed, reloading.
INFO 2019-05-01 18:35:10,190 autoreload Watching for file changes with StatReloader
ERROR 2019-05-01 18:35:18,877 log Internal Server Error: /nn/1
Traceback (most recent call last):
  File "/home/maus/.local/share/virtualenvs/kp-3crlKS4c/lib/python3.7/site-packages/django/core/handlers/exception.py", line 34, in inner
    response = get_response(request)
  File "/home/maus/.local/share/virtualenvs/kp-3crlKS4c/lib/python3.7/site-packages/django/core/handlers/base.py", line 115, in _get_response
    response = self.process_exception_by_middleware(e, request)
  File "/home/maus/.local/share/virtualenvs/kp-3crlKS4c/lib/python3.7/site-packages/django/core/handlers/base.py", line 113, in _get_response
    response = wrapped_callback(request, *callback_args, **callback_kwargs)
  File "/home/maus/.local/share/virtualenvs/kp-3crlKS4c/lib/python3.7/site-packages/django/views/generic/base.py", line 71, in view
    return self.dispatch(request, *args, **kwargs)
  File "/home/maus/.local/share/virtualenvs/kp-3crlKS4c/lib/python3.7/site-packages/django/views/generic/base.py", line 97, in dispatch
    return handler(request, *args, **kwargs)
  File "/home/maus/.local/share/virtualenvs/kp-3crlKS4c/lib/python3.7/site-packages/django/views/generic/detail.py", line 107, in get
    context = self.get_context_data(object=self.object)
  File "/home/maus/bsuir/kp/ignis/views.py", line 178, in get_context_data
    meta_data = dataset.meta_data()
  File "/home/maus/bsuir/kp/ignis/models.py", line 64, in meta_data
    return resolver.get_meta_data()
  File "/home/maus/bsuir/kp/engine/tool.py", line 61, in get_meta_data
    result = self.run()
  File "/home/maus/bsuir/kp/engine/tool.py", line 110, in run
    "/result.txt",
  File "/usr/lib/python3.7/subprocess.py", line 728, in __init__
    errread, errwrite) = self._get_handles(stdin, stdout, stderr)
  File "/usr/lib/python3.7/subprocess.py", line 1359, in _get_handles
    c2pwrite = stdout.fileno()
AttributeError: 'str' object has no attribute 'fileno'
ERROR 2019-05-01 18:35:18,878 basehttp "GET /nn/1 HTTP/1.1" 500 107152
INFO 2019-05-01 18:35:54,252 autoreload /home/maus/bsuir/kp/engine/tool.py changed, reloading.
INFO 2019-05-01 18:35:54,937 autoreload Watching for file changes with StatReloader
ERROR 2019-05-01 18:35:55,721 log Internal Server Error: /nn/1
Traceback (most recent call last):
  File "/home/maus/.local/share/virtualenvs/kp-3crlKS4c/lib/python3.7/site-packages/django/core/handlers/exception.py", line 34, in inner
    response = get_response(request)
  File "/home/maus/.local/share/virtualenvs/kp-3crlKS4c/lib/python3.7/site-packages/django/core/handlers/base.py", line 115, in _get_response
    response = self.process_exception_by_middleware(e, request)
  File "/home/maus/.local/share/virtualenvs/kp-3crlKS4c/lib/python3.7/site-packages/django/core/handlers/base.py", line 113, in _get_response
    response = wrapped_callback(request, *callback_args, **callback_kwargs)
  File "/home/maus/.local/share/virtualenvs/kp-3crlKS4c/lib/python3.7/site-packages/django/views/generic/base.py", line 71, in view
    return self.dispatch(request, *args, **kwargs)
  File "/home/maus/.local/share/virtualenvs/kp-3crlKS4c/lib/python3.7/site-packages/django/views/generic/base.py", line 97, in dispatch
    return handler(request, *args, **kwargs)
  File "/home/maus/.local/share/virtualenvs/kp-3crlKS4c/lib/python3.7/site-packages/django/views/generic/detail.py", line 107, in get
    context = self.get_context_data(object=self.object)
  File "/home/maus/bsuir/kp/ignis/views.py", line 178, in get_context_data
    meta_data = dataset.meta_data()
  File "/home/maus/bsuir/kp/ignis/models.py", line 64, in meta_data
    return resolver.get_meta_data()
  File "/home/maus/bsuir/kp/engine/tool.py", line 61, in get_meta_data
    result = self.run()
  File "/home/maus/bsuir/kp/engine/tool.py", line 110, in run
    "/result.txt",
  File "/usr/lib/python3.7/subprocess.py", line 728, in __init__
    errread, errwrite) = self._get_handles(stdin, stdout, stderr)
  File "/usr/lib/python3.7/subprocess.py", line 1359, in _get_handles
    c2pwrite = stdout.fileno()
AttributeError: 'str' object has no attribute 'fileno'
ERROR 2019-05-01 18:35:55,722 basehttp "GET /nn/1 HTTP/1.1" 500 107152
INFO 2019-05-01 18:36:10,826 autoreload /home/maus/bsuir/kp/engine/tool.py changed, reloading.
INFO 2019-05-01 18:36:11,490 autoreload Watching for file changes with StatReloader
INFO 2019-05-01 18:36:16,935 autoreload /home/maus/bsuir/kp/engine/tool.py changed, reloading.
INFO 2019-05-01 18:36:17,551 autoreload Watching for file changes with StatReloader
ERROR 2019-05-01 18:36:18,730 log Internal Server Error: /nn/1
Traceback (most recent call last):
  File "/home/maus/.local/share/virtualenvs/kp-3crlKS4c/lib/python3.7/site-packages/django/core/handlers/exception.py", line 34, in inner
    response = get_response(request)
  File "/home/maus/.local/share/virtualenvs/kp-3crlKS4c/lib/python3.7/site-packages/django/core/handlers/base.py", line 115, in _get_response
    response = self.process_exception_by_middleware(e, request)
  File "/home/maus/.local/share/virtualenvs/kp-3crlKS4c/lib/python3.7/site-packages/django/core/handlers/base.py", line 113, in _get_response
    response = wrapped_callback(request, *callback_args, **callback_kwargs)
  File "/home/maus/.local/share/virtualenvs/kp-3crlKS4c/lib/python3.7/site-packages/django/views/generic/base.py", line 71, in view
    return self.dispatch(request, *args, **kwargs)
  File "/home/maus/.local/share/virtualenvs/kp-3crlKS4c/lib/python3.7/site-packages/django/views/generic/base.py", line 97, in dispatch
    return handler(request, *args, **kwargs)
  File "/home/maus/.local/share/virtualenvs/kp-3crlKS4c/lib/python3.7/site-packages/django/views/generic/detail.py", line 107, in get
    context = self.get_context_data(object=self.object)
  File "/home/maus/bsuir/kp/ignis/views.py", line 178, in get_context_data
    meta_data = dataset.meta_data()
  File "/home/maus/bsuir/kp/ignis/models.py", line 64, in meta_data
    return resolver.get_meta_data()
  File "/home/maus/bsuir/kp/engine/tool.py", line 61, in get_meta_data
    result = self.run()
  File "/home/maus/bsuir/kp/engine/tool.py", line 110, in run
    "/result.txt",
  File "/usr/lib/python3.7/subprocess.py", line 728, in __init__
    errread, errwrite) = self._get_handles(stdin, stdout, stderr)
  File "/usr/lib/python3.7/subprocess.py", line 1359, in _get_handles
    c2pwrite = stdout.fileno()
AttributeError: 'str' object has no attribute 'fileno'
ERROR 2019-05-01 18:36:18,734 basehttp "GET /nn/1 HTTP/1.1" 500 107152
INFO 2019-05-01 18:36:53,286 autoreload /home/maus/bsuir/kp/engine/tool.py changed, reloading.
INFO 2019-05-01 18:36:53,670 autoreload Watching for file changes with StatReloader
INFO 2019-05-01 18:36:57,848 autoreload /home/maus/bsuir/kp/engine/tool.py changed, reloading.
INFO 2019-05-01 18:36:58,166 autoreload Watching for file changes with StatReloader
INFO 2019-05-01 18:37:09,385 autoreload /home/maus/bsuir/kp/engine/tool.py changed, reloading.
INFO 2019-05-01 18:37:09,958 autoreload Watching for file changes with StatReloader
ERROR 2019-05-01 18:37:18,542 log Internal Server Error: /nn/1
Traceback (most recent call last):
  File "/home/maus/.local/share/virtualenvs/kp-3crlKS4c/lib/python3.7/site-packages/django/core/handlers/exception.py", line 34, in inner
    response = get_response(request)
  File "/home/maus/.local/share/virtualenvs/kp-3crlKS4c/lib/python3.7/site-packages/django/core/handlers/base.py", line 115, in _get_response
    response = self.process_exception_by_middleware(e, request)
  File "/home/maus/.local/share/virtualenvs/kp-3crlKS4c/lib/python3.7/site-packages/django/core/handlers/base.py", line 113, in _get_response
    response = wrapped_callback(request, *callback_args, **callback_kwargs)
  File "/home/maus/.local/share/virtualenvs/kp-3crlKS4c/lib/python3.7/site-packages/django/views/generic/base.py", line 71, in view
    return self.dispatch(request, *args, **kwargs)
  File "/home/maus/.local/share/virtualenvs/kp-3crlKS4c/lib/python3.7/site-packages/django/views/generic/base.py", line 97, in dispatch
    return handler(request, *args, **kwargs)
  File "/home/maus/.local/share/virtualenvs/kp-3crlKS4c/lib/python3.7/site-packages/django/views/generic/detail.py", line 107, in get
    context = self.get_context_data(object=self.object)
  File "/home/maus/bsuir/kp/ignis/views.py", line 178, in get_context_data
    meta_data = dataset.meta_data()
  File "/home/maus/bsuir/kp/ignis/models.py", line 64, in meta_data
    return resolver.get_meta_data()
  File "/home/maus/bsuir/kp/engine/tool.py", line 61, in get_meta_data
    result = self.run()
  File "/home/maus/bsuir/kp/engine/tool.py", line 114, in run
    "/result.txt",
  File "/usr/lib/python3.7/subprocess.py", line 728, in __init__
    errread, errwrite) = self._get_handles(stdin, stdout, stderr)
  File "/usr/lib/python3.7/subprocess.py", line 1359, in _get_handles
    c2pwrite = stdout.fileno()
AttributeError: 'str' object has no attribute 'fileno'
ERROR 2019-05-01 18:37:18,546 basehttp "GET /nn/1 HTTP/1.1" 500 107152
INFO 2019-05-01 18:38:38,866 autoreload /home/maus/bsuir/kp/engine/tool.py changed, reloading.
INFO 2019-05-01 18:38:39,566 autoreload Watching for file changes with StatReloader
INFO 2019-05-01 18:38:53,340 autoreload /home/maus/bsuir/kp/engine/tool.py changed, reloading.
INFO 2019-05-01 18:38:53,715 autoreload Watching for file changes with StatReloader
INFO 2019-05-01 18:38:55,885 autoreload /home/maus/bsuir/kp/engine/tool.py changed, reloading.
INFO 2019-05-01 18:38:56,460 autoreload Watching for file changes with StatReloader
ERROR 2019-05-01 18:39:03,249 log Internal Server Error: /nn/1
Traceback (most recent call last):
  File "/home/maus/.local/share/virtualenvs/kp-3crlKS4c/lib/python3.7/site-packages/django/core/handlers/exception.py", line 34, in inner
    response = get_response(request)
  File "/home/maus/.local/share/virtualenvs/kp-3crlKS4c/lib/python3.7/site-packages/django/core/handlers/base.py", line 115, in _get_response
    response = self.process_exception_by_middleware(e, request)
  File "/home/maus/.local/share/virtualenvs/kp-3crlKS4c/lib/python3.7/site-packages/django/core/handlers/base.py", line 113, in _get_response
    response = wrapped_callback(request, *callback_args, **callback_kwargs)
  File "/home/maus/.local/share/virtualenvs/kp-3crlKS4c/lib/python3.7/site-packages/django/views/generic/base.py", line 71, in view
    return self.dispatch(request, *args, **kwargs)
  File "/home/maus/.local/share/virtualenvs/kp-3crlKS4c/lib/python3.7/site-packages/django/views/generic/base.py", line 97, in dispatch
    return handler(request, *args, **kwargs)
  File "/home/maus/.local/share/virtualenvs/kp-3crlKS4c/lib/python3.7/site-packages/django/views/generic/detail.py", line 107, in get
    context = self.get_context_data(object=self.object)
  File "/home/maus/bsuir/kp/ignis/views.py", line 178, in get_context_data
    meta_data = dataset.meta_data()
  File "/home/maus/bsuir/kp/ignis/models.py", line 64, in meta_data
    return resolver.get_meta_data()
  File "/home/maus/bsuir/kp/engine/tool.py", line 61, in get_meta_data
    result = self.run()
  File "/home/maus/bsuir/kp/engine/tool.py", line 98, in run
    stdout="/result.txt",
  File "/usr/lib/python3.7/subprocess.py", line 728, in __init__
    errread, errwrite) = self._get_handles(stdin, stdout, stderr)
  File "/usr/lib/python3.7/subprocess.py", line 1359, in _get_handles
    c2pwrite = stdout.fileno()
AttributeError: 'str' object has no attribute 'fileno'
ERROR 2019-05-01 18:39:03,251 basehttp "GET /nn/1 HTTP/1.1" 500 107120
INFO 2019-05-01 18:39:45,706 autoreload /home/maus/bsuir/kp/engine/tool.py changed, reloading.
INFO 2019-05-01 18:39:46,326 autoreload Watching for file changes with StatReloader
INFO 2019-05-01 18:40:07,389 autoreload /home/maus/bsuir/kp/engine/tool.py changed, reloading.
INFO 2019-05-01 18:40:08,005 autoreload Watching for file changes with StatReloader
ERROR 2019-05-01 18:40:15,114 log Internal Server Error: /nn/1
Traceback (most recent call last):
  File "/home/maus/.local/share/virtualenvs/kp-3crlKS4c/lib/python3.7/site-packages/django/core/handlers/exception.py", line 34, in inner
    response = get_response(request)
  File "/home/maus/.local/share/virtualenvs/kp-3crlKS4c/lib/python3.7/site-packages/django/core/handlers/base.py", line 115, in _get_response
    response = self.process_exception_by_middleware(e, request)
  File "/home/maus/.local/share/virtualenvs/kp-3crlKS4c/lib/python3.7/site-packages/django/core/handlers/base.py", line 113, in _get_response
    response = wrapped_callback(request, *callback_args, **callback_kwargs)
  File "/home/maus/.local/share/virtualenvs/kp-3crlKS4c/lib/python3.7/site-packages/django/views/generic/base.py", line 71, in view
    return self.dispatch(request, *args, **kwargs)
  File "/home/maus/.local/share/virtualenvs/kp-3crlKS4c/lib/python3.7/site-packages/django/views/generic/base.py", line 97, in dispatch
    return handler(request, *args, **kwargs)
  File "/home/maus/.local/share/virtualenvs/kp-3crlKS4c/lib/python3.7/site-packages/django/views/generic/detail.py", line 107, in get
    context = self.get_context_data(object=self.object)
  File "/home/maus/bsuir/kp/ignis/views.py", line 178, in get_context_data
    meta_data = dataset.meta_data()
  File "/home/maus/bsuir/kp/ignis/models.py", line 64, in meta_data
    return resolver.get_meta_data()
  File "/home/maus/bsuir/kp/engine/tool.py", line 61, in get_meta_data
    result = self.run()
  File "/home/maus/bsuir/kp/engine/tool.py", line 102, in run
    "rb",
FileNotFoundError: [Errno 2] No such file or directory: '/result.txt'
ERROR 2019-05-01 18:40:15,115 basehttp "GET /nn/1 HTTP/1.1" 500 95411
INFO 2019-05-01 18:40:51,058 autoreload /home/maus/bsuir/kp/engine/tool.py changed, reloading.
INFO 2019-05-01 18:40:51,445 autoreload Watching for file changes with StatReloader
INFO 2019-05-01 18:40:57,620 autoreload /home/maus/bsuir/kp/engine/tool.py changed, reloading.
INFO 2019-05-01 18:40:57,952 autoreload Watching for file changes with StatReloader
INFO 2019-05-01 18:41:09,163 autoreload /home/maus/bsuir/kp/engine/tool.py changed, reloading.
INFO 2019-05-01 18:41:09,733 autoreload Watching for file changes with StatReloader
INFO 2019-05-01 18:41:19,341 autoreload /home/maus/bsuir/kp/engine/tool.py changed, reloading.
INFO 2019-05-01 18:41:19,988 autoreload Watching for file changes with StatReloader
ERROR 2019-05-01 18:41:21,919 log Internal Server Error: /nn/1
Traceback (most recent call last):
  File "/home/maus/.local/share/virtualenvs/kp-3crlKS4c/lib/python3.7/site-packages/django/core/handlers/exception.py", line 34, in inner
    response = get_response(request)
  File "/home/maus/.local/share/virtualenvs/kp-3crlKS4c/lib/python3.7/site-packages/django/core/handlers/base.py", line 115, in _get_response
    response = self.process_exception_by_middleware(e, request)
  File "/home/maus/.local/share/virtualenvs/kp-3crlKS4c/lib/python3.7/site-packages/django/core/handlers/base.py", line 113, in _get_response
    response = wrapped_callback(request, *callback_args, **callback_kwargs)
  File "/home/maus/.local/share/virtualenvs/kp-3crlKS4c/lib/python3.7/site-packages/django/views/generic/base.py", line 71, in view
    return self.dispatch(request, *args, **kwargs)
  File "/home/maus/.local/share/virtualenvs/kp-3crlKS4c/lib/python3.7/site-packages/django/views/generic/base.py", line 97, in dispatch
    return handler(request, *args, **kwargs)
  File "/home/maus/.local/share/virtualenvs/kp-3crlKS4c/lib/python3.7/site-packages/django/views/generic/detail.py", line 107, in get
    context = self.get_context_data(object=self.object)
  File "/home/maus/bsuir/kp/ignis/views.py", line 178, in get_context_data
    meta_data = dataset.meta_data()
  File "/home/maus/bsuir/kp/ignis/models.py", line 64, in meta_data
    return resolver.get_meta_data()
  File "/home/maus/bsuir/kp/engine/tool.py", line 61, in get_meta_data
    result = self.run()
  File "/home/maus/bsuir/kp/engine/tool.py", line 101, in run
    with open(putput_file_path, "rb") as output:
NameError: name 'putput_file_path' is not defined
ERROR 2019-05-01 18:41:21,920 basehttp "GET /nn/1 HTTP/1.1" 500 95991
INFO 2019-05-01 18:41:53,646 autoreload /home/maus/bsuir/kp/engine/tool.py changed, reloading.
INFO 2019-05-01 18:41:54,257 autoreload Watching for file changes with StatReloader
ERROR 2019-05-01 18:41:56,330 log Internal Server Error: /nn/1
Traceback (most recent call last):
  File "/home/maus/.local/share/virtualenvs/kp-3crlKS4c/lib/python3.7/site-packages/django/core/handlers/exception.py", line 34, in inner
    response = get_response(request)
  File "/home/maus/.local/share/virtualenvs/kp-3crlKS4c/lib/python3.7/site-packages/django/core/handlers/base.py", line 115, in _get_response
    response = self.process_exception_by_middleware(e, request)
  File "/home/maus/.local/share/virtualenvs/kp-3crlKS4c/lib/python3.7/site-packages/django/core/handlers/base.py", line 113, in _get_response
    response = wrapped_callback(request, *callback_args, **callback_kwargs)
  File "/home/maus/.local/share/virtualenvs/kp-3crlKS4c/lib/python3.7/site-packages/django/views/generic/base.py", line 71, in view
    return self.dispatch(request, *args, **kwargs)
  File "/home/maus/.local/share/virtualenvs/kp-3crlKS4c/lib/python3.7/site-packages/django/views/generic/base.py", line 97, in dispatch
    return handler(request, *args, **kwargs)
  File "/home/maus/.local/share/virtualenvs/kp-3crlKS4c/lib/python3.7/site-packages/django/views/generic/detail.py", line 107, in get
    context = self.get_context_data(object=self.object)
  File "/home/maus/bsuir/kp/ignis/views.py", line 178, in get_context_data
    meta_data = dataset.meta_data()
  File "/home/maus/bsuir/kp/ignis/models.py", line 64, in meta_data
    return resolver.get_meta_data()
  File "/home/maus/bsuir/kp/engine/tool.py", line 61, in get_meta_data
    result = self.run()
  File "/home/maus/bsuir/kp/engine/tool.py", line 101, in run
    with open(output_file_path, "rb") as output:
FileNotFoundError: [Errno 2] No such file or directory: '/result.txt'
ERROR 2019-05-01 18:41:56,331 basehttp "GET /nn/1 HTTP/1.1" 500 96055
INFO 2019-05-01 18:42:21,722 autoreload /home/maus/bsuir/kp/engine/tool.py changed, reloading.
INFO 2019-05-01 18:42:22,363 autoreload Watching for file changes with StatReloader
ERROR 2019-05-01 18:42:24,941 log Internal Server Error: /nn/1
Traceback (most recent call last):
  File "/home/maus/.local/share/virtualenvs/kp-3crlKS4c/lib/python3.7/site-packages/django/core/handlers/exception.py", line 34, in inner
    response = get_response(request)
  File "/home/maus/.local/share/virtualenvs/kp-3crlKS4c/lib/python3.7/site-packages/django/core/handlers/base.py", line 115, in _get_response
    response = self.process_exception_by_middleware(e, request)
  File "/home/maus/.local/share/virtualenvs/kp-3crlKS4c/lib/python3.7/site-packages/django/core/handlers/base.py", line 113, in _get_response
    response = wrapped_callback(request, *callback_args, **callback_kwargs)
  File "/home/maus/.local/share/virtualenvs/kp-3crlKS4c/lib/python3.7/site-packages/django/views/generic/base.py", line 71, in view
    return self.dispatch(request, *args, **kwargs)
  File "/home/maus/.local/share/virtualenvs/kp-3crlKS4c/lib/python3.7/site-packages/django/views/generic/base.py", line 97, in dispatch
    return handler(request, *args, **kwargs)
  File "/home/maus/.local/share/virtualenvs/kp-3crlKS4c/lib/python3.7/site-packages/django/views/generic/detail.py", line 107, in get
    context = self.get_context_data(object=self.object)
  File "/home/maus/bsuir/kp/ignis/views.py", line 178, in get_context_data
    meta_data = dataset.meta_data()
  File "/home/maus/bsuir/kp/ignis/models.py", line 64, in meta_data
    return resolver.get_meta_data()
  File "/home/maus/bsuir/kp/engine/tool.py", line 61, in get_meta_data
    result = self.run()
  File "/home/maus/bsuir/kp/engine/tool.py", line 102, in run
    with open(output_file_path, "rb") as output:
FileNotFoundError: [Errno 2] No such file or directory: '/result.txt'
ERROR 2019-05-01 18:42:24,942 basehttp "GET /nn/1 HTTP/1.1" 500 96000
INFO 2019-05-01 18:42:57,017 autoreload /home/maus/bsuir/kp/engine/tool.py changed, reloading.
INFO 2019-05-01 18:42:57,677 autoreload Watching for file changes with StatReloader
INFO 2019-05-01 18:43:01,032 autoreload /home/maus/bsuir/kp/engine/tool.py changed, reloading.
INFO 2019-05-01 18:43:01,653 autoreload Watching for file changes with StatReloader
ERROR 2019-05-01 18:43:02,717 log Internal Server Error: /nn/1
Traceback (most recent call last):
  File "/home/maus/.local/share/virtualenvs/kp-3crlKS4c/lib/python3.7/site-packages/django/core/handlers/exception.py", line 34, in inner
    response = get_response(request)
  File "/home/maus/.local/share/virtualenvs/kp-3crlKS4c/lib/python3.7/site-packages/django/core/handlers/base.py", line 115, in _get_response
    response = self.process_exception_by_middleware(e, request)
  File "/home/maus/.local/share/virtualenvs/kp-3crlKS4c/lib/python3.7/site-packages/django/core/handlers/base.py", line 113, in _get_response
    response = wrapped_callback(request, *callback_args, **callback_kwargs)
  File "/home/maus/.local/share/virtualenvs/kp-3crlKS4c/lib/python3.7/site-packages/django/views/generic/base.py", line 71, in view
    return self.dispatch(request, *args, **kwargs)
  File "/home/maus/.local/share/virtualenvs/kp-3crlKS4c/lib/python3.7/site-packages/django/views/generic/base.py", line 97, in dispatch
    return handler(request, *args, **kwargs)
  File "/home/maus/.local/share/virtualenvs/kp-3crlKS4c/lib/python3.7/site-packages/django/views/generic/detail.py", line 107, in get
    context = self.get_context_data(object=self.object)
  File "/home/maus/bsuir/kp/ignis/views.py", line 178, in get_context_data
    meta_data = dataset.meta_data()
  File "/home/maus/bsuir/kp/ignis/models.py", line 64, in meta_data
    return resolver.get_meta_data()
  File "/home/maus/bsuir/kp/engine/tool.py", line 61, in get_meta_data
    result = self.run()
  File "/home/maus/bsuir/kp/engine/tool.py", line 102, in run
    with open(output_file_path, "rb") as output:
FileNotFoundError: [Errno 2] No such file or directory: '/home/maus/bsuir/kp/sandboxes/test2019-05-01 16:18:23+00:00/result.txt'
ERROR 2019-05-01 18:43:02,718 basehttp "GET /nn/1 HTTP/1.1" 500 96234
INFO 2019-05-01 18:43:44,686 autoreload /home/maus/bsuir/kp/engine/tool.py changed, reloading.
INFO 2019-05-01 18:43:45,343 autoreload Watching for file changes with StatReloader
INFO 2019-05-01 18:45:23,639 autoreload /home/maus/bsuir/kp/engine/tool.py changed, reloading.
INFO 2019-05-01 18:45:24,312 autoreload Watching for file changes with StatReloader
INFO 2019-05-01 18:45:28,708 autoreload /home/maus/bsuir/kp/engine/tool.py changed, reloading.
INFO 2019-05-01 18:45:29,413 autoreload Watching for file changes with StatReloader
INFO 2019-05-01 18:45:38,070 autoreload /home/maus/bsuir/kp/engine/tool.py changed, reloading.
INFO 2019-05-01 18:45:38,732 autoreload Watching for file changes with StatReloader
INFO 2019-05-01 18:45:45,456 basehttp "GET /nn/1 HTTP/1.1" 200 1667
WARNING 2019-05-01 18:45:45,567 basehttp "GET /static/css/styles.css HTTP/1.1" 404 1767
WARNING 2019-05-01 18:45:45,748 basehttp "GET /static/css/styles.css HTTP/1.1" 404 1767
INFO 2019-05-01 18:46:11,978 views user (root) want to update nn (test)
INFO 2019-05-01 18:46:12,351 basehttp "GET /nn/1/update HTTP/1.1" 200 2298
WARNING 2019-05-01 18:46:12,542 basehttp "GET /static/css/styles.css HTTP/1.1" 404 1767
WARNING 2019-05-01 18:46:12,647 basehttp "GET /static/css/styles.css HTTP/1.1" 404 1767
INFO 2019-05-01 18:46:56,561 basehttp "POST /nn/1/update HTTP/1.1" 302 0
INFO 2019-05-01 18:46:56,807 basehttp "GET /nn/ HTTP/1.1" 200 1508
WARNING 2019-05-01 18:46:56,954 basehttp "GET /static/css/styles.css HTTP/1.1" 404 1767
WARNING 2019-05-01 18:46:57,004 basehttp "GET /static/css/styles.css HTTP/1.1" 404 1767
INFO 2019-05-01 18:46:58,954 basehttp "GET /nn/1 HTTP/1.1" 200 1667
WARNING 2019-05-01 18:46:59,076 basehttp "GET /static/css/styles.css HTTP/1.1" 404 1767
WARNING 2019-05-01 18:46:59,138 basehttp "GET /static/css/styles.css HTTP/1.1" 404 1767
INFO 2019-05-01 18:47:41,889 autoreload /home/maus/bsuir/kp/engine/tool.py changed, reloading.
INFO 2019-05-01 18:47:42,596 autoreload Watching for file changes with StatReloader
INFO 2019-05-01 18:47:58,461 autoreload /home/maus/bsuir/kp/engine/tool.py changed, reloading.
INFO 2019-05-01 18:47:59,139 autoreload Watching for file changes with StatReloader
INFO 2019-05-01 18:48:03,201 basehttp "GET /nn/1 HTTP/1.1" 200 1667
WARNING 2019-05-01 18:48:03,311 basehttp "GET /static/css/styles.css HTTP/1.1" 404 1767
WARNING 2019-05-01 18:48:03,396 basehttp "GET /static/css/styles.css HTTP/1.1" 404 1767
INFO 2019-05-01 18:48:08,974 autoreload Watching for file changes with StatReloader
INFO 2019-05-01 18:48:10,320 basehttp "GET /nn/1 HTTP/1.1" 200 1667
WARNING 2019-05-01 18:48:10,426 basehttp "GET /static/css/styles.css HTTP/1.1" 404 1767
WARNING 2019-05-01 18:48:10,532 basehttp "GET /static/css/styles.css HTTP/1.1" 404 1767
INFO 2019-05-01 18:48:31,250 autoreload /home/maus/bsuir/kp/engine/tool.py changed, reloading.
INFO 2019-05-01 18:48:31,663 autoreload Watching for file changes with StatReloader
INFO 2019-05-01 18:48:36,845 autoreload /home/maus/bsuir/kp/engine/tool.py changed, reloading.
INFO 2019-05-01 18:48:37,413 autoreload Watching for file changes with StatReloader
INFO 2019-05-01 18:48:40,656 basehttp "GET /nn/1 HTTP/1.1" 200 1667
WARNING 2019-05-01 18:48:40,746 basehttp "GET /static/css/styles.css HTTP/1.1" 404 1767
WARNING 2019-05-01 18:48:40,872 basehttp "GET /static/css/styles.css HTTP/1.1" 404 1767
INFO 2019-05-01 18:49:52,757 autoreload /home/maus/bsuir/kp/engine/tool.py changed, reloading.
INFO 2019-05-01 18:49:53,412 autoreload Watching for file changes with StatReloader
INFO 2019-05-01 18:49:55,761 autoreload /home/maus/bsuir/kp/engine/tool.py changed, reloading.
INFO 2019-05-01 18:49:56,395 autoreload Watching for file changes with StatReloader
INFO 2019-05-01 18:50:00,120 basehttp "GET /nn/1 HTTP/1.1" 200 1667
WARNING 2019-05-01 18:50:00,227 basehttp "GET /static/css/styles.css HTTP/1.1" 404 1767
WARNING 2019-05-01 18:50:00,331 basehttp "GET /static/css/styles.css HTTP/1.1" 404 1767
INFO 2019-05-01 18:50:05,788 basehttp "GET /nn/1 HTTP/1.1" 200 1667
WARNING 2019-05-01 18:50:05,909 basehttp "GET /static/css/styles.css HTTP/1.1" 404 1767
WARNING 2019-05-01 18:50:06,022 basehttp "GET /static/css/styles.css HTTP/1.1" 404 1767
INFO 2019-05-01 18:50:37,418 autoreload /home/maus/bsuir/kp/engine/tool.py changed, reloading.
INFO 2019-05-01 18:50:38,077 autoreload Watching for file changes with StatReloader
INFO 2019-05-01 18:50:50,789 autoreload /home/maus/bsuir/kp/engine/tool.py changed, reloading.
INFO 2019-05-01 18:50:51,447 autoreload Watching for file changes with StatReloader
INFO 2019-05-01 18:50:53,874 basehttp "GET /nn/1 HTTP/1.1" 200 1667
WARNING 2019-05-01 18:50:53,954 basehttp "GET /static/css/styles.css HTTP/1.1" 404 1767
WARNING 2019-05-01 18:50:54,057 basehttp "GET /static/css/styles.css HTTP/1.1" 404 1767
INFO 2019-05-01 18:50:56,406 basehttp "GET /nn/1 HTTP/1.1" 200 1667
WARNING 2019-05-01 18:50:56,509 basehttp "GET /static/css/styles.css HTTP/1.1" 404 1767
WARNING 2019-05-01 18:50:56,623 basehttp "GET /static/css/styles.css HTTP/1.1" 404 1767
INFO 2019-05-01 18:52:02,852 views user (root) want to update nn (test)
INFO 2019-05-01 18:52:02,867 basehttp "GET /nn/1/update HTTP/1.1" 200 2357
WARNING 2019-05-01 18:52:03,004 basehttp "GET /static/css/styles.css HTTP/1.1" 404 1767
WARNING 2019-05-01 18:52:03,067 basehttp "GET /static/css/styles.css HTTP/1.1" 404 1767
INFO 2019-05-01 18:52:17,298 basehttp "POST /nn/1/update HTTP/1.1" 302 0
INFO 2019-05-01 18:52:17,347 basehttp "GET /nn/ HTTP/1.1" 200 1508
WARNING 2019-05-01 18:52:17,477 basehttp "GET /static/css/styles.css HTTP/1.1" 404 1767
WARNING 2019-05-01 18:52:17,541 basehttp "GET /static/css/styles.css HTTP/1.1" 404 1767
INFO 2019-05-01 18:52:19,725 basehttp "GET /nn/1 HTTP/1.1" 200 1667
WARNING 2019-05-01 18:52:19,837 basehttp "GET /static/css/styles.css HTTP/1.1" 404 1767
WARNING 2019-05-01 18:52:19,908 basehttp "GET /static/css/styles.css HTTP/1.1" 404 1767
INFO 2019-05-01 18:53:06,115 autoreload /home/maus/bsuir/kp/engine/tool.py changed, reloading.
INFO 2019-05-01 18:53:06,809 autoreload Watching for file changes with StatReloader
INFO 2019-05-01 18:53:33,279 autoreload /home/maus/bsuir/kp/engine/tool.py changed, reloading.
INFO 2019-05-01 18:53:33,927 autoreload Watching for file changes with StatReloader
INFO 2019-05-01 18:54:21,054 autoreload Watching for file changes with StatReloader
INFO 2019-05-01 18:55:13,777 autoreload /home/maus/bsuir/kp/engine/tool.py changed, reloading.
INFO 2019-05-01 18:55:14,531 autoreload Watching for file changes with StatReloader
ERROR 2019-05-01 18:55:23,412 log Internal Server Error: /nn/1
Traceback (most recent call last):
  File "/home/maus/.local/share/virtualenvs/kp-3crlKS4c/lib/python3.7/site-packages/django/core/handlers/exception.py", line 34, in inner
    response = get_response(request)
  File "/home/maus/.local/share/virtualenvs/kp-3crlKS4c/lib/python3.7/site-packages/django/core/handlers/base.py", line 115, in _get_response
    response = self.process_exception_by_middleware(e, request)
  File "/home/maus/.local/share/virtualenvs/kp-3crlKS4c/lib/python3.7/site-packages/django/core/handlers/base.py", line 113, in _get_response
    response = wrapped_callback(request, *callback_args, **callback_kwargs)
  File "/home/maus/.local/share/virtualenvs/kp-3crlKS4c/lib/python3.7/site-packages/django/views/generic/base.py", line 71, in view
    return self.dispatch(request, *args, **kwargs)
  File "/home/maus/.local/share/virtualenvs/kp-3crlKS4c/lib/python3.7/site-packages/django/views/generic/base.py", line 97, in dispatch
    return handler(request, *args, **kwargs)
  File "/home/maus/.local/share/virtualenvs/kp-3crlKS4c/lib/python3.7/site-packages/django/views/generic/detail.py", line 107, in get
    context = self.get_context_data(object=self.object)
  File "/home/maus/bsuir/kp/ignis/views.py", line 178, in get_context_data
    meta_data = dataset.meta_data()
  File "/home/maus/bsuir/kp/ignis/models.py", line 63, in meta_data
    resolver = NNResolver(self)
  File "/home/maus/bsuir/kp/engine/tool.py", line 57, in __init__
    self.name = str(self.nn) + str(datetime.datetime.timestamp(self.nn.date))
NameError: name 'datetime' is not defined
ERROR 2019-05-01 18:55:23,413 basehttp "GET /nn/1 HTTP/1.1" 500 91485
INFO 2019-05-01 18:55:39,902 autoreload /home/maus/bsuir/kp/engine/tool.py changed, reloading.
INFO 2019-05-01 18:55:40,551 autoreload Watching for file changes with StatReloader
INFO 2019-05-01 18:55:43,025 basehttp "GET /nn/1 HTTP/1.1" 200 1667
WARNING 2019-05-01 18:55:43,128 basehttp "GET /static/css/styles.css HTTP/1.1" 404 1767
WARNING 2019-05-01 18:55:43,288 basehttp "GET /static/css/styles.css HTTP/1.1" 404 1767
INFO 2019-05-01 18:56:26,667 autoreload /home/maus/bsuir/kp/engine/tool.py changed, reloading.
INFO 2019-05-01 18:56:27,312 autoreload Watching for file changes with StatReloader
INFO 2019-05-01 18:56:41,082 autoreload /home/maus/bsuir/kp/engine/tool.py changed, reloading.
INFO 2019-05-01 18:56:41,759 autoreload Watching for file changes with StatReloader
INFO 2019-05-01 18:56:46,399 basehttp "GET /nn/1 HTTP/1.1" 200 1667
WARNING 2019-05-01 18:56:46,479 basehttp "GET /static/css/styles.css HTTP/1.1" 404 1767
WARNING 2019-05-01 18:56:46,569 basehttp "GET /static/css/styles.css HTTP/1.1" 404 1767
INFO 2019-05-01 18:57:17,604 autoreload /home/maus/bsuir/kp/engine/tool.py changed, reloading.
INFO 2019-05-01 18:57:18,024 autoreload Watching for file changes with StatReloader
INFO 2019-05-01 18:57:22,204 autoreload /home/maus/bsuir/kp/engine/tool.py changed, reloading.
INFO 2019-05-01 18:57:22,796 autoreload Watching for file changes with StatReloader
INFO 2019-05-01 18:58:01,594 autoreload /home/maus/bsuir/kp/engine/tool.py changed, reloading.
INFO 2019-05-01 18:58:02,401 autoreload Watching for file changes with StatReloader
INFO 2019-05-01 18:58:14,123 autoreload /home/maus/bsuir/kp/engine/tool.py changed, reloading.
INFO 2019-05-01 18:58:14,740 autoreload Watching for file changes with StatReloader
INFO 2019-05-01 18:58:15,860 basehttp "GET /nn/1 HTTP/1.1" 200 1667
WARNING 2019-05-01 18:58:15,954 basehttp "GET /static/css/styles.css HTTP/1.1" 404 1767
WARNING 2019-05-01 18:58:16,072 basehttp "GET /static/css/styles.css HTTP/1.1" 404 1767
INFO 2019-05-01 18:58:52,585 autoreload /home/maus/bsuir/kp/engine/tool.py changed, reloading.
INFO 2019-05-01 18:58:53,323 autoreload Watching for file changes with StatReloader
INFO 2019-05-01 18:58:57,736 autoreload /home/maus/bsuir/kp/engine/tool.py changed, reloading.
INFO 2019-05-01 18:58:58,476 autoreload Watching for file changes with StatReloader
INFO 2019-05-01 18:59:00,805 autoreload /home/maus/bsuir/kp/engine/tool.py changed, reloading.
INFO 2019-05-01 18:59:01,466 autoreload Watching for file changes with StatReloader
INFO 2019-05-01 18:59:02,729 autoreload /home/maus/bsuir/kp/engine/tool.py changed, reloading.
INFO 2019-05-01 18:59:03,380 autoreload Watching for file changes with StatReloader
INFO 2019-05-01 18:59:06,932 basehttp "GET /nn/1 HTTP/1.1" 200 1667
WARNING 2019-05-01 18:59:07,013 basehttp "GET /static/css/styles.css HTTP/1.1" 404 1767
WARNING 2019-05-01 18:59:07,100 basehttp "GET /static/css/styles.css HTTP/1.1" 404 1767
INFO 2019-05-01 18:59:19,288 autoreload /home/maus/bsuir/kp/engine/tool.py changed, reloading.
INFO 2019-05-01 18:59:19,954 autoreload Watching for file changes with StatReloader
INFO 2019-05-01 18:59:21,410 basehttp "GET /nn/1 HTTP/1.1" 200 1667
WARNING 2019-05-01 18:59:21,463 basehttp "GET /static/css/styles.css HTTP/1.1" 404 1767
WARNING 2019-05-01 18:59:21,567 basehttp "GET /static/css/styles.css HTTP/1.1" 404 1767
INFO 2019-05-01 19:00:24,779 autoreload /home/maus/bsuir/kp/engine/tool.py changed, reloading.
INFO 2019-05-01 19:00:25,549 autoreload Watching for file changes with StatReloader
INFO 2019-05-01 19:00:27,868 autoreload /home/maus/bsuir/kp/engine/tool.py changed, reloading.
INFO 2019-05-01 19:00:28,488 autoreload Watching for file changes with StatReloader
INFO 2019-05-01 19:01:27,231 autoreload /home/maus/bsuir/kp/engine/tool.py changed, reloading.
INFO 2019-05-01 19:01:28,742 autoreload Watching for file changes with StatReloader
INFO 2019-05-01 19:01:37,395 basehttp "GET /nn/1 HTTP/1.1" 200 1667
WARNING 2019-05-01 19:01:37,519 basehttp "GET /static/css/styles.css HTTP/1.1" 404 1767
WARNING 2019-05-01 19:01:37,647 basehttp "GET /static/css/styles.css HTTP/1.1" 404 1767
INFO 2019-05-01 19:02:23,284 autoreload /home/maus/bsuir/kp/engine/tool.py changed, reloading.
INFO 2019-05-01 19:02:23,677 autoreload Watching for file changes with StatReloader
INFO 2019-05-01 19:02:26,839 autoreload /home/maus/bsuir/kp/engine/tool.py changed, reloading.
INFO 2019-05-01 19:02:27,470 autoreload Watching for file changes with StatReloader
INFO 2019-05-01 19:02:32,685 basehttp "GET /nn/1 HTTP/1.1" 200 1667
WARNING 2019-05-01 19:02:32,774 basehttp "GET /static/css/styles.css HTTP/1.1" 404 1767
WARNING 2019-05-01 19:02:33,325 basehttp "GET /static/css/styles.css HTTP/1.1" 404 1767
INFO 2019-05-01 19:02:47,640 autoreload /home/maus/bsuir/kp/engine/tool.py changed, reloading.
INFO 2019-05-01 19:02:48,259 autoreload Watching for file changes with StatReloader
INFO 2019-05-01 19:02:51,526 basehttp "GET /nn/1 HTTP/1.1" 200 1667
WARNING 2019-05-01 19:02:51,607 basehttp "GET /static/css/styles.css HTTP/1.1" 404 1767
WARNING 2019-05-01 19:02:51,703 basehttp "GET /static/css/styles.css HTTP/1.1" 404 1767
INFO 2019-05-01 19:03:13,732 autoreload /home/maus/bsuir/kp/engine/tool.py changed, reloading.
INFO 2019-05-01 19:03:14,440 autoreload Watching for file changes with StatReloader
INFO 2019-05-01 19:03:17,303 basehttp "GET /nn/1 HTTP/1.1" 200 1667
WARNING 2019-05-01 19:03:17,361 basehttp "GET /static/css/styles.css HTTP/1.1" 404 1767
WARNING 2019-05-01 19:03:17,463 basehttp "GET /static/css/styles.css HTTP/1.1" 404 1767
INFO 2019-05-01 19:03:22,584 basehttp "GET /nn/1 HTTP/1.1" 200 1667
WARNING 2019-05-01 19:03:22,663 basehttp "GET /static/css/styles.css HTTP/1.1" 404 1767
WARNING 2019-05-01 19:03:22,746 basehttp "GET /static/css/styles.css HTTP/1.1" 404 1767
INFO 2019-05-01 19:04:21,374 autoreload /home/maus/bsuir/kp/engine/tool.py changed, reloading.
INFO 2019-05-01 19:04:22,052 autoreload Watching for file changes with StatReloader
INFO 2019-05-01 19:04:32,790 autoreload /home/maus/bsuir/kp/engine/tool.py changed, reloading.
INFO 2019-05-01 19:04:33,451 autoreload Watching for file changes with StatReloader
INFO 2019-05-01 19:04:41,000 autoreload /home/maus/bsuir/kp/engine/tool.py changed, reloading.
INFO 2019-05-01 19:04:41,610 autoreload Watching for file changes with StatReloader
INFO 2019-05-01 19:04:46,943 basehttp "GET /nn/1 HTTP/1.1" 200 1667
WARNING 2019-05-01 19:04:47,058 basehttp "GET /static/css/styles.css HTTP/1.1" 404 1767
WARNING 2019-05-01 19:04:47,191 basehttp "GET /static/css/styles.css HTTP/1.1" 404 1767
INFO 2019-05-01 19:08:34,463 autoreload Watching for file changes with StatReloader
ERROR 2019-05-01 19:08:39,047 log Internal Server Error: /nn/1
Traceback (most recent call last):
  File "/home/maus/.local/share/virtualenvs/kp-3crlKS4c/lib/python3.7/site-packages/django/core/handlers/exception.py", line 34, in inner
    response = get_response(request)
  File "/home/maus/.local/share/virtualenvs/kp-3crlKS4c/lib/python3.7/site-packages/django/core/handlers/base.py", line 115, in _get_response
    response = self.process_exception_by_middleware(e, request)
  File "/home/maus/.local/share/virtualenvs/kp-3crlKS4c/lib/python3.7/site-packages/django/core/handlers/base.py", line 113, in _get_response
    response = wrapped_callback(request, *callback_args, **callback_kwargs)
  File "/home/maus/.local/share/virtualenvs/kp-3crlKS4c/lib/python3.7/site-packages/django/views/generic/base.py", line 71, in view
    return self.dispatch(request, *args, **kwargs)
  File "/home/maus/.local/share/virtualenvs/kp-3crlKS4c/lib/python3.7/site-packages/django/views/generic/base.py", line 97, in dispatch
    return handler(request, *args, **kwargs)
  File "/home/maus/.local/share/virtualenvs/kp-3crlKS4c/lib/python3.7/site-packages/django/views/generic/detail.py", line 107, in get
    context = self.get_context_data(object=self.object)
  File "/home/maus/bsuir/kp/ignis/views.py", line 178, in get_context_data
    meta_data = dataset.meta_data()
  File "/home/maus/bsuir/kp/ignis/models.py", line 64, in meta_data
    return resolver.get_meta_data()
  File "/home/maus/bsuir/kp/engine/tool.py", line 63, in get_meta_data
    result = self.run()
  File "/home/maus/bsuir/kp/engine/tool.py", line 124, in run
    stdout=output,
  File "/usr/lib/python3.7/subprocess.py", line 323, in call
    with Popen(*popenargs, **kwargs) as p:
  File "/usr/lib/python3.7/subprocess.py", line 775, in __init__
    restore_signals, start_new_session)
  File "/usr/lib/python3.7/subprocess.py", line 1523, in _execute_child
    raise child_exception_type(err_msg)
subprocess.SubprocessError: Exception occurred in preexec_fn.
ERROR 2019-05-01 19:08:39,050 basehttp "GET /nn/1 HTTP/1.1" 500 118393
INFO 2019-05-01 19:10:59,611 autoreload /home/maus/bsuir/kp/engine/tool.py changed, reloading.
INFO 2019-05-01 19:11:00,273 autoreload Watching for file changes with StatReloader
INFO 2019-05-01 19:11:08,827 autoreload /home/maus/bsuir/kp/engine/tool.py changed, reloading.
INFO 2019-05-01 19:11:09,494 autoreload Watching for file changes with StatReloader
INFO 2019-05-01 19:11:19,139 autoreload /home/maus/bsuir/kp/engine/tool.py changed, reloading.
INFO 2019-05-01 19:11:19,735 autoreload Watching for file changes with StatReloader
ERROR 2019-05-01 19:11:21,543 log Internal Server Error: /nn/1
Traceback (most recent call last):
  File "/home/maus/.local/share/virtualenvs/kp-3crlKS4c/lib/python3.7/site-packages/django/core/handlers/exception.py", line 34, in inner
    response = get_response(request)
  File "/home/maus/.local/share/virtualenvs/kp-3crlKS4c/lib/python3.7/site-packages/django/core/handlers/base.py", line 115, in _get_response
    response = self.process_exception_by_middleware(e, request)
  File "/home/maus/.local/share/virtualenvs/kp-3crlKS4c/lib/python3.7/site-packages/django/core/handlers/base.py", line 113, in _get_response
    response = wrapped_callback(request, *callback_args, **callback_kwargs)
  File "/home/maus/.local/share/virtualenvs/kp-3crlKS4c/lib/python3.7/site-packages/django/views/generic/base.py", line 71, in view
    return self.dispatch(request, *args, **kwargs)
  File "/home/maus/.local/share/virtualenvs/kp-3crlKS4c/lib/python3.7/site-packages/django/views/generic/base.py", line 97, in dispatch
    return handler(request, *args, **kwargs)
  File "/home/maus/.local/share/virtualenvs/kp-3crlKS4c/lib/python3.7/site-packages/django/views/generic/detail.py", line 107, in get
    context = self.get_context_data(object=self.object)
  File "/home/maus/bsuir/kp/ignis/views.py", line 178, in get_context_data
    meta_data = dataset.meta_data()
  File "/home/maus/bsuir/kp/ignis/models.py", line 64, in meta_data
    return resolver.get_meta_data()
  File "/home/maus/bsuir/kp/engine/tool.py", line 63, in get_meta_data
    result = self.run()
  File "/home/maus/bsuir/kp/engine/tool.py", line 124, in run
    stdout=output,
  File "/usr/lib/python3.7/subprocess.py", line 775, in __init__
    restore_signals, start_new_session)
  File "/usr/lib/python3.7/subprocess.py", line 1523, in _execute_child
    raise child_exception_type(err_msg)
subprocess.SubprocessError: Exception occurred in preexec_fn.
ERROR 2019-05-01 19:11:21,545 basehttp "GET /nn/1 HTTP/1.1" 500 114197
INFO 2019-05-01 19:13:29,212 autoreload /home/maus/bsuir/kp/engine/tool.py changed, reloading.
INFO 2019-05-01 19:13:29,909 autoreload Watching for file changes with StatReloader
ERROR 2019-05-01 19:13:33,009 log Internal Server Error: /nn/1
Traceback (most recent call last):
  File "/home/maus/.local/share/virtualenvs/kp-3crlKS4c/lib/python3.7/site-packages/django/core/handlers/exception.py", line 34, in inner
    response = get_response(request)
  File "/home/maus/.local/share/virtualenvs/kp-3crlKS4c/lib/python3.7/site-packages/django/core/handlers/base.py", line 115, in _get_response
    response = self.process_exception_by_middleware(e, request)
  File "/home/maus/.local/share/virtualenvs/kp-3crlKS4c/lib/python3.7/site-packages/django/core/handlers/base.py", line 113, in _get_response
    response = wrapped_callback(request, *callback_args, **callback_kwargs)
  File "/home/maus/.local/share/virtualenvs/kp-3crlKS4c/lib/python3.7/site-packages/django/views/generic/base.py", line 71, in view
    return self.dispatch(request, *args, **kwargs)
  File "/home/maus/.local/share/virtualenvs/kp-3crlKS4c/lib/python3.7/site-packages/django/views/generic/base.py", line 97, in dispatch
    return handler(request, *args, **kwargs)
  File "/home/maus/.local/share/virtualenvs/kp-3crlKS4c/lib/python3.7/site-packages/django/views/generic/detail.py", line 107, in get
    context = self.get_context_data(object=self.object)
  File "/home/maus/bsuir/kp/ignis/views.py", line 178, in get_context_data
    meta_data = dataset.meta_data()
  File "/home/maus/bsuir/kp/ignis/models.py", line 64, in meta_data
    return resolver.get_meta_data()
  File "/home/maus/bsuir/kp/engine/tool.py", line 63, in get_meta_data
    result = self.run()
  File "/home/maus/bsuir/kp/engine/tool.py", line 124, in run
    stdout=output,
  File "/usr/lib/python3.7/subprocess.py", line 775, in __init__
    restore_signals, start_new_session)
  File "/usr/lib/python3.7/subprocess.py", line 1523, in _execute_child
    raise child_exception_type(err_msg)
subprocess.SubprocessError: Exception occurred in preexec_fn.
ERROR 2019-05-01 19:13:33,010 basehttp "GET /nn/1 HTTP/1.1" 500 114197
INFO 2019-05-01 19:13:42,780 autoreload /home/maus/bsuir/kp/engine/tool.py changed, reloading.
INFO 2019-05-01 19:13:43,445 autoreload Watching for file changes with StatReloader
ERROR 2019-05-01 19:13:47,835 log Internal Server Error: /nn/1
Traceback (most recent call last):
  File "/home/maus/.local/share/virtualenvs/kp-3crlKS4c/lib/python3.7/site-packages/django/core/handlers/exception.py", line 34, in inner
    response = get_response(request)
  File "/home/maus/.local/share/virtualenvs/kp-3crlKS4c/lib/python3.7/site-packages/django/core/handlers/base.py", line 115, in _get_response
    response = self.process_exception_by_middleware(e, request)
  File "/home/maus/.local/share/virtualenvs/kp-3crlKS4c/lib/python3.7/site-packages/django/core/handlers/base.py", line 113, in _get_response
    response = wrapped_callback(request, *callback_args, **callback_kwargs)
  File "/home/maus/.local/share/virtualenvs/kp-3crlKS4c/lib/python3.7/site-packages/django/views/generic/base.py", line 71, in view
    return self.dispatch(request, *args, **kwargs)
  File "/home/maus/.local/share/virtualenvs/kp-3crlKS4c/lib/python3.7/site-packages/django/views/generic/base.py", line 97, in dispatch
    return handler(request, *args, **kwargs)
  File "/home/maus/.local/share/virtualenvs/kp-3crlKS4c/lib/python3.7/site-packages/django/views/generic/detail.py", line 107, in get
    context = self.get_context_data(object=self.object)
  File "/home/maus/bsuir/kp/ignis/views.py", line 178, in get_context_data
    meta_data = dataset.meta_data()
  File "/home/maus/bsuir/kp/ignis/models.py", line 64, in meta_data
    return resolver.get_meta_data()
  File "/home/maus/bsuir/kp/engine/tool.py", line 63, in get_meta_data
    result = self.run()
  File "/home/maus/bsuir/kp/engine/tool.py", line 124, in run
    stdout=output,
  File "/usr/lib/python3.7/subprocess.py", line 775, in __init__
    restore_signals, start_new_session)
  File "/usr/lib/python3.7/subprocess.py", line 1523, in _execute_child
    raise child_exception_type(err_msg)
subprocess.SubprocessError: Exception occurred in preexec_fn.
ERROR 2019-05-01 19:13:47,839 basehttp "GET /nn/1 HTTP/1.1" 500 114196
INFO 2019-05-01 19:17:02,688 autoreload Watching for file changes with StatReloader
ERROR 2019-05-01 19:17:06,662 log Internal Server Error: /nn/1
Traceback (most recent call last):
  File "/home/maus/.local/share/virtualenvs/kp-3crlKS4c/lib/python3.7/site-packages/django/core/handlers/exception.py", line 34, in inner
    response = get_response(request)
  File "/home/maus/.local/share/virtualenvs/kp-3crlKS4c/lib/python3.7/site-packages/django/core/handlers/base.py", line 115, in _get_response
    response = self.process_exception_by_middleware(e, request)
  File "/home/maus/.local/share/virtualenvs/kp-3crlKS4c/lib/python3.7/site-packages/django/core/handlers/base.py", line 113, in _get_response
    response = wrapped_callback(request, *callback_args, **callback_kwargs)
  File "/home/maus/.local/share/virtualenvs/kp-3crlKS4c/lib/python3.7/site-packages/django/views/generic/base.py", line 71, in view
    return self.dispatch(request, *args, **kwargs)
  File "/home/maus/.local/share/virtualenvs/kp-3crlKS4c/lib/python3.7/site-packages/django/views/generic/base.py", line 97, in dispatch
    return handler(request, *args, **kwargs)
  File "/home/maus/.local/share/virtualenvs/kp-3crlKS4c/lib/python3.7/site-packages/django/views/generic/detail.py", line 107, in get
    context = self.get_context_data(object=self.object)
  File "/home/maus/bsuir/kp/ignis/views.py", line 178, in get_context_data
    meta_data = dataset.meta_data()
  File "/home/maus/bsuir/kp/ignis/models.py", line 64, in meta_data
    return resolver.get_meta_data()
  File "/home/maus/bsuir/kp/engine/tool.py", line 63, in get_meta_data
    result = self.run()
  File "/home/maus/bsuir/kp/engine/tool.py", line 124, in run
    stdout=output,
  File "/usr/lib/python3.7/subprocess.py", line 775, in __init__
    restore_signals, start_new_session)
  File "/usr/lib/python3.7/subprocess.py", line 1523, in _execute_child
    raise child_exception_type(err_msg)
subprocess.SubprocessError: Exception occurred in preexec_fn.
ERROR 2019-05-01 19:17:06,664 basehttp "GET /nn/1 HTTP/1.1" 500 114336
WARNING 2019-05-01 19:17:06,909 log Not Found: /favicon.ico
WARNING 2019-05-01 19:17:06,909 basehttp "GET /favicon.ico HTTP/1.1" 404 4388
INFO 2019-05-01 19:17:18,721 autoreload /home/maus/bsuir/kp/engine/tool.py changed, reloading.
INFO 2019-05-01 19:17:19,453 autoreload Watching for file changes with StatReloader
INFO 2019-05-01 19:17:20,568 basehttp "GET /nn/1 HTTP/1.1" 200 1667
WARNING 2019-05-01 19:17:20,692 basehttp "GET /static/css/styles.css HTTP/1.1" 404 1767
WARNING 2019-05-01 19:17:20,862 basehttp "GET /static/css/styles.css HTTP/1.1" 404 1767
INFO 2019-05-01 19:17:43,657 autoreload /home/maus/bsuir/kp/engine/tool.py changed, reloading.
INFO 2019-05-01 19:17:44,388 autoreload Watching for file changes with StatReloader
INFO 2019-05-01 19:17:48,358 basehttp "GET /nn/1 HTTP/1.1" 200 1667
WARNING 2019-05-01 19:17:48,463 basehttp "GET /static/css/styles.css HTTP/1.1" 404 1767
WARNING 2019-05-01 19:17:48,556 basehttp "GET /static/css/styles.css HTTP/1.1" 404 1767
INFO 2019-05-01 19:18:35,750 autoreload /home/maus/bsuir/kp/engine/tool.py changed, reloading.
INFO 2019-05-01 19:18:36,489 autoreload Watching for file changes with StatReloader
INFO 2019-05-01 19:18:47,182 autoreload /home/maus/bsuir/kp/engine/tool.py changed, reloading.
INFO 2019-05-01 19:18:47,893 autoreload Watching for file changes with StatReloader
INFO 2019-05-01 19:18:52,276 autoreload /home/maus/bsuir/kp/engine/tool.py changed, reloading.
INFO 2019-05-01 19:18:52,960 autoreload Watching for file changes with StatReloader
INFO 2019-05-01 19:18:57,372 autoreload /home/maus/bsuir/kp/engine/tool.py changed, reloading.
INFO 2019-05-01 19:18:58,056 autoreload Watching for file changes with StatReloader
INFO 2019-05-01 19:19:06,621 autoreload /home/maus/bsuir/kp/engine/tool.py changed, reloading.
INFO 2019-05-01 19:19:07,241 autoreload Watching for file changes with StatReloader
INFO 2019-05-01 19:19:40,913 autoreload /home/maus/bsuir/kp/engine/tool.py changed, reloading.
INFO 2019-05-01 19:19:41,587 autoreload Watching for file changes with StatReloader
INFO 2019-05-01 19:20:05,849 autoreload /home/maus/bsuir/kp/ignis/views.py changed, reloading.
INFO 2019-05-01 19:20:06,553 autoreload Watching for file changes with StatReloader
INFO 2019-05-01 19:20:08,893 autoreload /home/maus/bsuir/kp/ignis/views.py changed, reloading.
INFO 2019-05-01 19:20:09,555 autoreload Watching for file changes with StatReloader
INFO 2019-05-01 19:20:43,717 basehttp "GET /nn/1 HTTP/1.1" 200 1716
WARNING 2019-05-01 19:20:43,817 basehttp "GET /static/css/styles.css HTTP/1.1" 404 1767
WARNING 2019-05-01 19:20:43,939 basehttp "GET /static/css/styles.css HTTP/1.1" 404 1767
INFO 2019-05-01 19:21:20,886 autoreload /home/maus/bsuir/kp/ignis/views.py changed, reloading.
INFO 2019-05-01 19:21:21,539 autoreload Watching for file changes with StatReloader
ERROR 2019-05-01 19:21:23,100 log Internal Server Error: /nn/1
Traceback (most recent call last):
  File "/home/maus/.local/share/virtualenvs/kp-3crlKS4c/lib/python3.7/site-packages/django/core/handlers/exception.py", line 34, in inner
    response = get_response(request)
  File "/home/maus/.local/share/virtualenvs/kp-3crlKS4c/lib/python3.7/site-packages/django/core/handlers/base.py", line 115, in _get_response
    response = self.process_exception_by_middleware(e, request)
  File "/home/maus/.local/share/virtualenvs/kp-3crlKS4c/lib/python3.7/site-packages/django/core/handlers/base.py", line 113, in _get_response
    response = wrapped_callback(request, *callback_args, **callback_kwargs)
  File "/home/maus/.local/share/virtualenvs/kp-3crlKS4c/lib/python3.7/site-packages/django/views/generic/base.py", line 71, in view
    return self.dispatch(request, *args, **kwargs)
  File "/home/maus/.local/share/virtualenvs/kp-3crlKS4c/lib/python3.7/site-packages/django/views/generic/base.py", line 97, in dispatch
    return handler(request, *args, **kwargs)
  File "/home/maus/.local/share/virtualenvs/kp-3crlKS4c/lib/python3.7/site-packages/django/views/generic/detail.py", line 107, in get
    context = self.get_context_data(object=self.object)
  File "/home/maus/bsuir/kp/ignis/views.py", line 179, in get_context_data
    context["result"] = meta_data.decode("utf-8")
AttributeError: 'list' object has no attribute 'decode'
ERROR 2019-05-01 19:21:23,103 basehttp "GET /nn/1 HTTP/1.1" 500 85544
INFO 2019-05-01 19:21:37,491 autoreload /home/maus/bsuir/kp/ignis/views.py changed, reloading.
INFO 2019-05-01 19:21:38,133 autoreload Watching for file changes with StatReloader
INFO 2019-05-01 19:21:45,687 autoreload /home/maus/bsuir/kp/ignis/views.py changed, reloading.
INFO 2019-05-01 19:21:46,298 autoreload Watching for file changes with StatReloader
INFO 2019-05-01 19:22:06,636 basehttp "GET /nn/1 HTTP/1.1" 200 1702
WARNING 2019-05-01 19:22:06,732 basehttp "GET /static/css/styles.css HTTP/1.1" 404 1767
WARNING 2019-05-01 19:22:06,814 basehttp "GET /static/css/styles.css HTTP/1.1" 404 1767
